<?xml version='1.0' encoding='utf-8'?>
<mujoco model="Simple2Wheel">
  <compiler angle="radian" meshdir="meshes" />
  <default>
    <motor ctrlrange="-1 1" gear="1" />
  </default>
  <visual>
    <headlight ambient=".4 .4 .4" diffuse=".8 .8 .8" specular="0.1 0.1 0.1" />
    <map znear="0.01" />
    <quality shadowsize="2048" />
  </visual>
  <asset>
    <mesh name="body_body" file="body_body.stl" />
    <mesh name="l_wheel_l_wheel" file="l_wheel_l_wheel.stl" />
    <mesh name="r_wheel_r_wheel" file="r_wheel_r_wheel.stl" />
    <texture type="skybox" builtin="gradient" rgb1="0.3 0.5 0.7" rgb2="0 0 0" width="512" height="3072" />
    <texture type="2d" name="groundplane" builtin="checker" mark="edge" rgb1="0.2 0.3 0.4" rgb2="0.1 0.2 0.3" markrgb="0.8 0.8 0.8" width="300" height="300" />
    <material name="groundplane" texture="groundplane" texuniform="true" texrepeat="5 5" reflectance="0.2" />
  </asset>
  <worldbody>
    <light directional="true" diffuse=".8 .8 .8" pos="0 0 10" dir="0 0 -1" />
    <geom name="floor" type="plane" size="5 5 0.1" rgba=".9 .9 .9 1" />
    <body name="root_adapter" pos="0 0 0" euler="1.5707963267948966 0 0">
      <body name="body_1" pos="0.000000 0.000000 0.000000" quat="1.000000 0.000000 0.000000 0.000000">
        <inertial pos="-50.000000 70.000000 0.000000" mass="8.124999999999996" fullinertia="53760.416667 84635.416667 53760.416667 0.000000 0.000000 0.000000" />
        <geom type="mesh" mesh="body_body" rgba="0.9647058823529412 0.9647058823529412 0.9529411764705882 1.0" />
        <body name="l_wheel_1" pos="0.000000 0.000000 0.000000" quat="1.000000 0.000000 0.000000 0.000000">
          <inertial pos="95.000000 75.000000 0.000000" mass="0.9000000000000001" fullinertia="3375.000000 1807.500000 1807.500000 0.000000 0.000000 0.000000" />
          <joint name="Revolute_1" type="hinge" pos="75.000000 75.000000 0.000000" axis="-1.000000 0.000000 0.000000" />
          <geom type="mesh" mesh="l_wheel_l_wheel" rgba="0.15294117647058825 0.15294117647058825 0.15294117647058825 1.0" />
        </body>
        <body name="r_wheel_1" pos="0.000000 0.000000 0.000000" quat="1.000000 0.000000 0.000000 0.000000">
          <inertial pos="-195.000000 75.000000 0.000000" mass="0.9000000000000002" fullinertia="3375.000000 1807.500000 1807.500000 0.000000 0.000000 0.000000" />
          <joint name="Revolute_2" type="hinge" pos="-175.000000 75.000000 0.000000" axis="1.000000 0.000000 0.000000" />
          <geom type="mesh" mesh="r_wheel_r_wheel" rgba="0.15294117647058825 0.15294117647058825 0.15294117647058825 1.0" />
        </body>
      </body>
    </body>
  </worldbody>
  <actuator>
    <motor name="Revolute_1_motor" joint="Revolute_1" ctrlrange="-1 1" />
    <motor name="Revolute_2_motor" joint="Revolute_2" ctrlrange="-1 1" />
  </actuator>
  <sensor>
    <jointpos name="Revolute_1_pos_sensor" joint="Revolute_1" />
    <jointvel name="Revolute_1_vel_sensor" joint="Revolute_1" />
    <jointpos name="Revolute_2_pos_sensor" joint="Revolute_2" />
    <jointvel name="Revolute_2_vel_sensor" joint="Revolute_2" />
  </sensor>
</mujoco>