<?xml version='1.0' encoding='utf-8'?>
<mujoco model="SimpleBiped">
  <compiler angle="radian" inertiafromgeom="true" />

  <default>
    <joint limited="true" damping="0.1" armature="0.01" />
    <geom contype="1" conaffinity="1" condim="3" density="1000"
          friction="0.7 0.1 0.1" />
  </default>

  <worldbody>
    <body name="base" pos="0 0 0.40">
      <freejoint name="root" />
      <geom name="torso" type="ellipsoid" size="0.14 0.12 0.10"
            rgba="0.9 0.7 0.3 1.0" />

      <!-- IMU site for sensors -->
      <site name="imu" pos="0 0 0" />

      <!-- Forward-facing camera (looks in -Y = forward, matches wheeler convention) -->
      <camera name="camera_1_cam" fovy="90.0"
              pos="0 -0.13 0.06" euler="-1.5707963 0 3.14159265" />

      <!-- Left leg (robot's left = -X when facing -Y) -->
      <body name="left_upper_leg" pos="-0.12 0 -0.08">
        <joint name="left_hip" type="hinge" axis="1 0 0"
               pos="0 0 0" range="-1.5708 0.7854" />
        <geom name="left_upper_leg" type="capsule" fromto="0 0 0 0 0 -0.12"
              size="0.045" rgba="0.85 0.65 0.25 1.0" friction="0.9" />

        <body name="left_lower_leg" pos="0 0 -0.12">
          <joint name="left_knee" type="hinge" axis="1 0 0"
                 pos="0 0 0" range="0 1.5708" />
          <geom name="left_lower_leg" type="capsule" fromto="0 0 0 0 0 -0.10"
                size="0.04" rgba="0.85 0.65 0.25 1.0" friction="0.9" />

          <body name="left_foot" pos="0 0 -0.10">
            <joint name="left_ankle" type="hinge" axis="1 0 0"
                   pos="0 0 0" range="-0.7854 0.7854" />
            <geom name="left_foot" type="box" size="0.06 0.10 0.02"
                  pos="0 -0.02 -0.015" rgba="1.0 0.6 0.1 1.0" friction="0.9" />
          </body>
        </body>
      </body>

      <!-- Right leg (robot's right = +X when facing -Y) -->
      <body name="right_upper_leg" pos="0.12 0 -0.08">
        <joint name="right_hip" type="hinge" axis="1 0 0"
               pos="0 0 0" range="-1.5708 0.7854" />
        <geom name="right_upper_leg" type="capsule" fromto="0 0 0 0 0 -0.12"
              size="0.045" rgba="0.85 0.65 0.25 1.0" friction="0.9" />

        <body name="right_lower_leg" pos="0 0 -0.12">
          <joint name="right_knee" type="hinge" axis="1 0 0"
                 pos="0 0 0" range="0 1.5708" />
          <geom name="right_lower_leg" type="capsule" fromto="0 0 0 0 0 -0.10"
                size="0.04" rgba="0.85 0.65 0.25 1.0" friction="0.9" />

          <body name="right_foot" pos="0 0 -0.10">
            <joint name="right_ankle" type="hinge" axis="1 0 0"
                   pos="0 0 0" range="-0.7854 0.7854" />
            <geom name="right_foot" type="box" size="0.06 0.10 0.02"
                  pos="0 -0.02 -0.015" rgba="1.0 0.6 0.1 1.0" friction="0.9" />
          </body>
        </body>
      </body>
    </body>
  </worldbody>

  <contact>
    <!-- Exclude adjacent body pairs -->
    <exclude body1="base" body2="left_upper_leg" />
    <exclude body1="base" body2="right_upper_leg" />
    <exclude body1="left_upper_leg" body2="left_lower_leg" />
    <exclude body1="left_lower_leg" body2="left_foot" />
    <exclude body1="right_upper_leg" body2="right_lower_leg" />
    <exclude body1="right_lower_leg" body2="right_foot" />
    <!-- Exclude left/right upper legs from colliding -->
    <exclude body1="left_upper_leg" body2="right_upper_leg" />
  </contact>

  <actuator>
    <!-- Torque motors (matching Walker2d control paradigm) -->
    <motor name="left_hip_motor" ctrllimited="true" ctrlrange="-1.0 1.0"
           gear="100" joint="left_hip" />
    <motor name="left_knee_motor" ctrllimited="true" ctrlrange="-1.0 1.0"
           gear="100" joint="left_knee" />
    <motor name="left_ankle_motor" ctrllimited="true" ctrlrange="-1.0 1.0"
           gear="100" joint="left_ankle" />
    <motor name="right_hip_motor" ctrllimited="true" ctrlrange="-1.0 1.0"
           gear="100" joint="right_hip" />
    <motor name="right_knee_motor" ctrllimited="true" ctrlrange="-1.0 1.0"
           gear="100" joint="right_knee" />
    <motor name="right_ankle_motor" ctrllimited="true" ctrlrange="-1.0 1.0"
           gear="100" joint="right_ankle" />
  </actuator>

  <sensor>
    <!-- Joint position sensors -->
    <jointpos name="left_hip_pos" joint="left_hip" />
    <jointpos name="left_knee_pos" joint="left_knee" />
    <jointpos name="left_ankle_pos" joint="left_ankle" />
    <jointpos name="right_hip_pos" joint="right_hip" />
    <jointpos name="right_knee_pos" joint="right_knee" />
    <jointpos name="right_ankle_pos" joint="right_ankle" />
    <!-- Joint velocity sensors -->
    <jointvel name="left_hip_vel" joint="left_hip" />
    <jointvel name="left_knee_vel" joint="left_knee" />
    <jointvel name="left_ankle_vel" joint="left_ankle" />
    <jointvel name="right_hip_vel" joint="right_hip" />
    <jointvel name="right_knee_vel" joint="right_knee" />
    <jointvel name="right_ankle_vel" joint="right_ankle" />
    <!-- IMU sensors -->
    <gyro name="torso_gyro" site="imu" />
    <accelerometer name="torso_accel" site="imu" />
  </sensor>
</mujoco>
