<?xml version='1.0' encoding='utf-8'?>
<mujoco model="so101_arm">
  <compiler angle="radian" meshdir="meshes"/>
  <default>
    <motor ctrlrange="-1 1" gear="1.0"/>
  </default>
  <asset>
    <mesh name="base_mesh" file="base.stl" scale="1 1 1"/>
    <mesh name="turntable_mesh" file="turntable.stl" scale="1 1 1"/>
    <mesh name="upper_arm_mesh" file="upper_arm.stl" scale="1 1 1"/>
    <mesh name="forearm_mesh" file="forearm.stl" scale="1 1 1"/>
    <mesh name="wrist_mesh" file="wrist.stl" scale="1 1 1"/>
    <mesh name="wrist_roll_mesh" file="wrist_roll.stl" scale="1 1 1"/>
    <mesh name="jaw_mesh" file="jaw.stl" scale="1 1 1"/>
    <mesh name="comp_base_pi_mesh" file="comp_base_pi.stl" scale="1 1 1"/>
    <mesh name="comp_base_battery_mesh" file="comp_base_battery.stl" scale="1 1 1"/>
    <mesh name="comp_wrist_roll_camera_mesh" file="comp_wrist_roll_camera.stl" scale="1 1 1"/>
    <mesh name="servo_STS3215_mesh" file="servo_STS3215.stl" scale="1 1 1"/>
    <mesh name="hardware_M3_shc_mesh" file="hardware_M3_shc.stl" scale="1 1 1"/>
    <mesh name="hardware_M2_shc_mesh" file="hardware_M2_shc.stl" scale="1 1 1"/>
    <mesh name="hardware_M2.5_shc_mesh" file="hardware_M2.5_shc.stl" scale="1 1 1"/>
    <mesh name="horn_shoulder_pan_mesh" file="horn_shoulder_pan.stl" scale="1 1 1"/>
    <mesh name="horn_shoulder_lift_mesh" file="horn_shoulder_lift.stl" scale="1 1 1"/>
    <mesh name="horn_elbow_flex_mesh" file="horn_elbow_flex.stl" scale="1 1 1"/>
    <mesh name="horn_wrist_flex_mesh" file="horn_wrist_flex.stl" scale="1 1 1"/>
    <mesh name="horn_wrist_roll_mesh" file="horn_wrist_roll.stl" scale="1 1 1"/>
    <mesh name="horn_gripper_mesh" file="horn_gripper.stl" scale="1 1 1"/>
    <mesh name="wire_servo_bus_base_0_mesh" file="wire_servo_bus_base_0.stl" scale="1 1 1"/>
    <mesh name="wire_servo_bus_turntable_1_mesh" file="wire_servo_bus_turntable_1.stl" scale="1 1 1"/>
    <mesh name="wire_servo_bus_turntable_2_mesh" file="wire_servo_bus_turntable_2.stl" scale="1 1 1"/>
    <mesh name="wire_servo_bus_upper_arm_3_mesh" file="wire_servo_bus_upper_arm_3.stl" scale="1 1 1"/>
    <mesh name="wire_servo_bus_upper_arm_4_mesh" file="wire_servo_bus_upper_arm_4.stl" scale="1 1 1"/>
    <mesh name="wire_servo_bus_forearm_5_mesh" file="wire_servo_bus_forearm_5.stl" scale="1 1 1"/>
    <mesh name="wire_servo_bus_forearm_6_mesh" file="wire_servo_bus_forearm_6.stl" scale="1 1 1"/>
    <mesh name="wire_servo_bus_wrist_7_mesh" file="wire_servo_bus_wrist_7.stl" scale="1 1 1"/>
    <mesh name="wire_servo_bus_wrist_roll_8_mesh" file="wire_servo_bus_wrist_roll_8.stl" scale="1 1 1"/>
    <mesh name="wire_servo_bus_wrist_roll_9_mesh" file="wire_servo_bus_wrist_roll_9.stl" scale="1 1 1"/>
    <mesh name="wire_camera_csi_wrist_roll_0_mesh" file="wire_camera_csi_wrist_roll_0.stl" scale="1 1 1"/>
    <mesh name="wire_camera_csi_wrist_1_mesh" file="wire_camera_csi_wrist_1.stl" scale="1 1 1"/>
    <mesh name="wire_camera_csi_forearm_2_mesh" file="wire_camera_csi_forearm_2.stl" scale="1 1 1"/>
    <mesh name="wire_camera_csi_forearm_3_mesh" file="wire_camera_csi_forearm_3.stl" scale="1 1 1"/>
    <mesh name="wire_camera_csi_upper_arm_4_mesh" file="wire_camera_csi_upper_arm_4.stl" scale="1 1 1"/>
    <mesh name="wire_camera_csi_upper_arm_5_mesh" file="wire_camera_csi_upper_arm_5.stl" scale="1 1 1"/>
    <mesh name="wire_camera_csi_turntable_6_mesh" file="wire_camera_csi_turntable_6.stl" scale="1 1 1"/>
    <mesh name="wire_camera_csi_turntable_7_mesh" file="wire_camera_csi_turntable_7.stl" scale="1 1 1"/>
    <mesh name="wire_camera_csi_base_8_mesh" file="wire_camera_csi_base_8.stl" scale="1 1 1"/>
    <mesh name="wire_power_base_0_mesh" file="wire_power_base_0.stl" scale="1 1 1"/>
    <mesh name="wire_power_base_1_mesh" file="wire_power_base_1.stl" scale="1 1 1"/>
  </asset>
  <worldbody>
    <body name="base" pos="0 0 0.0350">
      <freejoint name="root"/>
      <inertial pos="-0.004409 -0.000000 -0.000233" mass="0.171046" fullinertia="6.573944e-05 1.401280e-04 1.218728e-04 5.563400e-08 1.063758e-05 -6.078759e-11"/>
      <geom type="mesh" mesh="base_mesh" rgba="0.0588 0.6000 0.3765 1.0000" contype="1" conaffinity="1"/>
      <site name="imu" pos="0 0 0" size="0.005"/>
      <geom name="comp_base_pi" type="mesh" mesh="comp_base_pi_mesh" pos="0.000000 0.000000 0.000000" rgba="0.0588 0.6000 0.3765 1.0000" contype="0" conaffinity="0" group="1"/>
      <geom name="comp_base_battery" type="mesh" mesh="comp_base_battery_mesh" pos="0.000000 0.000000 -0.015800" rgba="0.0745 0.4863 0.7412 1.0000" contype="0" conaffinity="0" group="1"/>
      <geom name="shoulder_pan_servo" type="mesh" mesh="servo_STS3215_mesh" pos="-0.012500 0.000000 0.015000" quat="1.000000 0.000000 0.000000 0.000000" rgba="0.0941 0.1255 0.1490 1.0000" contype="0" conaffinity="0" group="1"/>
      <geom name="screw_shoulder_pan_ear_1" type="mesh" mesh="hardware_M3_shc_mesh" pos="0.004500 -0.010250 -0.002500" rgba="0.6549 0.7137 0.7608 0.9000" contype="0" conaffinity="0" group="1" quat="0.000000 1.000000 0.000000 0.000000"/>
      <geom name="screw_shoulder_pan_ear_2" type="mesh" mesh="hardware_M3_shc_mesh" pos="-0.012500 -0.010250 -0.002500" rgba="0.6549 0.7137 0.7608 0.9000" contype="0" conaffinity="0" group="1" quat="0.000000 1.000000 0.000000 0.000000"/>
      <geom name="screw_shoulder_pan_ear_3" type="mesh" mesh="hardware_M3_shc_mesh" pos="0.004500 0.010250 -0.002500" rgba="0.6549 0.7137 0.7608 0.9000" contype="0" conaffinity="0" group="1" quat="0.000000 1.000000 0.000000 0.000000"/>
      <geom name="screw_shoulder_pan_ear_4" type="mesh" mesh="hardware_M3_shc_mesh" pos="-0.012500 0.010250 -0.002500" rgba="0.6549 0.7137 0.7608 0.9000" contype="0" conaffinity="0" group="1" quat="0.000000 1.000000 0.000000 0.000000"/>
      <geom name="screw_shoulder_pan_ear_5" type="mesh" mesh="hardware_M3_shc_mesh" pos="-0.029500 -0.010250 -0.002500" rgba="0.6549 0.7137 0.7608 0.9000" contype="0" conaffinity="0" group="1" quat="0.000000 1.000000 0.000000 0.000000"/>
      <geom name="screw_shoulder_pan_ear_6" type="mesh" mesh="hardware_M3_shc_mesh" pos="-0.029500 0.010250 -0.002500" rgba="0.6549 0.7137 0.7608 0.9000" contype="0" conaffinity="0" group="1" quat="0.000000 1.000000 0.000000 0.000000"/>
      <geom name="horn_shoulder_pan_horn_out_1" type="mesh" mesh="hardware_M2_shc_mesh" pos="0.007000 0.000000 0.031000" rgba="0.6549 0.7137 0.7608 0.9000" contype="0" conaffinity="0" group="1"/>
      <geom name="horn_shoulder_pan_horn_out_2" type="mesh" mesh="hardware_M2_shc_mesh" pos="-0.007000 0.000000 0.031000" rgba="0.6549 0.7137 0.7608 0.9000" contype="0" conaffinity="0" group="1"/>
      <geom name="horn_shoulder_pan_horn_out_3" type="mesh" mesh="hardware_M2_shc_mesh" pos="0.000000 0.007000 0.031000" rgba="0.6549 0.7137 0.7608 0.9000" contype="0" conaffinity="0" group="1"/>
      <geom name="horn_shoulder_pan_horn_out_4" type="mesh" mesh="hardware_M2_shc_mesh" pos="0.000000 -0.007000 0.031000" rgba="0.6549 0.7137 0.7608 0.9000" contype="0" conaffinity="0" group="1"/>
      <geom name="rear_shoulder_pan_horn_rear_1" type="mesh" mesh="hardware_M2_shc_mesh" pos="0.007000 0.000000 -0.001000" rgba="0.6549 0.7137 0.7608 0.9000" contype="0" conaffinity="0" group="1" quat="0.000000 1.000000 0.000000 0.000000"/>
      <geom name="rear_shoulder_pan_horn_rear_2" type="mesh" mesh="hardware_M2_shc_mesh" pos="-0.007000 0.000000 -0.001000" rgba="0.6549 0.7137 0.7608 0.9000" contype="0" conaffinity="0" group="1" quat="0.000000 1.000000 0.000000 0.000000"/>
      <geom name="rear_shoulder_pan_horn_rear_3" type="mesh" mesh="hardware_M2_shc_mesh" pos="0.000000 0.007000 -0.001000" rgba="0.6549 0.7137 0.7608 0.9000" contype="0" conaffinity="0" group="1" quat="0.000000 1.000000 0.000000 0.000000"/>
      <geom name="rear_shoulder_pan_horn_rear_4" type="mesh" mesh="hardware_M2_shc_mesh" pos="0.000000 -0.007000 -0.001000" rgba="0.6549 0.7137 0.7608 0.9000" contype="0" conaffinity="0" group="1" quat="0.000000 1.000000 0.000000 0.000000"/>
      <geom name="mount_base_pi_m1" type="mesh" mesh="hardware_M2.5_shc_mesh" pos="-0.029000 -0.011500 0.000000" rgba="0.6549 0.7137 0.7608 0.9000" contype="0" conaffinity="0" group="1" quat="0.000000 1.000000 0.000000 0.000000"/>
      <geom name="mount_base_pi_m2" type="mesh" mesh="hardware_M2.5_shc_mesh" pos="0.029000 -0.011500 0.000000" rgba="0.6549 0.7137 0.7608 0.9000" contype="0" conaffinity="0" group="1" quat="0.000000 1.000000 0.000000 0.000000"/>
      <geom name="mount_base_pi_m3" type="mesh" mesh="hardware_M2.5_shc_mesh" pos="-0.029000 0.011500 0.000000" rgba="0.6549 0.7137 0.7608 0.9000" contype="0" conaffinity="0" group="1" quat="0.000000 1.000000 0.000000 0.000000"/>
      <geom name="mount_base_pi_m4" type="mesh" mesh="hardware_M2.5_shc_mesh" pos="0.029000 0.011500 0.000000" rgba="0.6549 0.7137 0.7608 0.9000" contype="0" conaffinity="0" group="1" quat="0.000000 1.000000 0.000000 0.000000"/>
      <geom name="wire_servo_bus_base_0" type="mesh" mesh="wire_servo_bus_base_0_mesh" pos="0 0 0" rgba="0.1686 0.5843 0.8392 0.9000" contype="0" conaffinity="0" group="2"/>
      <geom name="wire_camera_csi_base_8" type="mesh" mesh="wire_camera_csi_base_8_mesh" pos="0 0 0" rgba="1.0000 0.7882 0.2510 0.9000" contype="0" conaffinity="0" group="2"/>
      <geom name="wire_power_base_0" type="mesh" mesh="wire_power_base_0_mesh" pos="0 0 0" rgba="0.8588 0.2157 0.2157 0.9000" contype="0" conaffinity="0" group="2"/>
      <geom name="wire_power_base_1" type="mesh" mesh="wire_power_base_1_mesh" pos="0 0 0" rgba="0.8588 0.2157 0.2157 0.9000" contype="0" conaffinity="0" group="2"/>
      <body name="turntable" pos="0.000000 0.000000 0.031000">
        <inertial pos="-0.010312 -0.000000 0.016999" mass="0.090603" fullinertia="5.939619e-05 7.529475e-05 3.095086e-05 7.104867e-22 9.238215e-06 -1.274052e-21"/>
        <joint name="shoulder_pan" type="hinge" pos="0 0 0" axis="0.000000 0.000000 1.000000" damping="0.6237" range="-1.9200 1.9200"/>
        <geom name="shoulder_pan_horn_disc" type="mesh" mesh="horn_shoulder_pan_mesh" pos="0.000000 0.000000 0.004000" rgba="0.8824 0.9098 0.9294 0.9000" contype="0" conaffinity="0" group="1"/>
        <geom type="mesh" mesh="turntable_mesh" rgba="0.8078 0.8510 0.8784 1.0000" contype="1" conaffinity="1"/>
        <geom name="shoulder_lift_servo" type="mesh" mesh="servo_STS3215_mesh" pos="-0.016000 0.000000 0.032500" quat="0.707107 0.000000 0.707107 0.000000" rgba="0.0941 0.1255 0.1490 1.0000" contype="0" conaffinity="0" group="1"/>
        <geom name="screw_shoulder_lift_ear_1" type="mesh" mesh="hardware_M3_shc_mesh" pos="-0.033500 -0.010250 0.015500" rgba="0.6549 0.7137 0.7608 0.9000" contype="0" conaffinity="0" group="1" quat="0.707107 -0.000000 -0.707107 0.000000"/>
        <geom name="screw_shoulder_lift_ear_2" type="mesh" mesh="hardware_M3_shc_mesh" pos="-0.033500 -0.010250 0.032500" rgba="0.6549 0.7137 0.7608 0.9000" contype="0" conaffinity="0" group="1" quat="0.707107 -0.000000 -0.707107 0.000000"/>
        <geom name="screw_shoulder_lift_ear_3" type="mesh" mesh="hardware_M3_shc_mesh" pos="-0.033500 0.010250 0.015500" rgba="0.6549 0.7137 0.7608 0.9000" contype="0" conaffinity="0" group="1" quat="0.707107 -0.000000 -0.707107 0.000000"/>
        <geom name="screw_shoulder_lift_ear_4" type="mesh" mesh="hardware_M3_shc_mesh" pos="-0.033500 0.010250 0.032500" rgba="0.6549 0.7137 0.7608 0.9000" contype="0" conaffinity="0" group="1" quat="0.707107 -0.000000 -0.707107 0.000000"/>
        <geom name="screw_shoulder_lift_ear_5" type="mesh" mesh="hardware_M3_shc_mesh" pos="-0.033500 -0.010250 0.049500" rgba="0.6549 0.7137 0.7608 0.9000" contype="0" conaffinity="0" group="1" quat="0.707107 -0.000000 -0.707107 0.000000"/>
        <geom name="screw_shoulder_lift_ear_6" type="mesh" mesh="hardware_M3_shc_mesh" pos="-0.033500 0.010250 0.049500" rgba="0.6549 0.7137 0.7608 0.9000" contype="0" conaffinity="0" group="1" quat="0.707107 -0.000000 -0.707107 0.000000"/>
        <geom name="horn_shoulder_lift_horn_out_1" type="mesh" mesh="hardware_M2_shc_mesh" pos="0.000000 0.000000 0.013000" rgba="0.6549 0.7137 0.7608 0.9000" contype="0" conaffinity="0" group="1" quat="0.707107 0.000000 0.707107 0.000000"/>
        <geom name="horn_shoulder_lift_horn_out_2" type="mesh" mesh="hardware_M2_shc_mesh" pos="0.000000 0.000000 0.027000" rgba="0.6549 0.7137 0.7608 0.9000" contype="0" conaffinity="0" group="1" quat="0.707107 0.000000 0.707107 0.000000"/>
        <geom name="horn_shoulder_lift_horn_out_3" type="mesh" mesh="hardware_M2_shc_mesh" pos="0.000000 0.007000 0.020000" rgba="0.6549 0.7137 0.7608 0.9000" contype="0" conaffinity="0" group="1" quat="0.707107 0.000000 0.707107 0.000000"/>
        <geom name="horn_shoulder_lift_horn_out_4" type="mesh" mesh="hardware_M2_shc_mesh" pos="0.000000 -0.007000 0.020000" rgba="0.6549 0.7137 0.7608 0.9000" contype="0" conaffinity="0" group="1" quat="0.707107 0.000000 0.707107 0.000000"/>
        <geom name="rear_shoulder_lift_horn_rear_1" type="mesh" mesh="hardware_M2_shc_mesh" pos="-0.032000 0.000000 0.013000" rgba="0.6549 0.7137 0.7608 0.9000" contype="0" conaffinity="0" group="1" quat="0.707107 -0.000000 -0.707107 0.000000"/>
        <geom name="rear_shoulder_lift_horn_rear_2" type="mesh" mesh="hardware_M2_shc_mesh" pos="-0.032000 0.000000 0.027000" rgba="0.6549 0.7137 0.7608 0.9000" contype="0" conaffinity="0" group="1" quat="0.707107 -0.000000 -0.707107 0.000000"/>
        <geom name="rear_shoulder_lift_horn_rear_3" type="mesh" mesh="hardware_M2_shc_mesh" pos="-0.032000 0.007000 0.020000" rgba="0.6549 0.7137 0.7608 0.9000" contype="0" conaffinity="0" group="1" quat="0.707107 -0.000000 -0.707107 0.000000"/>
        <geom name="rear_shoulder_lift_horn_rear_4" type="mesh" mesh="hardware_M2_shc_mesh" pos="-0.032000 -0.007000 0.020000" rgba="0.6549 0.7137 0.7608 0.9000" contype="0" conaffinity="0" group="1" quat="0.707107 -0.000000 -0.707107 0.000000"/>
        <geom name="wire_servo_bus_turntable_1" type="mesh" mesh="wire_servo_bus_turntable_1_mesh" pos="0 0 0" rgba="0.1686 0.5843 0.8392 0.9000" contype="0" conaffinity="0" group="2"/>
        <geom name="wire_servo_bus_turntable_2" type="mesh" mesh="wire_servo_bus_turntable_2_mesh" pos="0 0 0" rgba="0.1686 0.5843 0.8392 0.9000" contype="0" conaffinity="0" group="2"/>
        <geom name="wire_camera_csi_turntable_6" type="mesh" mesh="wire_camera_csi_turntable_6_mesh" pos="0 0 0" rgba="1.0000 0.7882 0.2510 0.9000" contype="0" conaffinity="0" group="2"/>
        <geom name="wire_camera_csi_turntable_7" type="mesh" mesh="wire_camera_csi_turntable_7_mesh" pos="0 0 0" rgba="1.0000 0.7882 0.2510 0.9000" contype="0" conaffinity="0" group="2"/>
        <body name="upper_arm" pos="0.000000 0.000000 0.020000">
          <inertial pos="-0.010633 -0.000000 0.091940" mass="0.102157" fullinertia="2.345392e-04 2.520608e-04 3.059408e-05 -2.673538e-13 3.017715e-05 -3.799942e-12"/>
          <joint name="shoulder_lift" type="hinge" pos="0 0 0" axis="1.000000 0.000000 0.000000" damping="0.6237" range="-1.7450 1.7450"/>
          <geom name="shoulder_lift_horn_disc" type="mesh" mesh="horn_shoulder_lift_mesh" pos="0.004000 0.000000 0.000000" rgba="0.8824 0.9098 0.9294 0.9000" contype="0" conaffinity="0" group="1"/>
          <geom type="mesh" mesh="upper_arm_mesh" rgba="0.7490 0.8000 0.8392 1.0000" contype="1" conaffinity="1"/>
          <geom name="elbow_flex_servo" type="mesh" mesh="servo_STS3215_mesh" pos="-0.016000 0.000000 0.128500" quat="0.707107 0.000000 0.707107 0.000000" rgba="0.0941 0.1255 0.1490 1.0000" contype="0" conaffinity="0" group="1"/>
          <geom name="screw_elbow_flex_ear_1" type="mesh" mesh="hardware_M3_shc_mesh" pos="-0.033500 -0.010250 0.111500" rgba="0.6549 0.7137 0.7608 0.9000" contype="0" conaffinity="0" group="1" quat="0.707107 -0.000000 -0.707107 0.000000"/>
          <geom name="screw_elbow_flex_ear_2" type="mesh" mesh="hardware_M3_shc_mesh" pos="-0.033500 -0.010250 0.128500" rgba="0.6549 0.7137 0.7608 0.9000" contype="0" conaffinity="0" group="1" quat="0.707107 -0.000000 -0.707107 0.000000"/>
          <geom name="screw_elbow_flex_ear_3" type="mesh" mesh="hardware_M3_shc_mesh" pos="-0.033500 0.010250 0.111500" rgba="0.6549 0.7137 0.7608 0.9000" contype="0" conaffinity="0" group="1" quat="0.707107 -0.000000 -0.707107 0.000000"/>
          <geom name="screw_elbow_flex_ear_4" type="mesh" mesh="hardware_M3_shc_mesh" pos="-0.033500 0.010250 0.128500" rgba="0.6549 0.7137 0.7608 0.9000" contype="0" conaffinity="0" group="1" quat="0.707107 -0.000000 -0.707107 0.000000"/>
          <geom name="screw_elbow_flex_ear_5" type="mesh" mesh="hardware_M3_shc_mesh" pos="-0.033500 -0.010250 0.145500" rgba="0.6549 0.7137 0.7608 0.9000" contype="0" conaffinity="0" group="1" quat="0.707107 -0.000000 -0.707107 0.000000"/>
          <geom name="screw_elbow_flex_ear_6" type="mesh" mesh="hardware_M3_shc_mesh" pos="-0.033500 0.010250 0.145500" rgba="0.6549 0.7137 0.7608 0.9000" contype="0" conaffinity="0" group="1" quat="0.707107 -0.000000 -0.707107 0.000000"/>
          <geom name="horn_elbow_flex_horn_out_1" type="mesh" mesh="hardware_M2_shc_mesh" pos="0.000000 0.000000 0.109000" rgba="0.6549 0.7137 0.7608 0.9000" contype="0" conaffinity="0" group="1" quat="0.707107 0.000000 0.707107 0.000000"/>
          <geom name="horn_elbow_flex_horn_out_2" type="mesh" mesh="hardware_M2_shc_mesh" pos="0.000000 0.000000 0.123000" rgba="0.6549 0.7137 0.7608 0.9000" contype="0" conaffinity="0" group="1" quat="0.707107 0.000000 0.707107 0.000000"/>
          <geom name="horn_elbow_flex_horn_out_3" type="mesh" mesh="hardware_M2_shc_mesh" pos="0.000000 0.007000 0.116000" rgba="0.6549 0.7137 0.7608 0.9000" contype="0" conaffinity="0" group="1" quat="0.707107 0.000000 0.707107 0.000000"/>
          <geom name="horn_elbow_flex_horn_out_4" type="mesh" mesh="hardware_M2_shc_mesh" pos="0.000000 -0.007000 0.116000" rgba="0.6549 0.7137 0.7608 0.9000" contype="0" conaffinity="0" group="1" quat="0.707107 0.000000 0.707107 0.000000"/>
          <geom name="rear_elbow_flex_horn_rear_1" type="mesh" mesh="hardware_M2_shc_mesh" pos="-0.032000 0.000000 0.109000" rgba="0.6549 0.7137 0.7608 0.9000" contype="0" conaffinity="0" group="1" quat="0.707107 -0.000000 -0.707107 0.000000"/>
          <geom name="rear_elbow_flex_horn_rear_2" type="mesh" mesh="hardware_M2_shc_mesh" pos="-0.032000 0.000000 0.123000" rgba="0.6549 0.7137 0.7608 0.9000" contype="0" conaffinity="0" group="1" quat="0.707107 -0.000000 -0.707107 0.000000"/>
          <geom name="rear_elbow_flex_horn_rear_3" type="mesh" mesh="hardware_M2_shc_mesh" pos="-0.032000 0.007000 0.116000" rgba="0.6549 0.7137 0.7608 0.9000" contype="0" conaffinity="0" group="1" quat="0.707107 -0.000000 -0.707107 0.000000"/>
          <geom name="rear_elbow_flex_horn_rear_4" type="mesh" mesh="hardware_M2_shc_mesh" pos="-0.032000 -0.007000 0.116000" rgba="0.6549 0.7137 0.7608 0.9000" contype="0" conaffinity="0" group="1" quat="0.707107 -0.000000 -0.707107 0.000000"/>
          <geom name="wire_servo_bus_upper_arm_3" type="mesh" mesh="wire_servo_bus_upper_arm_3_mesh" pos="0 0 0" rgba="0.1686 0.5843 0.8392 0.9000" contype="0" conaffinity="0" group="2"/>
          <geom name="wire_servo_bus_upper_arm_4" type="mesh" mesh="wire_servo_bus_upper_arm_4_mesh" pos="0 0 0" rgba="0.1686 0.5843 0.8392 0.9000" contype="0" conaffinity="0" group="2"/>
          <geom name="wire_camera_csi_upper_arm_4" type="mesh" mesh="wire_camera_csi_upper_arm_4_mesh" pos="0 0 0" rgba="1.0000 0.7882 0.2510 0.9000" contype="0" conaffinity="0" group="2"/>
          <geom name="wire_camera_csi_upper_arm_5" type="mesh" mesh="wire_camera_csi_upper_arm_5_mesh" pos="0 0 0" rgba="1.0000 0.7882 0.2510 0.9000" contype="0" conaffinity="0" group="2"/>
          <body name="forearm" pos="0.000000 0.000000 0.116000">
            <inertial pos="-0.011278 -0.000000 0.105639" mass="0.095229" fullinertia="2.969812e-04 3.143858e-04 2.805991e-05 -1.725981e-22 3.375506e-05 -4.622950e-21"/>
            <joint name="elbow_flex" type="hinge" pos="0 0 0" axis="1.000000 0.000000 0.000000" damping="0.6237" range="-1.6900 1.6900"/>
            <geom name="elbow_flex_horn_disc" type="mesh" mesh="horn_elbow_flex_mesh" pos="0.004000 0.000000 0.000000" rgba="0.8824 0.9098 0.9294 0.9000" contype="0" conaffinity="0" group="1"/>
            <geom type="mesh" mesh="forearm_mesh" rgba="0.7490 0.8000 0.8392 1.0000" contype="1" conaffinity="1"/>
            <geom name="wrist_flex_servo" type="mesh" mesh="servo_STS3215_mesh" pos="-0.016000 0.000000 0.147500" quat="0.707107 0.000000 0.707107 0.000000" rgba="0.0941 0.1255 0.1490 1.0000" contype="0" conaffinity="0" group="1"/>
            <geom name="screw_wrist_flex_ear_1" type="mesh" mesh="hardware_M3_shc_mesh" pos="-0.033500 -0.010250 0.130500" rgba="0.6549 0.7137 0.7608 0.9000" contype="0" conaffinity="0" group="1" quat="0.707107 -0.000000 -0.707107 0.000000"/>
            <geom name="screw_wrist_flex_ear_2" type="mesh" mesh="hardware_M3_shc_mesh" pos="-0.033500 -0.010250 0.147500" rgba="0.6549 0.7137 0.7608 0.9000" contype="0" conaffinity="0" group="1" quat="0.707107 -0.000000 -0.707107 0.000000"/>
            <geom name="screw_wrist_flex_ear_3" type="mesh" mesh="hardware_M3_shc_mesh" pos="-0.033500 0.010250 0.130500" rgba="0.6549 0.7137 0.7608 0.9000" contype="0" conaffinity="0" group="1" quat="0.707107 -0.000000 -0.707107 0.000000"/>
            <geom name="screw_wrist_flex_ear_4" type="mesh" mesh="hardware_M3_shc_mesh" pos="-0.033500 0.010250 0.147500" rgba="0.6549 0.7137 0.7608 0.9000" contype="0" conaffinity="0" group="1" quat="0.707107 -0.000000 -0.707107 0.000000"/>
            <geom name="screw_wrist_flex_ear_5" type="mesh" mesh="hardware_M3_shc_mesh" pos="-0.033500 -0.010250 0.164500" rgba="0.6549 0.7137 0.7608 0.9000" contype="0" conaffinity="0" group="1" quat="0.707107 -0.000000 -0.707107 0.000000"/>
            <geom name="screw_wrist_flex_ear_6" type="mesh" mesh="hardware_M3_shc_mesh" pos="-0.033500 0.010250 0.164500" rgba="0.6549 0.7137 0.7608 0.9000" contype="0" conaffinity="0" group="1" quat="0.707107 -0.000000 -0.707107 0.000000"/>
            <geom name="horn_wrist_flex_horn_out_1" type="mesh" mesh="hardware_M2_shc_mesh" pos="0.000000 0.000000 0.128000" rgba="0.6549 0.7137 0.7608 0.9000" contype="0" conaffinity="0" group="1" quat="0.707107 0.000000 0.707107 0.000000"/>
            <geom name="horn_wrist_flex_horn_out_2" type="mesh" mesh="hardware_M2_shc_mesh" pos="0.000000 0.000000 0.142000" rgba="0.6549 0.7137 0.7608 0.9000" contype="0" conaffinity="0" group="1" quat="0.707107 0.000000 0.707107 0.000000"/>
            <geom name="horn_wrist_flex_horn_out_3" type="mesh" mesh="hardware_M2_shc_mesh" pos="0.000000 0.007000 0.135000" rgba="0.6549 0.7137 0.7608 0.9000" contype="0" conaffinity="0" group="1" quat="0.707107 0.000000 0.707107 0.000000"/>
            <geom name="horn_wrist_flex_horn_out_4" type="mesh" mesh="hardware_M2_shc_mesh" pos="0.000000 -0.007000 0.135000" rgba="0.6549 0.7137 0.7608 0.9000" contype="0" conaffinity="0" group="1" quat="0.707107 0.000000 0.707107 0.000000"/>
            <geom name="rear_wrist_flex_horn_rear_1" type="mesh" mesh="hardware_M2_shc_mesh" pos="-0.032000 0.000000 0.128000" rgba="0.6549 0.7137 0.7608 0.9000" contype="0" conaffinity="0" group="1" quat="0.707107 -0.000000 -0.707107 0.000000"/>
            <geom name="rear_wrist_flex_horn_rear_2" type="mesh" mesh="hardware_M2_shc_mesh" pos="-0.032000 0.000000 0.142000" rgba="0.6549 0.7137 0.7608 0.9000" contype="0" conaffinity="0" group="1" quat="0.707107 -0.000000 -0.707107 0.000000"/>
            <geom name="rear_wrist_flex_horn_rear_3" type="mesh" mesh="hardware_M2_shc_mesh" pos="-0.032000 0.007000 0.135000" rgba="0.6549 0.7137 0.7608 0.9000" contype="0" conaffinity="0" group="1" quat="0.707107 -0.000000 -0.707107 0.000000"/>
            <geom name="rear_wrist_flex_horn_rear_4" type="mesh" mesh="hardware_M2_shc_mesh" pos="-0.032000 -0.007000 0.135000" rgba="0.6549 0.7137 0.7608 0.9000" contype="0" conaffinity="0" group="1" quat="0.707107 -0.000000 -0.707107 0.000000"/>
            <geom name="wire_servo_bus_forearm_5" type="mesh" mesh="wire_servo_bus_forearm_5_mesh" pos="0 0 0" rgba="0.1686 0.5843 0.8392 0.9000" contype="0" conaffinity="0" group="2"/>
            <geom name="wire_servo_bus_forearm_6" type="mesh" mesh="wire_servo_bus_forearm_6_mesh" pos="0 0 0" rgba="0.1686 0.5843 0.8392 0.9000" contype="0" conaffinity="0" group="2"/>
            <geom name="wire_camera_csi_forearm_2" type="mesh" mesh="wire_camera_csi_forearm_2_mesh" pos="0 0 0" rgba="1.0000 0.7882 0.2510 0.9000" contype="0" conaffinity="0" group="2"/>
            <geom name="wire_camera_csi_forearm_3" type="mesh" mesh="wire_camera_csi_forearm_3_mesh" pos="0 0 0" rgba="1.0000 0.7882 0.2510 0.9000" contype="0" conaffinity="0" group="2"/>
            <body name="wrist" pos="0.000000 0.000000 0.135000">
              <inertial pos="-0.011392 -0.000004 0.006788" mass="0.087654" fullinertia="3.111533e-05 4.963241e-05 3.095033e-05 -4.998851e-09 -1.742345e-06 -1.591877e-08"/>
              <joint name="wrist_flex" type="hinge" pos="0 0 0" axis="1.000000 0.000000 0.000000" damping="0.6237" range="-1.6580 1.6580"/>
              <geom name="wrist_flex_horn_disc" type="mesh" mesh="horn_wrist_flex_mesh" pos="0.004000 0.000000 0.000000" rgba="0.8824 0.9098 0.9294 0.9000" contype="0" conaffinity="0" group="1"/>
              <geom type="mesh" mesh="wrist_mesh" rgba="0.8078 0.8510 0.8784 1.0000" contype="1" conaffinity="1"/>
              <geom name="wrist_roll_servo" type="mesh" mesh="servo_STS3215_mesh" pos="-0.012500 0.000000 0.016000" quat="1.000000 0.000000 0.000000 0.000000" rgba="0.0941 0.1255 0.1490 1.0000" contype="0" conaffinity="0" group="1"/>
              <geom name="screw_wrist_roll_ear_1" type="mesh" mesh="hardware_M3_shc_mesh" pos="0.004500 -0.010250 -0.001500" rgba="0.6549 0.7137 0.7608 0.9000" contype="0" conaffinity="0" group="1" quat="0.000000 1.000000 0.000000 0.000000"/>
              <geom name="screw_wrist_roll_ear_2" type="mesh" mesh="hardware_M3_shc_mesh" pos="-0.012500 -0.010250 -0.001500" rgba="0.6549 0.7137 0.7608 0.9000" contype="0" conaffinity="0" group="1" quat="0.000000 1.000000 0.000000 0.000000"/>
              <geom name="screw_wrist_roll_ear_3" type="mesh" mesh="hardware_M3_shc_mesh" pos="0.004500 0.010250 -0.001500" rgba="0.6549 0.7137 0.7608 0.9000" contype="0" conaffinity="0" group="1" quat="0.000000 1.000000 0.000000 0.000000"/>
              <geom name="screw_wrist_roll_ear_4" type="mesh" mesh="hardware_M3_shc_mesh" pos="-0.012500 0.010250 -0.001500" rgba="0.6549 0.7137 0.7608 0.9000" contype="0" conaffinity="0" group="1" quat="0.000000 1.000000 0.000000 0.000000"/>
              <geom name="screw_wrist_roll_ear_5" type="mesh" mesh="hardware_M3_shc_mesh" pos="-0.029500 -0.010250 -0.001500" rgba="0.6549 0.7137 0.7608 0.9000" contype="0" conaffinity="0" group="1" quat="0.000000 1.000000 0.000000 0.000000"/>
              <geom name="screw_wrist_roll_ear_6" type="mesh" mesh="hardware_M3_shc_mesh" pos="-0.029500 0.010250 -0.001500" rgba="0.6549 0.7137 0.7608 0.9000" contype="0" conaffinity="0" group="1" quat="0.000000 1.000000 0.000000 0.000000"/>
              <geom name="horn_wrist_roll_horn_out_1" type="mesh" mesh="hardware_M2_shc_mesh" pos="0.007000 0.000000 0.032000" rgba="0.6549 0.7137 0.7608 0.9000" contype="0" conaffinity="0" group="1"/>
              <geom name="horn_wrist_roll_horn_out_2" type="mesh" mesh="hardware_M2_shc_mesh" pos="-0.007000 0.000000 0.032000" rgba="0.6549 0.7137 0.7608 0.9000" contype="0" conaffinity="0" group="1"/>
              <geom name="horn_wrist_roll_horn_out_3" type="mesh" mesh="hardware_M2_shc_mesh" pos="0.000000 0.007000 0.032000" rgba="0.6549 0.7137 0.7608 0.9000" contype="0" conaffinity="0" group="1"/>
              <geom name="horn_wrist_roll_horn_out_4" type="mesh" mesh="hardware_M2_shc_mesh" pos="0.000000 -0.007000 0.032000" rgba="0.6549 0.7137 0.7608 0.9000" contype="0" conaffinity="0" group="1"/>
              <geom name="rear_wrist_roll_horn_rear_1" type="mesh" mesh="hardware_M2_shc_mesh" pos="0.007000 0.000000 0.000000" rgba="0.6549 0.7137 0.7608 0.9000" contype="0" conaffinity="0" group="1" quat="0.000000 1.000000 0.000000 0.000000"/>
              <geom name="rear_wrist_roll_horn_rear_2" type="mesh" mesh="hardware_M2_shc_mesh" pos="-0.007000 0.000000 0.000000" rgba="0.6549 0.7137 0.7608 0.9000" contype="0" conaffinity="0" group="1" quat="0.000000 1.000000 0.000000 0.000000"/>
              <geom name="rear_wrist_roll_horn_rear_3" type="mesh" mesh="hardware_M2_shc_mesh" pos="0.000000 0.007000 0.000000" rgba="0.6549 0.7137 0.7608 0.9000" contype="0" conaffinity="0" group="1" quat="0.000000 1.000000 0.000000 0.000000"/>
              <geom name="rear_wrist_roll_horn_rear_4" type="mesh" mesh="hardware_M2_shc_mesh" pos="0.000000 -0.007000 0.000000" rgba="0.6549 0.7137 0.7608 0.9000" contype="0" conaffinity="0" group="1" quat="0.000000 1.000000 0.000000 0.000000"/>
              <geom name="wire_servo_bus_wrist_7" type="mesh" mesh="wire_servo_bus_wrist_7_mesh" pos="0 0 0" rgba="0.1686 0.5843 0.8392 0.9000" contype="0" conaffinity="0" group="2"/>
              <geom name="wire_camera_csi_wrist_1" type="mesh" mesh="wire_camera_csi_wrist_1_mesh" pos="0 0 0" rgba="1.0000 0.7882 0.2510 0.9000" contype="0" conaffinity="0" group="2"/>
              <body name="wrist_roll" pos="0.000000 0.000000 0.032000">
                <inertial pos="-0.012430 -0.000060 0.022427" mass="0.074257" fullinertia="2.768519e-05 3.722828e-05 1.941901e-05 -6.849009e-08 4.905581e-06 -1.454871e-07"/>
                <joint name="wrist_roll" type="hinge" pos="0 0 0" axis="0.000000 0.000000 1.000000" damping="0.6237" range="-2.7440 2.8410"/>
                <geom name="wrist_roll_horn_disc" type="mesh" mesh="horn_wrist_roll_mesh" pos="0.000000 0.000000 0.004000" rgba="0.8824 0.9098 0.9294 0.9000" contype="0" conaffinity="0" group="1"/>
                <geom type="mesh" mesh="wrist_roll_mesh" rgba="0.0392 0.4000 0.2510 1.0000" contype="1" conaffinity="1"/>
                <camera name="camera_cam" fovy="62.2" pos="0.000000 0.004500 0.000000" euler="1.5707963267948966 0 0"/>
                <geom name="comp_wrist_roll_camera" type="mesh" mesh="comp_wrist_roll_camera_mesh" pos="0.000000 0.004500 0.000000" rgba="0.0392 0.4000 0.2510 1.0000" contype="0" conaffinity="0" group="1"/>
                <geom name="gripper_servo" type="mesh" mesh="servo_STS3215_mesh" pos="-0.016000 0.000000 0.030500" quat="0.707107 0.000000 0.707107 0.000000" rgba="0.0941 0.1255 0.1490 1.0000" contype="0" conaffinity="0" group="1"/>
                <geom name="screw_gripper_ear_1" type="mesh" mesh="hardware_M3_shc_mesh" pos="-0.033500 -0.010250 0.013500" rgba="0.6549 0.7137 0.7608 0.9000" contype="0" conaffinity="0" group="1" quat="0.707107 -0.000000 -0.707107 0.000000"/>
                <geom name="screw_gripper_ear_2" type="mesh" mesh="hardware_M3_shc_mesh" pos="-0.033500 -0.010250 0.030500" rgba="0.6549 0.7137 0.7608 0.9000" contype="0" conaffinity="0" group="1" quat="0.707107 -0.000000 -0.707107 0.000000"/>
                <geom name="screw_gripper_ear_3" type="mesh" mesh="hardware_M3_shc_mesh" pos="-0.033500 0.010250 0.013500" rgba="0.6549 0.7137 0.7608 0.9000" contype="0" conaffinity="0" group="1" quat="0.707107 -0.000000 -0.707107 0.000000"/>
                <geom name="screw_gripper_ear_4" type="mesh" mesh="hardware_M3_shc_mesh" pos="-0.033500 0.010250 0.030500" rgba="0.6549 0.7137 0.7608 0.9000" contype="0" conaffinity="0" group="1" quat="0.707107 -0.000000 -0.707107 0.000000"/>
                <geom name="screw_gripper_ear_5" type="mesh" mesh="hardware_M3_shc_mesh" pos="-0.033500 -0.010250 0.047500" rgba="0.6549 0.7137 0.7608 0.9000" contype="0" conaffinity="0" group="1" quat="0.707107 -0.000000 -0.707107 0.000000"/>
                <geom name="screw_gripper_ear_6" type="mesh" mesh="hardware_M3_shc_mesh" pos="-0.033500 0.010250 0.047500" rgba="0.6549 0.7137 0.7608 0.9000" contype="0" conaffinity="0" group="1" quat="0.707107 -0.000000 -0.707107 0.000000"/>
                <geom name="horn_gripper_horn_out_1" type="mesh" mesh="hardware_M2_shc_mesh" pos="0.000000 0.000000 0.011000" rgba="0.6549 0.7137 0.7608 0.9000" contype="0" conaffinity="0" group="1" quat="0.707107 0.000000 0.707107 0.000000"/>
                <geom name="horn_gripper_horn_out_2" type="mesh" mesh="hardware_M2_shc_mesh" pos="0.000000 0.000000 0.025000" rgba="0.6549 0.7137 0.7608 0.9000" contype="0" conaffinity="0" group="1" quat="0.707107 0.000000 0.707107 0.000000"/>
                <geom name="horn_gripper_horn_out_3" type="mesh" mesh="hardware_M2_shc_mesh" pos="0.000000 0.007000 0.018000" rgba="0.6549 0.7137 0.7608 0.9000" contype="0" conaffinity="0" group="1" quat="0.707107 0.000000 0.707107 0.000000"/>
                <geom name="horn_gripper_horn_out_4" type="mesh" mesh="hardware_M2_shc_mesh" pos="0.000000 -0.007000 0.018000" rgba="0.6549 0.7137 0.7608 0.9000" contype="0" conaffinity="0" group="1" quat="0.707107 0.000000 0.707107 0.000000"/>
                <geom name="rear_gripper_horn_rear_1" type="mesh" mesh="hardware_M2_shc_mesh" pos="-0.032000 0.000000 0.011000" rgba="0.6549 0.7137 0.7608 0.9000" contype="0" conaffinity="0" group="1" quat="0.707107 -0.000000 -0.707107 0.000000"/>
                <geom name="rear_gripper_horn_rear_2" type="mesh" mesh="hardware_M2_shc_mesh" pos="-0.032000 0.000000 0.025000" rgba="0.6549 0.7137 0.7608 0.9000" contype="0" conaffinity="0" group="1" quat="0.707107 -0.000000 -0.707107 0.000000"/>
                <geom name="rear_gripper_horn_rear_3" type="mesh" mesh="hardware_M2_shc_mesh" pos="-0.032000 0.007000 0.018000" rgba="0.6549 0.7137 0.7608 0.9000" contype="0" conaffinity="0" group="1" quat="0.707107 -0.000000 -0.707107 0.000000"/>
                <geom name="rear_gripper_horn_rear_4" type="mesh" mesh="hardware_M2_shc_mesh" pos="-0.032000 -0.007000 0.018000" rgba="0.6549 0.7137 0.7608 0.9000" contype="0" conaffinity="0" group="1" quat="0.707107 -0.000000 -0.707107 0.000000"/>
                <geom name="mount_wrist_roll_camera_m1" type="mesh" mesh="hardware_M2_shc_mesh" pos="-0.010500 -0.005000 0.000000" rgba="0.6549 0.7137 0.7608 0.9000" contype="0" conaffinity="0" group="1" quat="0.000000 1.000000 0.000000 0.000000"/>
                <geom name="mount_wrist_roll_camera_m2" type="mesh" mesh="hardware_M2_shc_mesh" pos="0.010500 -0.005000 0.000000" rgba="0.6549 0.7137 0.7608 0.9000" contype="0" conaffinity="0" group="1" quat="0.000000 1.000000 0.000000 0.000000"/>
                <geom name="mount_wrist_roll_camera_m3" type="mesh" mesh="hardware_M2_shc_mesh" pos="-0.010500 0.007500 0.000000" rgba="0.6549 0.7137 0.7608 0.9000" contype="0" conaffinity="0" group="1" quat="0.000000 1.000000 0.000000 0.000000"/>
                <geom name="mount_wrist_roll_camera_m4" type="mesh" mesh="hardware_M2_shc_mesh" pos="0.010500 0.007500 0.000000" rgba="0.6549 0.7137 0.7608 0.9000" contype="0" conaffinity="0" group="1" quat="0.000000 1.000000 0.000000 0.000000"/>
                <geom name="wire_servo_bus_wrist_roll_8" type="mesh" mesh="wire_servo_bus_wrist_roll_8_mesh" pos="0 0 0" rgba="0.1686 0.5843 0.8392 0.9000" contype="0" conaffinity="0" group="2"/>
                <geom name="wire_servo_bus_wrist_roll_9" type="mesh" mesh="wire_servo_bus_wrist_roll_9_mesh" pos="0 0 0" rgba="0.1686 0.5843 0.8392 0.9000" contype="0" conaffinity="0" group="2"/>
                <geom name="wire_camera_csi_wrist_roll_0" type="mesh" mesh="wire_camera_csi_wrist_roll_0_mesh" pos="0 0 0" rgba="1.0000 0.7882 0.2510 0.9000" contype="0" conaffinity="0" group="2"/>
                <body name="jaw" pos="0.000000 0.000000 0.018000">
                  <inertial pos="-0.022194 0.000000 0.001994" mass="0.013066" fullinertia="2.883888e-06 9.712723e-06 7.374901e-06 -1.003683e-22 1.909087e-06 3.744923e-23"/>
                  <joint name="gripper" type="hinge" pos="0 0 0" axis="1.000000 0.000000 0.000000" damping="0.6237" range="-0.1750 1.7450"/>
                  <geom name="gripper_horn_disc" type="mesh" mesh="horn_gripper_mesh" pos="0.004000 0.000000 0.000000" rgba="0.8824 0.9098 0.9294 0.9000" contype="0" conaffinity="0" group="1"/>
                  <geom type="mesh" mesh="jaw_mesh" rgba="0.8078 0.8510 0.8784 1.0000" contype="1" conaffinity="1"/>
                </body>
              </body>
            </body>
          </body>
        </body>
      </body>
    </body>
  </worldbody>
  <contact>
    <exclude body1="base" body2="forearm"/>
    <exclude body1="base" body2="turntable"/>
    <exclude body1="base" body2="upper_arm"/>
    <exclude body1="forearm" body2="jaw"/>
    <exclude body1="forearm" body2="wrist"/>
    <exclude body1="forearm" body2="wrist_roll"/>
    <exclude body1="turntable" body2="forearm"/>
    <exclude body1="turntable" body2="upper_arm"/>
    <exclude body1="turntable" body2="wrist"/>
    <exclude body1="upper_arm" body2="forearm"/>
    <exclude body1="upper_arm" body2="wrist"/>
    <exclude body1="upper_arm" body2="wrist_roll"/>
    <exclude body1="wrist" body2="jaw"/>
    <exclude body1="wrist" body2="wrist_roll"/>
    <exclude body1="wrist_roll" body2="jaw"/>
  </contact>
  <actuator>
    <position name="shoulder_pan_motor" joint="shoulder_pan" kp="58.8" ctrlrange="-1.9200 1.9200" forcerange="-2.94 2.94"/>
    <position name="shoulder_lift_motor" joint="shoulder_lift" kp="58.8" ctrlrange="-1.7450 1.7450" forcerange="-2.94 2.94"/>
    <position name="elbow_flex_motor" joint="elbow_flex" kp="58.8" ctrlrange="-1.6900 1.6900" forcerange="-2.94 2.94"/>
    <position name="wrist_flex_motor" joint="wrist_flex" kp="58.8" ctrlrange="-1.6580 1.6580" forcerange="-2.94 2.94"/>
    <position name="wrist_roll_motor" joint="wrist_roll" kp="58.8" ctrlrange="-2.7440 2.8410" forcerange="-2.94 2.94"/>
    <position name="gripper_motor" joint="gripper" kp="17.7" ctrlrange="-0.1750 1.7450" forcerange="-0.59 0.59"/>
  </actuator>
  <sensor>
    <jointpos name="shoulder_pan_pos_sensor" joint="shoulder_pan"/>
    <jointvel name="shoulder_pan_vel_sensor" joint="shoulder_pan"/>
    <jointpos name="shoulder_lift_pos_sensor" joint="shoulder_lift"/>
    <jointvel name="shoulder_lift_vel_sensor" joint="shoulder_lift"/>
    <jointpos name="elbow_flex_pos_sensor" joint="elbow_flex"/>
    <jointvel name="elbow_flex_vel_sensor" joint="elbow_flex"/>
    <jointpos name="wrist_flex_pos_sensor" joint="wrist_flex"/>
    <jointvel name="wrist_flex_vel_sensor" joint="wrist_flex"/>
    <jointpos name="wrist_roll_pos_sensor" joint="wrist_roll"/>
    <jointvel name="wrist_roll_vel_sensor" joint="wrist_roll"/>
    <jointpos name="gripper_pos_sensor" joint="gripper"/>
    <jointvel name="gripper_vel_sensor" joint="gripper"/>
    <gyro name="imu_gyro" site="imu"/>
    <accelerometer name="imu_accel" site="imu"/>
  </sensor>
</mujoco>
