<?xml version='1.0' encoding='utf-8'?>
<mujoco model="so101_arm">
  <compiler angle="radian" meshdir="meshes"/>
  <default>
    <motor ctrlrange="-1 1" gear="1.0"/>
  </default>
  <asset>
    <mesh name="base_mesh" file="base.stl" scale="1 1 1"/>
    <mesh name="turntable_mesh" file="turntable.stl" scale="1 1 1"/>
    <mesh name="upper_arm_mesh" file="upper_arm.stl" scale="1 1 1"/>
    <mesh name="forearm_mesh" file="forearm.stl" scale="1 1 1"/>
    <mesh name="wrist_mesh" file="wrist.stl" scale="1 1 1"/>
    <mesh name="wrist_roll_mesh" file="wrist_roll.stl" scale="1 1 1"/>
    <mesh name="jaw_mesh" file="jaw.stl" scale="1 1 1"/>
  </asset>
  <worldbody>
    <body name="base" pos="0 0 0.0350">
      <freejoint name="root"/>
      <inertial pos="-0.004675 -0.000000 -0.001264" mass="0.163995" fullinertia="6.693775e-05 1.227614e-04 1.067249e-04 6.442006e-08 9.761671e-06 -2.091892e-21"/>
      <geom type="mesh" mesh="base_mesh" rgba="0.9 0.9 0.9 1.0" contype="1" conaffinity="1"/>
      <site name="imu" pos="0 0 0" size="0.005"/>
      <geom name="comp_base_pi" type="box" size="0.032500 0.015000 0.002500" pos="0.000000 0.000000 0.000000" rgba="0.0 0.5 0.0 1.0" contype="0" conaffinity="0" group="1"/>
      <geom name="comp_base_battery" type="box" size="0.036500 0.017500 0.009000" pos="0.000000 0.000000 -0.016000" rgba="0.2 0.2 0.8 1.0" contype="0" conaffinity="0" group="1"/>
      <geom name="shoulder_pan_servo" type="box" size="0.022700 0.012400 0.015900" pos="-0.012500 0.000000 0.015100" quat="1.000000 0.000000 0.000000 0.000000" rgba="0.2 0.8 0.2 0.8" contype="0" conaffinity="0" group="1"/>
      <geom name="shoulder_pan_servo_boss" type="cylinder" size="0.004000 0.001400" pos="0.000000 0.000000 0.032400" rgba="0.2 0.8 0.2 0.8" contype="0" conaffinity="0" group="1"/>
      <geom name="screw_shoulder_pan_ear_1" type="cylinder" size="0.0021 0.001" pos="-0.008300 -0.010250 -0.002400" rgba="0.7 0.7 0.7 0.9" contype="0" conaffinity="0" group="1"/>
      <geom name="screw_shoulder_pan_ear_2" type="cylinder" size="0.0021 0.001" pos="-0.029000 -0.010250 -0.002400" rgba="0.7 0.7 0.7 0.9" contype="0" conaffinity="0" group="1"/>
      <geom name="screw_shoulder_pan_ear_3" type="cylinder" size="0.0021 0.001" pos="-0.008300 0.010250 -0.002400" rgba="0.7 0.7 0.7 0.9" contype="0" conaffinity="0" group="1"/>
      <geom name="screw_shoulder_pan_ear_4" type="cylinder" size="0.0021 0.001" pos="-0.029000 0.010250 -0.002400" rgba="0.7 0.7 0.7 0.9" contype="0" conaffinity="0" group="1"/>
      <geom name="screw_shoulder_pan_ear_5" type="cylinder" size="0.0021 0.001" pos="-0.032800 -0.010250 -0.002400" rgba="0.7 0.7 0.7 0.9" contype="0" conaffinity="0" group="1"/>
      <geom name="screw_shoulder_pan_ear_6" type="cylinder" size="0.0021 0.001" pos="-0.032800 0.010250 -0.002400" rgba="0.7 0.7 0.7 0.9" contype="0" conaffinity="0" group="1"/>
      <geom name="horn_shoulder_pan_out_1" type="cylinder" size="0.0013 0.001" pos="-0.004950 0.004950 0.033800" rgba="0.7 0.7 0.7 0.9" contype="0" conaffinity="0" group="1"/>
      <geom name="horn_shoulder_pan_out_2" type="cylinder" size="0.0013 0.001" pos="0.004950 0.004950 0.033800" rgba="0.7 0.7 0.7 0.9" contype="0" conaffinity="0" group="1"/>
      <geom name="horn_shoulder_pan_out_3" type="cylinder" size="0.0013 0.001" pos="-0.004950 -0.004950 0.033800" rgba="0.7 0.7 0.7 0.9" contype="0" conaffinity="0" group="1"/>
      <geom name="horn_shoulder_pan_out_4" type="cylinder" size="0.0013 0.001" pos="0.004950 -0.004950 0.033800" rgba="0.7 0.7 0.7 0.9" contype="0" conaffinity="0" group="1"/>
      <geom name="rear_shoulder_pan_rear_1" type="cylinder" size="0.0013 0.001" pos="-0.004950 0.004950 -0.003900" rgba="0.7 0.7 0.7 0.9" contype="0" conaffinity="0" group="1"/>
      <geom name="rear_shoulder_pan_rear_2" type="cylinder" size="0.0013 0.001" pos="0.004950 0.004950 -0.003900" rgba="0.7 0.7 0.7 0.9" contype="0" conaffinity="0" group="1"/>
      <geom name="rear_shoulder_pan_rear_3" type="cylinder" size="0.0013 0.001" pos="-0.004950 -0.004950 -0.003900" rgba="0.7 0.7 0.7 0.9" contype="0" conaffinity="0" group="1"/>
      <geom name="rear_shoulder_pan_rear_4" type="cylinder" size="0.0013 0.001" pos="0.004950 -0.004950 -0.003900" rgba="0.7 0.7 0.7 0.9" contype="0" conaffinity="0" group="1"/>
      <geom name="mount_base_pi_m1" type="cylinder" size="0.0013 0.001" pos="-0.029000 -0.011500 0.000000" rgba="0.7 0.7 0.7 0.9" contype="0" conaffinity="0" group="1"/>
      <geom name="mount_base_pi_m2" type="cylinder" size="0.0013 0.001" pos="0.029000 -0.011500 0.000000" rgba="0.7 0.7 0.7 0.9" contype="0" conaffinity="0" group="1"/>
      <geom name="mount_base_pi_m3" type="cylinder" size="0.0013 0.001" pos="-0.029000 0.011500 0.000000" rgba="0.7 0.7 0.7 0.9" contype="0" conaffinity="0" group="1"/>
      <geom name="mount_base_pi_m4" type="cylinder" size="0.0013 0.001" pos="0.029000 0.011500 0.000000" rgba="0.7 0.7 0.7 0.9" contype="0" conaffinity="0" group="1"/>
      <geom name="wire_servo_bus_base_0" type="capsule" fromto="0.000000 0.000000 0.000000 -0.020500 0.000000 -0.000800" size="0.0009" rgba="0.2 0.4 1.0 0.9" contype="0" conaffinity="0" group="2"/>
      <geom name="wire_power_base_0" type="capsule" fromto="0.036500 0.000000 -0.016000 0.036500 0.000000 0.000000" size="0.0012" rgba="0.9 0.2 0.2 0.9" contype="0" conaffinity="0" group="2"/>
      <geom name="wire_power_base_1" type="capsule" fromto="0.036500 0.000000 0.000000 -0.032500 0.000000 0.000000" size="0.0012" rgba="0.9 0.2 0.2 0.9" contype="0" conaffinity="0" group="2"/>
      <body name="turntable" pos="0.000000 0.000000 0.031000">
        <inertial pos="-0.007995 0.000119 0.020186" mass="0.080377" fullinertia="5.073116e-05 7.167998e-05 3.406009e-05 -2.251910e-07 1.459357e-05 3.628541e-07"/>
        <joint name="shoulder_pan" type="hinge" pos="0 0 0" axis="0.000000 0.000000 1.000000" damping="0.6237" range="-1.9200 1.9200"/>
        <geom name="shoulder_pan_horn_disc" type="cylinder" size="0.009250 0.001400" pos="0.000000 0.000000 0.001400" rgba="0.85 0.85 0.88 0.9" contype="0" conaffinity="0" group="1"/>
        <geom type="mesh" mesh="turntable_mesh" rgba="0.9 0.9 0.9 1.0" contype="1" conaffinity="1"/>
        <geom name="shoulder_lift_servo" type="box" size="0.022700 0.012400 0.015900" pos="-0.015900 0.000000 0.032500" quat="0.707107 0.000000 0.707107 0.000000" rgba="0.2 0.8 0.2 0.8" contype="0" conaffinity="0" group="1"/>
        <geom name="shoulder_lift_servo_boss" type="cylinder" size="0.004000 0.001400" pos="0.001400 0.000000 0.020000" rgba="0.2 0.8 0.2 0.8" contype="0" conaffinity="0" group="1" quat="0.707107 0.000000 0.707107 0.000000"/>
        <geom name="screw_shoulder_lift_ear_1" type="cylinder" size="0.0021 0.001" pos="-0.033400 -0.010250 0.028300" rgba="0.7 0.7 0.7 0.9" contype="0" conaffinity="0" group="1"/>
        <geom name="screw_shoulder_lift_ear_2" type="cylinder" size="0.0021 0.001" pos="-0.033400 -0.010250 0.049000" rgba="0.7 0.7 0.7 0.9" contype="0" conaffinity="0" group="1"/>
        <geom name="screw_shoulder_lift_ear_3" type="cylinder" size="0.0021 0.001" pos="-0.033400 0.010250 0.028300" rgba="0.7 0.7 0.7 0.9" contype="0" conaffinity="0" group="1"/>
        <geom name="screw_shoulder_lift_ear_4" type="cylinder" size="0.0021 0.001" pos="-0.033400 0.010250 0.049000" rgba="0.7 0.7 0.7 0.9" contype="0" conaffinity="0" group="1"/>
        <geom name="screw_shoulder_lift_ear_5" type="cylinder" size="0.0021 0.001" pos="-0.033400 -0.010250 0.052800" rgba="0.7 0.7 0.7 0.9" contype="0" conaffinity="0" group="1"/>
        <geom name="screw_shoulder_lift_ear_6" type="cylinder" size="0.0021 0.001" pos="-0.033400 0.010250 0.052800" rgba="0.7 0.7 0.7 0.9" contype="0" conaffinity="0" group="1"/>
        <geom name="horn_shoulder_lift_out_1" type="cylinder" size="0.0013 0.001" pos="0.002800 0.004950 0.024950" rgba="0.7 0.7 0.7 0.9" contype="0" conaffinity="0" group="1"/>
        <geom name="horn_shoulder_lift_out_2" type="cylinder" size="0.0013 0.001" pos="0.002800 0.004950 0.015050" rgba="0.7 0.7 0.7 0.9" contype="0" conaffinity="0" group="1"/>
        <geom name="horn_shoulder_lift_out_3" type="cylinder" size="0.0013 0.001" pos="0.002800 -0.004950 0.024950" rgba="0.7 0.7 0.7 0.9" contype="0" conaffinity="0" group="1"/>
        <geom name="horn_shoulder_lift_out_4" type="cylinder" size="0.0013 0.001" pos="0.002800 -0.004950 0.015050" rgba="0.7 0.7 0.7 0.9" contype="0" conaffinity="0" group="1"/>
        <geom name="rear_shoulder_lift_rear_1" type="cylinder" size="0.0013 0.001" pos="-0.034900 0.004950 0.024950" rgba="0.7 0.7 0.7 0.9" contype="0" conaffinity="0" group="1"/>
        <geom name="rear_shoulder_lift_rear_2" type="cylinder" size="0.0013 0.001" pos="-0.034900 0.004950 0.015050" rgba="0.7 0.7 0.7 0.9" contype="0" conaffinity="0" group="1"/>
        <geom name="rear_shoulder_lift_rear_3" type="cylinder" size="0.0013 0.001" pos="-0.034900 -0.004950 0.024950" rgba="0.7 0.7 0.7 0.9" contype="0" conaffinity="0" group="1"/>
        <geom name="rear_shoulder_lift_rear_4" type="cylinder" size="0.0013 0.001" pos="-0.034900 -0.004950 0.015050" rgba="0.7 0.7 0.7 0.9" contype="0" conaffinity="0" group="1"/>
        <geom name="wire_servo_bus_turntable_1" type="capsule" fromto="0.000000 0.000000 0.000000 -0.031800 0.000000 0.000000" size="0.0009" rgba="0.2 0.4 1.0 0.9" contype="0" conaffinity="0" group="2"/>
        <geom name="wire_servo_bus_turntable_2" type="capsule" fromto="-0.031800 0.000000 0.000000 -0.031800 0.000000 0.040500" size="0.0009" rgba="0.2 0.4 1.0 0.9" contype="0" conaffinity="0" group="2"/>
        <body name="upper_arm" pos="0.000000 0.000000 0.020000">
          <inertial pos="-0.011786 0.000032 0.092716" mass="0.090301" fullinertia="2.536168e-04 2.771976e-04 3.478321e-05 1.077618e-08 3.303355e-05 3.494851e-07"/>
          <joint name="shoulder_lift" type="hinge" pos="0 0 0" axis="1.000000 0.000000 0.000000" damping="0.6237" range="-1.7450 1.7450"/>
          <geom name="shoulder_lift_horn_disc" type="cylinder" size="0.009250 0.001400" pos="0.001400 0.000000 0.000000" rgba="0.85 0.85 0.88 0.9" contype="0" conaffinity="0" group="1" quat="0.707107 0.000000 0.707107 0.000000"/>
          <geom type="mesh" mesh="upper_arm_mesh" rgba="0.7 0.7 0.7 1.0" contype="1" conaffinity="1"/>
          <geom name="elbow_flex_servo" type="box" size="0.022700 0.012400 0.015900" pos="-0.015900 0.000000 0.128500" quat="0.707107 0.000000 0.707107 0.000000" rgba="0.2 0.8 0.2 0.8" contype="0" conaffinity="0" group="1"/>
          <geom name="elbow_flex_servo_boss" type="cylinder" size="0.004000 0.001400" pos="0.001400 0.000000 0.116000" rgba="0.2 0.8 0.2 0.8" contype="0" conaffinity="0" group="1" quat="0.707107 0.000000 0.707107 0.000000"/>
          <geom name="screw_elbow_flex_ear_1" type="cylinder" size="0.0021 0.001" pos="-0.033400 -0.010250 0.124300" rgba="0.7 0.7 0.7 0.9" contype="0" conaffinity="0" group="1"/>
          <geom name="screw_elbow_flex_ear_2" type="cylinder" size="0.0021 0.001" pos="-0.033400 -0.010250 0.145000" rgba="0.7 0.7 0.7 0.9" contype="0" conaffinity="0" group="1"/>
          <geom name="screw_elbow_flex_ear_3" type="cylinder" size="0.0021 0.001" pos="-0.033400 0.010250 0.124300" rgba="0.7 0.7 0.7 0.9" contype="0" conaffinity="0" group="1"/>
          <geom name="screw_elbow_flex_ear_4" type="cylinder" size="0.0021 0.001" pos="-0.033400 0.010250 0.145000" rgba="0.7 0.7 0.7 0.9" contype="0" conaffinity="0" group="1"/>
          <geom name="screw_elbow_flex_ear_5" type="cylinder" size="0.0021 0.001" pos="-0.033400 -0.010250 0.148800" rgba="0.7 0.7 0.7 0.9" contype="0" conaffinity="0" group="1"/>
          <geom name="screw_elbow_flex_ear_6" type="cylinder" size="0.0021 0.001" pos="-0.033400 0.010250 0.148800" rgba="0.7 0.7 0.7 0.9" contype="0" conaffinity="0" group="1"/>
          <geom name="horn_elbow_flex_out_1" type="cylinder" size="0.0013 0.001" pos="0.002800 0.004950 0.120950" rgba="0.7 0.7 0.7 0.9" contype="0" conaffinity="0" group="1"/>
          <geom name="horn_elbow_flex_out_2" type="cylinder" size="0.0013 0.001" pos="0.002800 0.004950 0.111050" rgba="0.7 0.7 0.7 0.9" contype="0" conaffinity="0" group="1"/>
          <geom name="horn_elbow_flex_out_3" type="cylinder" size="0.0013 0.001" pos="0.002800 -0.004950 0.120950" rgba="0.7 0.7 0.7 0.9" contype="0" conaffinity="0" group="1"/>
          <geom name="horn_elbow_flex_out_4" type="cylinder" size="0.0013 0.001" pos="0.002800 -0.004950 0.111050" rgba="0.7 0.7 0.7 0.9" contype="0" conaffinity="0" group="1"/>
          <geom name="rear_elbow_flex_rear_1" type="cylinder" size="0.0013 0.001" pos="-0.034900 0.004950 0.120950" rgba="0.7 0.7 0.7 0.9" contype="0" conaffinity="0" group="1"/>
          <geom name="rear_elbow_flex_rear_2" type="cylinder" size="0.0013 0.001" pos="-0.034900 0.004950 0.111050" rgba="0.7 0.7 0.7 0.9" contype="0" conaffinity="0" group="1"/>
          <geom name="rear_elbow_flex_rear_3" type="cylinder" size="0.0013 0.001" pos="-0.034900 -0.004950 0.120950" rgba="0.7 0.7 0.7 0.9" contype="0" conaffinity="0" group="1"/>
          <geom name="rear_elbow_flex_rear_4" type="cylinder" size="0.0013 0.001" pos="-0.034900 -0.004950 0.111050" rgba="0.7 0.7 0.7 0.9" contype="0" conaffinity="0" group="1"/>
          <geom name="wire_servo_bus_upper_arm_3" type="capsule" fromto="0.000000 0.000000 0.000000 0.000000 0.000000 0.136500" size="0.0009" rgba="0.2 0.4 1.0 0.9" contype="0" conaffinity="0" group="2"/>
          <geom name="wire_servo_bus_upper_arm_4" type="capsule" fromto="0.000000 0.000000 0.136500 -0.031800 0.000000 0.136500" size="0.0009" rgba="0.2 0.4 1.0 0.9" contype="0" conaffinity="0" group="2"/>
          <body name="forearm" pos="0.000000 0.000000 0.116000">
            <inertial pos="-0.013105 0.000000 0.105265" mass="0.087652" fullinertia="3.456955e-04 3.667748e-04 3.048280e-05 2.492304e-16 2.638940e-05 5.789385e-15"/>
            <joint name="elbow_flex" type="hinge" pos="0 0 0" axis="1.000000 0.000000 0.000000" damping="0.6237" range="-1.6900 1.6900"/>
            <geom name="elbow_flex_horn_disc" type="cylinder" size="0.009250 0.001400" pos="0.001400 0.000000 0.000000" rgba="0.85 0.85 0.88 0.9" contype="0" conaffinity="0" group="1" quat="0.707107 0.000000 0.707107 0.000000"/>
            <geom type="mesh" mesh="forearm_mesh" rgba="0.7 0.7 0.7 1.0" contype="1" conaffinity="1"/>
            <geom name="wrist_flex_servo" type="box" size="0.022700 0.012400 0.015900" pos="-0.015900 0.000000 0.147500" quat="0.707107 0.000000 0.707107 0.000000" rgba="0.2 0.8 0.2 0.8" contype="0" conaffinity="0" group="1"/>
            <geom name="wrist_flex_servo_boss" type="cylinder" size="0.004000 0.001400" pos="0.001400 0.000000 0.135000" rgba="0.2 0.8 0.2 0.8" contype="0" conaffinity="0" group="1" quat="0.707107 0.000000 0.707107 0.000000"/>
            <geom name="screw_wrist_flex_ear_1" type="cylinder" size="0.0021 0.001" pos="-0.033400 -0.010250 0.143300" rgba="0.7 0.7 0.7 0.9" contype="0" conaffinity="0" group="1"/>
            <geom name="screw_wrist_flex_ear_2" type="cylinder" size="0.0021 0.001" pos="-0.033400 -0.010250 0.164000" rgba="0.7 0.7 0.7 0.9" contype="0" conaffinity="0" group="1"/>
            <geom name="screw_wrist_flex_ear_3" type="cylinder" size="0.0021 0.001" pos="-0.033400 0.010250 0.143300" rgba="0.7 0.7 0.7 0.9" contype="0" conaffinity="0" group="1"/>
            <geom name="screw_wrist_flex_ear_4" type="cylinder" size="0.0021 0.001" pos="-0.033400 0.010250 0.164000" rgba="0.7 0.7 0.7 0.9" contype="0" conaffinity="0" group="1"/>
            <geom name="screw_wrist_flex_ear_5" type="cylinder" size="0.0021 0.001" pos="-0.033400 -0.010250 0.167800" rgba="0.7 0.7 0.7 0.9" contype="0" conaffinity="0" group="1"/>
            <geom name="screw_wrist_flex_ear_6" type="cylinder" size="0.0021 0.001" pos="-0.033400 0.010250 0.167800" rgba="0.7 0.7 0.7 0.9" contype="0" conaffinity="0" group="1"/>
            <geom name="horn_wrist_flex_out_1" type="cylinder" size="0.0013 0.001" pos="0.002800 0.004950 0.139950" rgba="0.7 0.7 0.7 0.9" contype="0" conaffinity="0" group="1"/>
            <geom name="horn_wrist_flex_out_2" type="cylinder" size="0.0013 0.001" pos="0.002800 0.004950 0.130050" rgba="0.7 0.7 0.7 0.9" contype="0" conaffinity="0" group="1"/>
            <geom name="horn_wrist_flex_out_3" type="cylinder" size="0.0013 0.001" pos="0.002800 -0.004950 0.139950" rgba="0.7 0.7 0.7 0.9" contype="0" conaffinity="0" group="1"/>
            <geom name="horn_wrist_flex_out_4" type="cylinder" size="0.0013 0.001" pos="0.002800 -0.004950 0.130050" rgba="0.7 0.7 0.7 0.9" contype="0" conaffinity="0" group="1"/>
            <geom name="rear_wrist_flex_rear_1" type="cylinder" size="0.0013 0.001" pos="-0.034900 0.004950 0.139950" rgba="0.7 0.7 0.7 0.9" contype="0" conaffinity="0" group="1"/>
            <geom name="rear_wrist_flex_rear_2" type="cylinder" size="0.0013 0.001" pos="-0.034900 0.004950 0.130050" rgba="0.7 0.7 0.7 0.9" contype="0" conaffinity="0" group="1"/>
            <geom name="rear_wrist_flex_rear_3" type="cylinder" size="0.0013 0.001" pos="-0.034900 -0.004950 0.139950" rgba="0.7 0.7 0.7 0.9" contype="0" conaffinity="0" group="1"/>
            <geom name="rear_wrist_flex_rear_4" type="cylinder" size="0.0013 0.001" pos="-0.034900 -0.004950 0.130050" rgba="0.7 0.7 0.7 0.9" contype="0" conaffinity="0" group="1"/>
            <geom name="wire_servo_bus_forearm_5" type="capsule" fromto="0.000000 0.000000 0.000000 0.000000 0.000000 0.155500" size="0.0009" rgba="0.2 0.4 1.0 0.9" contype="0" conaffinity="0" group="2"/>
            <geom name="wire_servo_bus_forearm_6" type="capsule" fromto="0.000000 0.000000 0.155500 -0.031800 0.000000 0.155500" size="0.0009" rgba="0.2 0.4 1.0 0.9" contype="0" conaffinity="0" group="2"/>
            <body name="wrist" pos="0.000000 0.000000 0.135000">
              <inertial pos="-0.012897 -0.000006 0.009712" mass="0.086664" fullinertia="2.496350e-05 4.934277e-05 3.745845e-05 -1.052056e-08 -4.059201e-06 -2.013775e-08"/>
              <joint name="wrist_flex" type="hinge" pos="0 0 0" axis="1.000000 0.000000 0.000000" damping="0.6237" range="-1.6580 1.6580"/>
              <geom name="wrist_flex_horn_disc" type="cylinder" size="0.009250 0.001400" pos="0.001400 0.000000 0.000000" rgba="0.85 0.85 0.88 0.9" contype="0" conaffinity="0" group="1" quat="0.707107 0.000000 0.707107 0.000000"/>
              <geom type="mesh" mesh="wrist_mesh" rgba="0.9 0.9 0.9 1.0" contype="1" conaffinity="1"/>
              <geom name="wrist_roll_servo" type="box" size="0.022700 0.012400 0.015900" pos="-0.012500 0.000000 0.016100" quat="1.000000 0.000000 0.000000 0.000000" rgba="0.2 0.8 0.2 0.8" contype="0" conaffinity="0" group="1"/>
              <geom name="wrist_roll_servo_boss" type="cylinder" size="0.004000 0.001400" pos="0.000000 0.000000 0.033400" rgba="0.2 0.8 0.2 0.8" contype="0" conaffinity="0" group="1"/>
              <geom name="screw_wrist_roll_ear_1" type="cylinder" size="0.0021 0.001" pos="-0.008300 -0.010250 -0.001400" rgba="0.7 0.7 0.7 0.9" contype="0" conaffinity="0" group="1"/>
              <geom name="screw_wrist_roll_ear_2" type="cylinder" size="0.0021 0.001" pos="-0.029000 -0.010250 -0.001400" rgba="0.7 0.7 0.7 0.9" contype="0" conaffinity="0" group="1"/>
              <geom name="screw_wrist_roll_ear_3" type="cylinder" size="0.0021 0.001" pos="-0.008300 0.010250 -0.001400" rgba="0.7 0.7 0.7 0.9" contype="0" conaffinity="0" group="1"/>
              <geom name="screw_wrist_roll_ear_4" type="cylinder" size="0.0021 0.001" pos="-0.029000 0.010250 -0.001400" rgba="0.7 0.7 0.7 0.9" contype="0" conaffinity="0" group="1"/>
              <geom name="screw_wrist_roll_ear_5" type="cylinder" size="0.0021 0.001" pos="-0.032800 -0.010250 -0.001400" rgba="0.7 0.7 0.7 0.9" contype="0" conaffinity="0" group="1"/>
              <geom name="screw_wrist_roll_ear_6" type="cylinder" size="0.0021 0.001" pos="-0.032800 0.010250 -0.001400" rgba="0.7 0.7 0.7 0.9" contype="0" conaffinity="0" group="1"/>
              <geom name="horn_wrist_roll_out_1" type="cylinder" size="0.0013 0.001" pos="-0.004950 0.004950 0.034800" rgba="0.7 0.7 0.7 0.9" contype="0" conaffinity="0" group="1"/>
              <geom name="horn_wrist_roll_out_2" type="cylinder" size="0.0013 0.001" pos="0.004950 0.004950 0.034800" rgba="0.7 0.7 0.7 0.9" contype="0" conaffinity="0" group="1"/>
              <geom name="horn_wrist_roll_out_3" type="cylinder" size="0.0013 0.001" pos="-0.004950 -0.004950 0.034800" rgba="0.7 0.7 0.7 0.9" contype="0" conaffinity="0" group="1"/>
              <geom name="horn_wrist_roll_out_4" type="cylinder" size="0.0013 0.001" pos="0.004950 -0.004950 0.034800" rgba="0.7 0.7 0.7 0.9" contype="0" conaffinity="0" group="1"/>
              <geom name="rear_wrist_roll_rear_1" type="cylinder" size="0.0013 0.001" pos="-0.004950 0.004950 -0.002900" rgba="0.7 0.7 0.7 0.9" contype="0" conaffinity="0" group="1"/>
              <geom name="rear_wrist_roll_rear_2" type="cylinder" size="0.0013 0.001" pos="0.004950 0.004950 -0.002900" rgba="0.7 0.7 0.7 0.9" contype="0" conaffinity="0" group="1"/>
              <geom name="rear_wrist_roll_rear_3" type="cylinder" size="0.0013 0.001" pos="-0.004950 -0.004950 -0.002900" rgba="0.7 0.7 0.7 0.9" contype="0" conaffinity="0" group="1"/>
              <geom name="rear_wrist_roll_rear_4" type="cylinder" size="0.0013 0.001" pos="0.004950 -0.004950 -0.002900" rgba="0.7 0.7 0.7 0.9" contype="0" conaffinity="0" group="1"/>
              <geom name="wire_servo_bus_wrist_7" type="capsule" fromto="0.000000 0.000000 0.000000 -0.020500 0.000000 0.000200" size="0.0009" rgba="0.2 0.4 1.0 0.9" contype="0" conaffinity="0" group="2"/>
              <body name="wrist_roll" pos="0.000000 0.000000 0.032000">
                <inertial pos="-0.011781 0.000369 0.025018" mass="0.071217" fullinertia="2.479261e-05 3.664727e-05 2.130512e-05 -3.670251e-07 2.149300e-06 1.003961e-06"/>
                <joint name="wrist_roll" type="hinge" pos="0 0 0" axis="0.000000 0.000000 1.000000" damping="0.6237" range="-2.7440 2.8410"/>
                <geom name="wrist_roll_horn_disc" type="cylinder" size="0.009250 0.001400" pos="0.000000 0.000000 0.001400" rgba="0.85 0.85 0.88 0.9" contype="0" conaffinity="0" group="1"/>
                <geom type="mesh" mesh="wrist_roll_mesh" rgba="0.9 0.9 0.9 1.0" contype="1" conaffinity="1"/>
                <camera name="camera_cam" fovy="62.2" pos="0.000000 0.005500 0.000000" euler="0 3.141592653589793 0"/>
                <geom name="comp_wrist_roll_camera" type="box" size="0.012500 0.012000 0.004500" pos="0.000000 0.005500 0.000000" rgba="0.85 0.75 0.1 1.0" contype="0" conaffinity="0" group="1"/>
                <geom name="gripper_servo" type="box" size="0.022700 0.012400 0.015900" pos="-0.015900 0.000000 0.030500" quat="0.707107 0.000000 0.707107 0.000000" rgba="0.2 0.8 0.2 0.8" contype="0" conaffinity="0" group="1"/>
                <geom name="gripper_servo_boss" type="cylinder" size="0.004000 0.001400" pos="0.001400 0.000000 0.018000" rgba="0.2 0.8 0.2 0.8" contype="0" conaffinity="0" group="1" quat="0.707107 0.000000 0.707107 0.000000"/>
                <geom name="screw_gripper_ear_1" type="cylinder" size="0.0021 0.001" pos="-0.033400 -0.010250 0.026300" rgba="0.7 0.7 0.7 0.9" contype="0" conaffinity="0" group="1"/>
                <geom name="screw_gripper_ear_2" type="cylinder" size="0.0021 0.001" pos="-0.033400 -0.010250 0.047000" rgba="0.7 0.7 0.7 0.9" contype="0" conaffinity="0" group="1"/>
                <geom name="screw_gripper_ear_3" type="cylinder" size="0.0021 0.001" pos="-0.033400 0.010250 0.026300" rgba="0.7 0.7 0.7 0.9" contype="0" conaffinity="0" group="1"/>
                <geom name="screw_gripper_ear_4" type="cylinder" size="0.0021 0.001" pos="-0.033400 0.010250 0.047000" rgba="0.7 0.7 0.7 0.9" contype="0" conaffinity="0" group="1"/>
                <geom name="screw_gripper_ear_5" type="cylinder" size="0.0021 0.001" pos="-0.033400 -0.010250 0.050800" rgba="0.7 0.7 0.7 0.9" contype="0" conaffinity="0" group="1"/>
                <geom name="screw_gripper_ear_6" type="cylinder" size="0.0021 0.001" pos="-0.033400 0.010250 0.050800" rgba="0.7 0.7 0.7 0.9" contype="0" conaffinity="0" group="1"/>
                <geom name="horn_gripper_out_1" type="cylinder" size="0.0013 0.001" pos="0.002800 0.004950 0.022950" rgba="0.7 0.7 0.7 0.9" contype="0" conaffinity="0" group="1"/>
                <geom name="horn_gripper_out_2" type="cylinder" size="0.0013 0.001" pos="0.002800 0.004950 0.013050" rgba="0.7 0.7 0.7 0.9" contype="0" conaffinity="0" group="1"/>
                <geom name="horn_gripper_out_3" type="cylinder" size="0.0013 0.001" pos="0.002800 -0.004950 0.022950" rgba="0.7 0.7 0.7 0.9" contype="0" conaffinity="0" group="1"/>
                <geom name="horn_gripper_out_4" type="cylinder" size="0.0013 0.001" pos="0.002800 -0.004950 0.013050" rgba="0.7 0.7 0.7 0.9" contype="0" conaffinity="0" group="1"/>
                <geom name="rear_gripper_rear_1" type="cylinder" size="0.0013 0.001" pos="-0.034900 0.004950 0.022950" rgba="0.7 0.7 0.7 0.9" contype="0" conaffinity="0" group="1"/>
                <geom name="rear_gripper_rear_2" type="cylinder" size="0.0013 0.001" pos="-0.034900 0.004950 0.013050" rgba="0.7 0.7 0.7 0.9" contype="0" conaffinity="0" group="1"/>
                <geom name="rear_gripper_rear_3" type="cylinder" size="0.0013 0.001" pos="-0.034900 -0.004950 0.022950" rgba="0.7 0.7 0.7 0.9" contype="0" conaffinity="0" group="1"/>
                <geom name="rear_gripper_rear_4" type="cylinder" size="0.0013 0.001" pos="-0.034900 -0.004950 0.013050" rgba="0.7 0.7 0.7 0.9" contype="0" conaffinity="0" group="1"/>
                <geom name="mount_wrist_roll_camera_m1" type="cylinder" size="0.0010 0.001" pos="-0.010500 -0.004000 0.000000" rgba="0.7 0.7 0.7 0.9" contype="0" conaffinity="0" group="1"/>
                <geom name="mount_wrist_roll_camera_m2" type="cylinder" size="0.0010 0.001" pos="0.010500 -0.004000 0.000000" rgba="0.7 0.7 0.7 0.9" contype="0" conaffinity="0" group="1"/>
                <geom name="wire_servo_bus_wrist_roll_8" type="capsule" fromto="0.000000 0.000000 0.000000 -0.031800 0.000000 0.000000" size="0.0009" rgba="0.2 0.4 1.0 0.9" contype="0" conaffinity="0" group="2"/>
                <geom name="wire_servo_bus_wrist_roll_9" type="capsule" fromto="-0.031800 0.000000 0.000000 -0.031800 0.000000 0.038500" size="0.0009" rgba="0.2 0.4 1.0 0.9" contype="0" conaffinity="0" group="2"/>
                <body name="jaw" pos="0.000000 0.000000 0.018000">
                  <inertial pos="-0.024126 0.000000 0.001809" mass="0.014522" fullinertia="3.262233e-06 1.052069e-05 8.108676e-06 -1.036259e-22 1.887058e-06 2.102774e-23"/>
                  <joint name="gripper" type="hinge" pos="0 0 0" axis="1.000000 0.000000 0.000000" damping="0.6237" range="-0.1750 1.7450"/>
                  <geom name="gripper_horn_disc" type="cylinder" size="0.009250 0.001400" pos="0.001400 0.000000 0.000000" rgba="0.85 0.85 0.88 0.9" contype="0" conaffinity="0" group="1" quat="0.707107 0.000000 0.707107 0.000000"/>
                  <geom type="mesh" mesh="jaw_mesh" rgba="0.85 0.85 0.85 1.0" contype="1" conaffinity="1"/>
                </body>
              </body>
            </body>
          </body>
        </body>
      </body>
    </body>
  </worldbody>
  <contact>
    <exclude body1="base" body2="forearm"/>
    <exclude body1="base" body2="turntable"/>
    <exclude body1="base" body2="upper_arm"/>
    <exclude body1="forearm" body2="jaw"/>
    <exclude body1="forearm" body2="wrist"/>
    <exclude body1="forearm" body2="wrist_roll"/>
    <exclude body1="turntable" body2="forearm"/>
    <exclude body1="turntable" body2="upper_arm"/>
    <exclude body1="turntable" body2="wrist"/>
    <exclude body1="upper_arm" body2="forearm"/>
    <exclude body1="upper_arm" body2="wrist"/>
    <exclude body1="upper_arm" body2="wrist_roll"/>
    <exclude body1="wrist" body2="jaw"/>
    <exclude body1="wrist" body2="wrist_roll"/>
    <exclude body1="wrist_roll" body2="jaw"/>
  </contact>
  <actuator>
    <position name="shoulder_pan_motor" joint="shoulder_pan" kp="58.8" ctrlrange="-1.9200 1.9200" forcerange="-2.94 2.94"/>
    <position name="shoulder_lift_motor" joint="shoulder_lift" kp="58.8" ctrlrange="-1.7450 1.7450" forcerange="-2.94 2.94"/>
    <position name="elbow_flex_motor" joint="elbow_flex" kp="58.8" ctrlrange="-1.6900 1.6900" forcerange="-2.94 2.94"/>
    <position name="wrist_flex_motor" joint="wrist_flex" kp="58.8" ctrlrange="-1.6580 1.6580" forcerange="-2.94 2.94"/>
    <position name="wrist_roll_motor" joint="wrist_roll" kp="58.8" ctrlrange="-2.7440 2.8410" forcerange="-2.94 2.94"/>
    <position name="gripper_motor" joint="gripper" kp="17.7" ctrlrange="-0.1750 1.7450" forcerange="-0.59 0.59"/>
  </actuator>
  <sensor>
    <jointpos name="shoulder_pan_pos_sensor" joint="shoulder_pan"/>
    <jointvel name="shoulder_pan_vel_sensor" joint="shoulder_pan"/>
    <jointpos name="shoulder_lift_pos_sensor" joint="shoulder_lift"/>
    <jointvel name="shoulder_lift_vel_sensor" joint="shoulder_lift"/>
    <jointpos name="elbow_flex_pos_sensor" joint="elbow_flex"/>
    <jointvel name="elbow_flex_vel_sensor" joint="elbow_flex"/>
    <jointpos name="wrist_flex_pos_sensor" joint="wrist_flex"/>
    <jointvel name="wrist_flex_vel_sensor" joint="wrist_flex"/>
    <jointpos name="wrist_roll_pos_sensor" joint="wrist_roll"/>
    <jointvel name="wrist_roll_vel_sensor" joint="wrist_roll"/>
    <jointpos name="gripper_pos_sensor" joint="gripper"/>
    <jointvel name="gripper_vel_sensor" joint="gripper"/>
    <gyro name="imu_gyro" site="imu"/>
    <accelerometer name="imu_accel" site="imu"/>
  </sensor>
</mujoco>
