<?xml version='1.0' encoding='utf-8'?>
<mujoco model="simple_plane">
  <compiler angle="radian" meshdir="meshes"/>
  <default>
    <motor ctrlrange="-1 1" gear="1.0"/>
  </default>
  <asset>
    <mesh name="fuselage_mesh" file="fuselage.stl" scale="1 1 1"/>
    <mesh name="left_wing_mesh" file="left_wing.stl" scale="1 1 1"/>
    <mesh name="left_aileron_surface_mesh" file="left_aileron_surface.stl" scale="1 1 1"/>
    <mesh name="right_wing_mesh" file="right_wing.stl" scale="1 1 1"/>
    <mesh name="right_aileron_surface_mesh" file="right_aileron_surface.stl" scale="1 1 1"/>
    <mesh name="tail_boom_mesh" file="tail_boom.stl" scale="1 1 1"/>
    <mesh name="horizontal_stab_mesh" file="horizontal_stab.stl" scale="1 1 1"/>
    <mesh name="elevator_surface_mesh" file="elevator_surface.stl" scale="1 1 1"/>
    <mesh name="vertical_fin_mesh" file="vertical_fin.stl" scale="1 1 1"/>
    <mesh name="rudder_surface_mesh" file="rudder_surface.stl" scale="1 1 1"/>
    <mesh name="comp_fuselage_fc_mesh" file="comp_fuselage_fc.stl" scale="1 1 1"/>
    <mesh name="comp_fuselage_battery_mesh" file="comp_fuselage_battery.stl" scale="1 1 1"/>
    <mesh name="comp_fuselage_esc_mesh" file="comp_fuselage_esc.stl" scale="1 1 1"/>
    <mesh name="comp_fuselage_motor_mesh" file="comp_fuselage_motor.stl" scale="1 1 1"/>
    <mesh name="comp_fuselage_prop_mesh" file="comp_fuselage_prop.stl" scale="1 1 1"/>
    <mesh name="servo_SCS0009_mesh" file="servo_SCS0009.stl" scale="1 1 1"/>
    <mesh name="hardware_M3_shc_mesh" file="hardware_M3_shc.stl" scale="1 1 1"/>
    <mesh name="hardware_M2_shc_mesh" file="hardware_M2_shc.stl" scale="1 1 1"/>
    <mesh name="horn_left_aileron_mesh" file="horn_left_aileron.stl" scale="1 1 1"/>
    <mesh name="horn_right_aileron_mesh" file="horn_right_aileron.stl" scale="1 1 1"/>
    <mesh name="horn_elevator_mesh" file="horn_elevator.stl" scale="1 1 1"/>
    <mesh name="horn_rudder_mesh" file="horn_rudder.stl" scale="1 1 1"/>
  </asset>
  <worldbody>
    <body name="fuselage" pos="0 0 0.0350">
      <freejoint name="root"/>
      <inertial pos="-0.000000 0.011734 -0.000431" mass="0.633975" fullinertia="1.230313e-02 4.146874e-04 1.247476e-02 -2.157784e-20 -8.703008e-22 -3.059385e-06"/>
      <geom type="mesh" mesh="fuselage_mesh" rgba="0.0588 0.6000 0.3765 1.0000" contype="1" conaffinity="1"/>
      <site name="imu" pos="0 0 0" size="0.005"/>
      <geom name="comp_fuselage_fc" type="mesh" mesh="comp_fuselage_fc_mesh" pos="0.000000 0.000000 0.021000" rgba="0.0588 0.6000 0.3765 1.0000" contype="0" conaffinity="0" group="1"/>
      <geom name="comp_fuselage_battery" type="mesh" mesh="comp_fuselage_battery_mesh" pos="0.000000 0.000000 0.000000" rgba="0.0745 0.4863 0.7412 1.0000" contype="0" conaffinity="0" group="1"/>
      <geom name="comp_fuselage_esc" type="mesh" mesh="comp_fuselage_esc_mesh" pos="0.000000 0.000000 -0.019500" rgba="0.0941 0.1255 0.1490 1.0000" contype="0" conaffinity="0" group="1"/>
      <geom name="comp_fuselage_motor" type="mesh" mesh="comp_fuselage_motor_mesh" pos="0.000000 0.231000 0.000000" rgba="0.0941 0.1255 0.1490 1.0000" contype="0" conaffinity="0" group="1" quat="0.707107 -0.707107 0.000000 0.000000"/>
      <geom name="comp_fuselage_prop" type="mesh" mesh="comp_fuselage_prop_mesh" pos="0.000000 0.135700 0.000000" rgba="0.0941 0.1255 0.1490 1.0000" contype="0" conaffinity="0" group="1"/>
      <geom name="mount_fuselage_fc_fc_1" type="mesh" mesh="hardware_M3_shc_mesh" pos="0.015250 0.015250 0.021000" quat="0.000000 0.000000 -1.000000 0.000000" rgba="0.2235 0.2941 0.3490 0.9000" contype="0" conaffinity="0" group="1"/>
      <geom name="mount_fuselage_fc_fc_2" type="mesh" mesh="hardware_M3_shc_mesh" pos="0.015250 -0.015250 0.021000" quat="0.000000 0.000000 -1.000000 0.000000" rgba="0.2235 0.2941 0.3490 0.9000" contype="0" conaffinity="0" group="1"/>
      <geom name="mount_fuselage_fc_fc_3" type="mesh" mesh="hardware_M3_shc_mesh" pos="-0.015250 0.015250 0.021000" quat="0.000000 0.000000 -1.000000 0.000000" rgba="0.2235 0.2941 0.3490 0.9000" contype="0" conaffinity="0" group="1"/>
      <geom name="mount_fuselage_fc_fc_4" type="mesh" mesh="hardware_M3_shc_mesh" pos="-0.015250 -0.015250 0.021000" quat="0.000000 0.000000 -1.000000 0.000000" rgba="0.2235 0.2941 0.3490 0.9000" contype="0" conaffinity="0" group="1"/>
      <body name="left_wing" pos="-0.220000 0.050000 0.025000">
        <inertial pos="-0.000453 -0.001893 0.000259" mass="0.318528" fullinertia="6.157910e-04 3.711296e-03 4.313145e-03 -8.127675e-06 7.214589e-07 3.731045e-06"/>
        <geom type="mesh" mesh="left_wing_mesh" rgba="0.8078 0.8510 0.8784 1.0000" contype="1" conaffinity="1"/>
        <geom name="left_aileron_servo" type="mesh" mesh="servo_SCS0009_mesh" pos="-0.011250 -0.055000 0.005800" quat="0.707107 0.000000 0.707107 0.000000" rgba="0.0941 0.1255 0.1490 1.0000" contype="0" conaffinity="0" group="1"/>
        <geom name="screw_left_aileron_ear_1" type="mesh" mesh="hardware_M2_shc_mesh" pos="-0.007750 -0.055000 -0.008200" quat="0.707107 0.000000 0.707107 0.000000" rgba="0.2235 0.2941 0.3490 0.9000" contype="0" conaffinity="0" group="1"/>
        <geom name="screw_left_aileron_ear_2" type="mesh" mesh="hardware_M2_shc_mesh" pos="-0.007750 -0.055000 0.019800" quat="0.707107 0.000000 0.707107 0.000000" rgba="0.2235 0.2941 0.3490 0.9000" contype="0" conaffinity="0" group="1"/>
        <geom name="horn_left_aileron_out_1" type="mesh" mesh="hardware_M2_shc_mesh" pos="0.002000 -0.051000 -0.004000" quat="0.707107 0.000000 -0.707107 0.000000" rgba="0.2235 0.2941 0.3490 0.9000" contype="0" conaffinity="0" group="1"/>
        <geom name="horn_left_aileron_out_2" type="mesh" mesh="hardware_M2_shc_mesh" pos="0.002000 -0.059000 -0.004000" quat="0.707107 0.000000 -0.707107 0.000000" rgba="0.2235 0.2941 0.3490 0.9000" contype="0" conaffinity="0" group="1"/>
        <geom name="horn_left_aileron_out_3" type="mesh" mesh="hardware_M2_shc_mesh" pos="0.002000 -0.051000 0.004000" quat="0.707107 0.000000 -0.707107 0.000000" rgba="0.2235 0.2941 0.3490 0.9000" contype="0" conaffinity="0" group="1"/>
        <geom name="horn_left_aileron_out_4" type="mesh" mesh="hardware_M2_shc_mesh" pos="0.002000 -0.059000 0.004000" quat="0.707107 0.000000 -0.707107 0.000000" rgba="0.2235 0.2941 0.3490 0.9000" contype="0" conaffinity="0" group="1"/>
        <body name="left_aileron_surface" pos="0.000000 -0.055000 0.000000">
          <inertial pos="0.000000 0.000000 0.000000" mass="0.027587" fullinertia="3.825336e-06 7.463084e-05 7.816192e-05 -1.426192e-23 -3.993337e-24 -1.267726e-24"/>
          <joint name="left_aileron" type="hinge" pos="0 0 0" axis="1.000000 0.000000 0.000000" damping="0.0216" range="-0.3500 0.3500"/>
          <geom name="left_aileron_horn_disc" type="mesh" mesh="horn_left_aileron_mesh" pos="0.003000 0.000000 0.000000" rgba="0.8824 0.9098 0.9294 0.9000" contype="0" conaffinity="0" group="1"/>
          <geom type="mesh" mesh="left_aileron_surface_mesh" rgba="0.8078 0.8510 0.8784 1.0000" contype="1" conaffinity="1"/>
        </body>
      </body>
      <body name="right_wing" pos="0.220000 0.050000 0.025000">
        <inertial pos="-0.000453 -0.001893 0.000259" mass="0.318528" fullinertia="6.157910e-04 3.711296e-03 4.313145e-03 -8.127675e-06 7.214589e-07 3.731045e-06"/>
        <geom type="mesh" mesh="right_wing_mesh" rgba="0.8078 0.8510 0.8784 1.0000" contype="1" conaffinity="1"/>
        <geom name="right_aileron_servo" type="mesh" mesh="servo_SCS0009_mesh" pos="-0.011250 -0.055000 0.005800" quat="0.707107 0.000000 0.707107 0.000000" rgba="0.0941 0.1255 0.1490 1.0000" contype="0" conaffinity="0" group="1"/>
        <geom name="screw_right_aileron_ear_1" type="mesh" mesh="hardware_M2_shc_mesh" pos="-0.007750 -0.055000 -0.008200" quat="0.707107 0.000000 0.707107 0.000000" rgba="0.2235 0.2941 0.3490 0.9000" contype="0" conaffinity="0" group="1"/>
        <geom name="screw_right_aileron_ear_2" type="mesh" mesh="hardware_M2_shc_mesh" pos="-0.007750 -0.055000 0.019800" quat="0.707107 0.000000 0.707107 0.000000" rgba="0.2235 0.2941 0.3490 0.9000" contype="0" conaffinity="0" group="1"/>
        <geom name="horn_right_aileron_out_1" type="mesh" mesh="hardware_M2_shc_mesh" pos="0.002000 -0.051000 -0.004000" quat="0.707107 0.000000 -0.707107 0.000000" rgba="0.2235 0.2941 0.3490 0.9000" contype="0" conaffinity="0" group="1"/>
        <geom name="horn_right_aileron_out_2" type="mesh" mesh="hardware_M2_shc_mesh" pos="0.002000 -0.059000 -0.004000" quat="0.707107 0.000000 -0.707107 0.000000" rgba="0.2235 0.2941 0.3490 0.9000" contype="0" conaffinity="0" group="1"/>
        <geom name="horn_right_aileron_out_3" type="mesh" mesh="hardware_M2_shc_mesh" pos="0.002000 -0.051000 0.004000" quat="0.707107 0.000000 -0.707107 0.000000" rgba="0.2235 0.2941 0.3490 0.9000" contype="0" conaffinity="0" group="1"/>
        <geom name="horn_right_aileron_out_4" type="mesh" mesh="hardware_M2_shc_mesh" pos="0.002000 -0.059000 0.004000" quat="0.707107 0.000000 -0.707107 0.000000" rgba="0.2235 0.2941 0.3490 0.9000" contype="0" conaffinity="0" group="1"/>
        <body name="right_aileron_surface" pos="0.000000 -0.055000 0.000000">
          <inertial pos="0.000000 0.000000 0.000000" mass="0.027587" fullinertia="3.825336e-06 7.463084e-05 7.816192e-05 -1.426192e-23 -3.993337e-24 -1.267726e-24"/>
          <joint name="right_aileron" type="hinge" pos="0 0 0" axis="1.000000 0.000000 0.000000" damping="0.0216" range="-0.3500 0.3500"/>
          <geom name="right_aileron_horn_disc" type="mesh" mesh="horn_right_aileron_mesh" pos="0.003000 0.000000 0.000000" rgba="0.8824 0.9098 0.9294 0.9000" contype="0" conaffinity="0" group="1"/>
          <geom type="mesh" mesh="right_aileron_surface_mesh" rgba="0.8078 0.8510 0.8784 1.0000" contype="1" conaffinity="1"/>
        </body>
      </body>
      <body name="tail_boom" pos="0.000000 -0.375000 0.000000">
        <inertial pos="-0.000000 0.000000 0.125000" mass="0.042315" fullinertia="2.219123e-04 2.219123e-04 3.046658e-06 -2.482795e-22 -2.475877e-21 -2.848461e-23"/>
        <geom type="mesh" mesh="tail_boom_mesh" rgba="0.7490 0.8000 0.8392 1.0000" contype="1" conaffinity="1"/>
        <body name="horizontal_stab" pos="0.000000 0.000000 0.250000">
          <inertial pos="-0.001811 -0.003626 0.000959" mass="0.087664" fullinertia="4.860025e-05 3.951290e-04 4.404446e-04 -2.876700e-06 5.776825e-07 1.419099e-06"/>
          <geom type="mesh" mesh="horizontal_stab_mesh" rgba="0.8078 0.8510 0.8784 1.0000" contype="1" conaffinity="1"/>
          <geom name="elevator_servo" type="mesh" mesh="servo_SCS0009_mesh" pos="-0.011250 -0.025000 0.005800" quat="0.707107 0.000000 0.707107 0.000000" rgba="0.0941 0.1255 0.1490 1.0000" contype="0" conaffinity="0" group="1"/>
          <geom name="screw_elevator_ear_1" type="mesh" mesh="hardware_M2_shc_mesh" pos="-0.007750 -0.025000 -0.008200" quat="0.707107 0.000000 0.707107 0.000000" rgba="0.2235 0.2941 0.3490 0.9000" contype="0" conaffinity="0" group="1"/>
          <geom name="screw_elevator_ear_2" type="mesh" mesh="hardware_M2_shc_mesh" pos="-0.007750 -0.025000 0.019800" quat="0.707107 0.000000 0.707107 0.000000" rgba="0.2235 0.2941 0.3490 0.9000" contype="0" conaffinity="0" group="1"/>
          <geom name="horn_elevator_out_1" type="mesh" mesh="hardware_M2_shc_mesh" pos="0.002000 -0.021000 -0.004000" quat="0.707107 0.000000 -0.707107 0.000000" rgba="0.2235 0.2941 0.3490 0.9000" contype="0" conaffinity="0" group="1"/>
          <geom name="horn_elevator_out_2" type="mesh" mesh="hardware_M2_shc_mesh" pos="0.002000 -0.029000 -0.004000" quat="0.707107 0.000000 -0.707107 0.000000" rgba="0.2235 0.2941 0.3490 0.9000" contype="0" conaffinity="0" group="1"/>
          <geom name="horn_elevator_out_3" type="mesh" mesh="hardware_M2_shc_mesh" pos="0.002000 -0.021000 0.004000" quat="0.707107 0.000000 -0.707107 0.000000" rgba="0.2235 0.2941 0.3490 0.9000" contype="0" conaffinity="0" group="1"/>
          <geom name="horn_elevator_out_4" type="mesh" mesh="hardware_M2_shc_mesh" pos="0.002000 -0.029000 0.004000" quat="0.707107 0.000000 -0.707107 0.000000" rgba="0.2235 0.2941 0.3490 0.9000" contype="0" conaffinity="0" group="1"/>
          <body name="elevator_surface" pos="0.000000 -0.025000 0.000000">
            <inertial pos="-0.000000 0.000000 0.000000" mass="0.029361" fullinertia="2.358638e-06 1.530766e-04 1.551220e-04 7.589548e-24 2.023879e-24 2.428655e-25"/>
            <joint name="elevator" type="hinge" pos="0 0 0" axis="1.000000 0.000000 0.000000" damping="0.0216" range="-0.5200 0.5200"/>
            <geom name="elevator_horn_disc" type="mesh" mesh="horn_elevator_mesh" pos="0.003000 0.000000 0.000000" rgba="0.8824 0.9098 0.9294 0.9000" contype="0" conaffinity="0" group="1"/>
            <geom type="mesh" mesh="elevator_surface_mesh" rgba="0.8078 0.8510 0.8784 1.0000" contype="1" conaffinity="1"/>
          </body>
        </body>
        <body name="vertical_fin" pos="0.000000 0.000000 0.250000">
          <inertial pos="-0.002502 -0.001343 -0.004839" mass="0.033936" fullinertia="3.608452e-05 2.012333e-05 1.932338e-05 -1.357307e-06 -3.139326e-07 -2.668705e-06"/>
          <geom type="mesh" mesh="vertical_fin_mesh" rgba="0.8078 0.8510 0.8784 1.0000" contype="1" conaffinity="1"/>
          <geom name="rudder_servo" type="mesh" mesh="servo_SCS0009_mesh" pos="-0.005800 -0.025000 -0.011250" quat="1.000000 0.000000 0.000000 0.000000" rgba="0.0941 0.1255 0.1490 1.0000" contype="0" conaffinity="0" group="1"/>
          <geom name="screw_rudder_ear_1" type="mesh" mesh="hardware_M2_shc_mesh" pos="0.008200 -0.025000 -0.007750" quat="1.000000 0.000000 0.000000 0.000000" rgba="0.2235 0.2941 0.3490 0.9000" contype="0" conaffinity="0" group="1"/>
          <geom name="screw_rudder_ear_2" type="mesh" mesh="hardware_M2_shc_mesh" pos="-0.019800 -0.025000 -0.007750" quat="1.000000 0.000000 0.000000 0.000000" rgba="0.2235 0.2941 0.3490 0.9000" contype="0" conaffinity="0" group="1"/>
          <geom name="horn_rudder_out_1" type="mesh" mesh="hardware_M2_shc_mesh" pos="0.004000 -0.021000 0.002000" quat="0.000000 0.000000 -1.000000 0.000000" rgba="0.2235 0.2941 0.3490 0.9000" contype="0" conaffinity="0" group="1"/>
          <geom name="horn_rudder_out_2" type="mesh" mesh="hardware_M2_shc_mesh" pos="0.004000 -0.029000 0.002000" quat="0.000000 0.000000 -1.000000 0.000000" rgba="0.2235 0.2941 0.3490 0.9000" contype="0" conaffinity="0" group="1"/>
          <geom name="horn_rudder_out_3" type="mesh" mesh="hardware_M2_shc_mesh" pos="-0.004000 -0.021000 0.002000" quat="0.000000 0.000000 -1.000000 0.000000" rgba="0.2235 0.2941 0.3490 0.9000" contype="0" conaffinity="0" group="1"/>
          <geom name="horn_rudder_out_4" type="mesh" mesh="hardware_M2_shc_mesh" pos="-0.004000 -0.029000 0.002000" quat="0.000000 0.000000 -1.000000 0.000000" rgba="0.2235 0.2941 0.3490 0.9000" contype="0" conaffinity="0" group="1"/>
          <body name="rudder_surface" pos="0.000000 -0.025000 0.000000">
            <inertial pos="0.000000 0.000000 0.000000" mass="0.011965" fullinertia="1.086861e-05 1.003502e-05 9.612237e-07 -4.948790e-26 6.598387e-25 -6.185987e-25"/>
            <joint name="rudder" type="hinge" pos="0 0 0" axis="0.000000 0.000000 1.000000" damping="0.0216" range="-0.5200 0.5200"/>
            <geom name="rudder_horn_disc" type="mesh" mesh="horn_rudder_mesh" pos="0.000000 0.000000 0.003000" rgba="0.8824 0.9098 0.9294 0.9000" contype="0" conaffinity="0" group="1"/>
            <geom type="mesh" mesh="rudder_surface_mesh" rgba="0.8078 0.8510 0.8784 1.0000" contype="1" conaffinity="1"/>
          </body>
        </body>
      </body>
    </body>
  </worldbody>
  <contact>
    <exclude body1="fuselage" body2="elevator_surface"/>
    <exclude body1="fuselage" body2="horizontal_stab"/>
    <exclude body1="fuselage" body2="left_aileron_surface"/>
    <exclude body1="fuselage" body2="left_wing"/>
    <exclude body1="fuselage" body2="right_aileron_surface"/>
    <exclude body1="fuselage" body2="right_wing"/>
    <exclude body1="fuselage" body2="rudder_surface"/>
    <exclude body1="fuselage" body2="tail_boom"/>
    <exclude body1="fuselage" body2="vertical_fin"/>
    <exclude body1="horizontal_stab" body2="elevator_surface"/>
    <exclude body1="left_wing" body2="left_aileron_surface"/>
    <exclude body1="right_wing" body2="right_aileron_surface"/>
    <exclude body1="tail_boom" body2="elevator_surface"/>
    <exclude body1="tail_boom" body2="horizontal_stab"/>
    <exclude body1="tail_boom" body2="rudder_surface"/>
    <exclude body1="tail_boom" body2="vertical_fin"/>
    <exclude body1="vertical_fin" body2="rudder_surface"/>
  </contact>
  <actuator>
    <position name="left_aileron_motor" joint="left_aileron" kp="4.5" ctrlrange="-0.3500 0.3500" forcerange="-0.23 0.23"/>
    <position name="right_aileron_motor" joint="right_aileron" kp="4.5" ctrlrange="-0.3500 0.3500" forcerange="-0.23 0.23"/>
    <position name="elevator_motor" joint="elevator" kp="4.5" ctrlrange="-0.5200 0.5200" forcerange="-0.23 0.23"/>
    <position name="rudder_motor" joint="rudder" kp="4.5" ctrlrange="-0.5200 0.5200" forcerange="-0.23 0.23"/>
  </actuator>
  <sensor>
    <jointpos name="left_aileron_pos_sensor" joint="left_aileron"/>
    <jointvel name="left_aileron_vel_sensor" joint="left_aileron"/>
    <jointpos name="right_aileron_pos_sensor" joint="right_aileron"/>
    <jointvel name="right_aileron_vel_sensor" joint="right_aileron"/>
    <jointpos name="elevator_pos_sensor" joint="elevator"/>
    <jointvel name="elevator_vel_sensor" joint="elevator"/>
    <jointpos name="rudder_pos_sensor" joint="rudder"/>
    <jointvel name="rudder_vel_sensor" joint="rudder"/>
    <gyro name="imu_gyro" site="imu"/>
    <accelerometer name="imu_accel" site="imu"/>
  </sensor>
</mujoco>
