<?xml version='1.0' encoding='utf-8'?>
<mujoco model="simple_plane">
  <compiler angle="radian" meshdir="meshes"/>
  <default>
    <motor ctrlrange="-1 1" gear="1.0"/>
  </default>
  <asset>
    <mesh name="fuselage_mesh" file="fuselage.stl" scale="1 1 1"/>
    <mesh name="firewall_mesh" file="firewall.stl" scale="1 1 1"/>
    <mesh name="left_wing_mesh" file="left_wing.stl" scale="1 1 1"/>
    <mesh name="left_aileron_surface_mesh" file="left_aileron_surface.stl" scale="1 1 1"/>
    <mesh name="right_wing_mesh" file="right_wing.stl" scale="1 1 1"/>
    <mesh name="right_aileron_surface_mesh" file="right_aileron_surface.stl" scale="1 1 1"/>
    <mesh name="tail_boom_mesh" file="tail_boom.stl" scale="1 1 1"/>
    <mesh name="horizontal_stab_mesh" file="horizontal_stab.stl" scale="1 1 1"/>
    <mesh name="elevator_surface_mesh" file="elevator_surface.stl" scale="1 1 1"/>
    <mesh name="vertical_fin_mesh" file="vertical_fin.stl" scale="1 1 1"/>
    <mesh name="rudder_surface_mesh" file="rudder_surface.stl" scale="1 1 1"/>
    <mesh name="main_gear_mesh" file="main_gear.stl" scale="1 1 1"/>
    <mesh name="nose_skid_mesh" file="nose_skid.stl" scale="1 1 1"/>
    <mesh name="comp_fuselage_fc_mesh" file="comp_fuselage_fc.stl" scale="1 1 1"/>
    <mesh name="comp_fuselage_battery_mesh" file="comp_fuselage_battery.stl" scale="1 1 1"/>
    <mesh name="comp_fuselage_esc_mesh" file="comp_fuselage_esc.stl" scale="1 1 1"/>
    <mesh name="comp_firewall_motor_mesh" file="comp_firewall_motor.stl" scale="1 1 1"/>
    <mesh name="comp_firewall_prop_mesh" file="comp_firewall_prop.stl" scale="1 1 1"/>
    <mesh name="servo_SCS0009_mesh" file="servo_SCS0009.stl" scale="1 1 1"/>
    <mesh name="hardware_M3_shc_mesh" file="hardware_M3_shc.stl" scale="1 1 1"/>
    <mesh name="hardware_M2_shc_mesh" file="hardware_M2_shc.stl" scale="1 1 1"/>
    <mesh name="horn_left_aileron_mesh" file="horn_left_aileron.stl" scale="1 1 1"/>
    <mesh name="horn_right_aileron_mesh" file="horn_right_aileron.stl" scale="1 1 1"/>
    <mesh name="horn_elevator_mesh" file="horn_elevator.stl" scale="1 1 1"/>
    <mesh name="horn_rudder_mesh" file="horn_rudder.stl" scale="1 1 1"/>
  </asset>
  <worldbody>
    <body name="fuselage" pos="0 0 0.0325">
      <freejoint name="root"/>
      <inertial pos="-0.000000 0.000000 -0.000859" mass="0.281790" fullinertia="2.020797e-03 1.849387e-04 2.125762e-03 2.616598e-22 2.625809e-23 -2.283958e-21"/>
      <geom type="mesh" mesh="fuselage_mesh" rgba="0.8078 0.8510 0.8784 1.0000" contype="1" conaffinity="1"/>
      <site name="imu" pos="0 0 0" size="0.005"/>
      <geom name="comp_fuselage_fc" type="mesh" mesh="comp_fuselage_fc_mesh" pos="0.000000 0.000000 0.018500" rgba="0.0588 0.6000 0.3765 1.0000" contype="0" conaffinity="0" group="1"/>
      <geom name="comp_fuselage_battery" type="mesh" mesh="comp_fuselage_battery_mesh" pos="0.000000 0.000000 0.000000" rgba="0.0745 0.4863 0.7412 1.0000" contype="0" conaffinity="0" group="1"/>
      <geom name="comp_fuselage_esc" type="mesh" mesh="comp_fuselage_esc_mesh" pos="0.000000 0.000000 -0.017000" rgba="0.0941 0.1255 0.1490 1.0000" contype="0" conaffinity="0" group="1"/>
      <geom name="mount_fuselage_fc_fc_1" type="mesh" mesh="hardware_M3_shc_mesh" pos="0.015250 0.015250 0.018500" quat="0.000000 0.000000 -1.000000 0.000000" rgba="0.2235 0.2941 0.3490 0.9000" contype="0" conaffinity="0" group="1"/>
      <geom name="mount_fuselage_fc_fc_2" type="mesh" mesh="hardware_M3_shc_mesh" pos="0.015250 -0.015250 0.018500" quat="0.000000 0.000000 -1.000000 0.000000" rgba="0.2235 0.2941 0.3490 0.9000" contype="0" conaffinity="0" group="1"/>
      <geom name="mount_fuselage_fc_fc_3" type="mesh" mesh="hardware_M3_shc_mesh" pos="-0.015250 0.015250 0.018500" quat="0.000000 0.000000 -1.000000 0.000000" rgba="0.2235 0.2941 0.3490 0.9000" contype="0" conaffinity="0" group="1"/>
      <geom name="mount_fuselage_fc_fc_4" type="mesh" mesh="hardware_M3_shc_mesh" pos="-0.015250 -0.015250 0.018500" quat="0.000000 0.000000 -1.000000 0.000000" rgba="0.2235 0.2941 0.3490 0.9000" contype="0" conaffinity="0" group="1"/>
      <body name="firewall" pos="0.000000 0.200000 0.000000">
        <inertial pos="-0.000000 -0.029633 -0.000000" mass="0.068910" fullinertia="1.343712e-04 5.207531e-05 1.777468e-04 1.309218e-22 4.567487e-23 5.385994e-22"/>
        <geom type="mesh" mesh="firewall_mesh" rgba="0.8078 0.8510 0.8784 1.0000" contype="1" conaffinity="1"/>
        <geom name="comp_firewall_motor" type="mesh" mesh="comp_firewall_motor_mesh" pos="0.000000 -0.016500 0.000000" rgba="0.0941 0.1255 0.1490 1.0000" contype="0" conaffinity="0" group="1" quat="0.707107 -0.707107 0.000000 0.000000"/>
        <geom name="comp_firewall_prop" type="mesh" mesh="comp_firewall_prop_mesh" pos="0.000000 -0.111800 0.000000" rgba="0.0941 0.1255 0.1490 1.0000" contype="0" conaffinity="0" group="1"/>
      </body>
      <body name="left_wing" pos="-0.270000 0.050000 0.022000">
        <inertial pos="-0.001292 -0.006038 0.000666" mass="0.121577" fullinertia="2.144630e-04 1.996915e-03 2.208330e-03 -6.745424e-06 6.793912e-07 3.481799e-06"/>
        <geom type="mesh" mesh="left_wing_mesh" rgba="0.8078 0.8510 0.8784 1.0000" contype="1" conaffinity="1"/>
        <geom name="left_aileron_servo" type="mesh" mesh="servo_SCS0009_mesh" pos="-0.011250 -0.055000 0.005800" quat="0.707107 0.000000 0.707107 0.000000" rgba="0.0941 0.1255 0.1490 1.0000" contype="0" conaffinity="0" group="1"/>
        <geom name="screw_left_aileron_ear_1" type="mesh" mesh="hardware_M2_shc_mesh" pos="-0.007750 -0.055000 -0.008200" quat="0.707107 0.000000 0.707107 0.000000" rgba="0.2235 0.2941 0.3490 0.9000" contype="0" conaffinity="0" group="1"/>
        <geom name="screw_left_aileron_ear_2" type="mesh" mesh="hardware_M2_shc_mesh" pos="-0.007750 -0.055000 0.019800" quat="0.707107 0.000000 0.707107 0.000000" rgba="0.2235 0.2941 0.3490 0.9000" contype="0" conaffinity="0" group="1"/>
        <geom name="horn_left_aileron_out_1" type="mesh" mesh="hardware_M2_shc_mesh" pos="0.002000 -0.051000 -0.004000" quat="0.707107 0.000000 -0.707107 0.000000" rgba="0.2235 0.2941 0.3490 0.9000" contype="0" conaffinity="0" group="1"/>
        <geom name="horn_left_aileron_out_2" type="mesh" mesh="hardware_M2_shc_mesh" pos="0.002000 -0.059000 -0.004000" quat="0.707107 0.000000 -0.707107 0.000000" rgba="0.2235 0.2941 0.3490 0.9000" contype="0" conaffinity="0" group="1"/>
        <geom name="horn_left_aileron_out_3" type="mesh" mesh="hardware_M2_shc_mesh" pos="0.002000 -0.051000 0.004000" quat="0.707107 0.000000 -0.707107 0.000000" rgba="0.2235 0.2941 0.3490 0.9000" contype="0" conaffinity="0" group="1"/>
        <geom name="horn_left_aileron_out_4" type="mesh" mesh="hardware_M2_shc_mesh" pos="0.002000 -0.059000 0.004000" quat="0.707107 0.000000 -0.707107 0.000000" rgba="0.2235 0.2941 0.3490 0.9000" contype="0" conaffinity="0" group="1"/>
        <body name="left_aileron_surface" pos="0.000000 -0.055000 0.000000">
          <inertial pos="0.000000 -0.000000 0.000000" mass="0.012374" fullinertia="1.289000e-06 4.993586e-05 5.117330e-05 -2.251890e-23 3.948119e-24 5.815832e-25"/>
          <joint name="left_aileron" type="hinge" pos="0 0 0" axis="1.000000 0.000000 0.000000" damping="0.0216" range="-0.3500 0.3500"/>
          <geom name="left_aileron_horn_disc" type="mesh" mesh="horn_left_aileron_mesh" pos="0.003000 0.000000 0.000000" rgba="0.8824 0.9098 0.9294 0.9000" contype="0" conaffinity="0" group="1"/>
          <geom type="mesh" mesh="left_aileron_surface_mesh" rgba="0.8078 0.8510 0.8784 1.0000" contype="1" conaffinity="1"/>
        </body>
      </body>
      <body name="right_wing" pos="0.270000 0.050000 0.022000">
        <inertial pos="-0.001292 -0.006038 0.000666" mass="0.121577" fullinertia="2.144630e-04 1.996915e-03 2.208330e-03 -6.745424e-06 6.793912e-07 3.481799e-06"/>
        <geom type="mesh" mesh="right_wing_mesh" rgba="0.8078 0.8510 0.8784 1.0000" contype="1" conaffinity="1"/>
        <geom name="right_aileron_servo" type="mesh" mesh="servo_SCS0009_mesh" pos="-0.011250 -0.055000 0.005800" quat="0.707107 0.000000 0.707107 0.000000" rgba="0.0941 0.1255 0.1490 1.0000" contype="0" conaffinity="0" group="1"/>
        <geom name="screw_right_aileron_ear_1" type="mesh" mesh="hardware_M2_shc_mesh" pos="-0.007750 -0.055000 -0.008200" quat="0.707107 0.000000 0.707107 0.000000" rgba="0.2235 0.2941 0.3490 0.9000" contype="0" conaffinity="0" group="1"/>
        <geom name="screw_right_aileron_ear_2" type="mesh" mesh="hardware_M2_shc_mesh" pos="-0.007750 -0.055000 0.019800" quat="0.707107 0.000000 0.707107 0.000000" rgba="0.2235 0.2941 0.3490 0.9000" contype="0" conaffinity="0" group="1"/>
        <geom name="horn_right_aileron_out_1" type="mesh" mesh="hardware_M2_shc_mesh" pos="0.002000 -0.051000 -0.004000" quat="0.707107 0.000000 -0.707107 0.000000" rgba="0.2235 0.2941 0.3490 0.9000" contype="0" conaffinity="0" group="1"/>
        <geom name="horn_right_aileron_out_2" type="mesh" mesh="hardware_M2_shc_mesh" pos="0.002000 -0.059000 -0.004000" quat="0.707107 0.000000 -0.707107 0.000000" rgba="0.2235 0.2941 0.3490 0.9000" contype="0" conaffinity="0" group="1"/>
        <geom name="horn_right_aileron_out_3" type="mesh" mesh="hardware_M2_shc_mesh" pos="0.002000 -0.051000 0.004000" quat="0.707107 0.000000 -0.707107 0.000000" rgba="0.2235 0.2941 0.3490 0.9000" contype="0" conaffinity="0" group="1"/>
        <geom name="horn_right_aileron_out_4" type="mesh" mesh="hardware_M2_shc_mesh" pos="0.002000 -0.059000 0.004000" quat="0.707107 0.000000 -0.707107 0.000000" rgba="0.2235 0.2941 0.3490 0.9000" contype="0" conaffinity="0" group="1"/>
        <body name="right_aileron_surface" pos="0.000000 -0.055000 0.000000">
          <inertial pos="0.000000 -0.000000 0.000000" mass="0.012374" fullinertia="1.289000e-06 4.993586e-05 5.117330e-05 -2.251890e-23 3.948119e-24 5.815832e-25"/>
          <joint name="right_aileron" type="hinge" pos="0 0 0" axis="1.000000 0.000000 0.000000" damping="0.0216" range="-0.3500 0.3500"/>
          <geom name="right_aileron_horn_disc" type="mesh" mesh="horn_right_aileron_mesh" pos="0.003000 0.000000 0.000000" rgba="0.8824 0.9098 0.9294 0.9000" contype="0" conaffinity="0" group="1"/>
          <geom type="mesh" mesh="right_aileron_surface_mesh" rgba="0.8078 0.8510 0.8784 1.0000" contype="1" conaffinity="1"/>
        </body>
      </body>
      <body name="tail_boom" pos="0.000000 -0.300000 0.000000">
        <inertial pos="0.000000 -0.000000 0.125000" mass="0.016482" fullinertia="8.625607e-05 8.625607e-05 8.241026e-07 -4.422942e-23 8.679441e-23 -2.130255e-23"/>
        <geom type="mesh" mesh="tail_boom_mesh" rgba="0.8078 0.8510 0.8784 1.0000" contype="1" conaffinity="1"/>
        <body name="horizontal_stab" pos="0.000000 0.000000 0.250000">
          <inertial pos="-0.003928 -0.008388 0.002023" mass="0.040123" fullinertia="1.786176e-05 1.112097e-04 1.267209e-04 -2.167755e-06 4.633982e-07 1.119923e-06"/>
          <geom type="mesh" mesh="horizontal_stab_mesh" rgba="0.8078 0.8510 0.8784 1.0000" contype="1" conaffinity="1"/>
          <geom name="elevator_servo" type="mesh" mesh="servo_SCS0009_mesh" pos="-0.011250 -0.025000 0.005800" quat="0.707107 0.000000 0.707107 0.000000" rgba="0.0941 0.1255 0.1490 1.0000" contype="0" conaffinity="0" group="1"/>
          <geom name="screw_elevator_ear_1" type="mesh" mesh="hardware_M2_shc_mesh" pos="-0.007750 -0.025000 -0.008200" quat="0.707107 0.000000 0.707107 0.000000" rgba="0.2235 0.2941 0.3490 0.9000" contype="0" conaffinity="0" group="1"/>
          <geom name="screw_elevator_ear_2" type="mesh" mesh="hardware_M2_shc_mesh" pos="-0.007750 -0.025000 0.019800" quat="0.707107 0.000000 0.707107 0.000000" rgba="0.2235 0.2941 0.3490 0.9000" contype="0" conaffinity="0" group="1"/>
          <geom name="horn_elevator_out_1" type="mesh" mesh="hardware_M2_shc_mesh" pos="0.002000 -0.021000 -0.004000" quat="0.707107 0.000000 -0.707107 0.000000" rgba="0.2235 0.2941 0.3490 0.9000" contype="0" conaffinity="0" group="1"/>
          <geom name="horn_elevator_out_2" type="mesh" mesh="hardware_M2_shc_mesh" pos="0.002000 -0.029000 -0.004000" quat="0.707107 0.000000 -0.707107 0.000000" rgba="0.2235 0.2941 0.3490 0.9000" contype="0" conaffinity="0" group="1"/>
          <geom name="horn_elevator_out_3" type="mesh" mesh="hardware_M2_shc_mesh" pos="0.002000 -0.021000 0.004000" quat="0.707107 0.000000 -0.707107 0.000000" rgba="0.2235 0.2941 0.3490 0.9000" contype="0" conaffinity="0" group="1"/>
          <geom name="horn_elevator_out_4" type="mesh" mesh="hardware_M2_shc_mesh" pos="0.002000 -0.029000 0.004000" quat="0.707107 0.000000 -0.707107 0.000000" rgba="0.2235 0.2941 0.3490 0.9000" contype="0" conaffinity="0" group="1"/>
          <body name="elevator_surface" pos="0.000000 -0.025000 0.000000">
            <inertial pos="0.000000 -0.000000 0.000000" mass="0.009110" fullinertia="4.934800e-07 3.676426e-05 3.721978e-05 3.014379e-24 8.289541e-25 2.569073e-25"/>
            <joint name="elevator" type="hinge" pos="0 0 0" axis="1.000000 0.000000 0.000000" damping="0.0216" range="-0.5200 0.5200"/>
            <geom name="elevator_horn_disc" type="mesh" mesh="horn_elevator_mesh" pos="0.003000 0.000000 0.000000" rgba="0.8824 0.9098 0.9294 0.9000" contype="0" conaffinity="0" group="1"/>
            <geom type="mesh" mesh="elevator_surface_mesh" rgba="0.8078 0.8510 0.8784 1.0000" contype="1" conaffinity="1"/>
          </body>
        </body>
        <body name="vertical_fin" pos="0.000000 0.000000 0.250000">
          <inertial pos="-0.003766 -0.011716 -0.007367" mass="0.021668" fullinertia="1.504840e-05 8.153826e-06 9.772277e-06 -7.391766e-07 -1.837651e-07 -1.364479e-06"/>
          <geom type="mesh" mesh="vertical_fin_mesh" rgba="0.8078 0.8510 0.8784 1.0000" contype="1" conaffinity="1"/>
          <geom name="rudder_servo" type="mesh" mesh="servo_SCS0009_mesh" pos="-0.005800 -0.025000 -0.011250" quat="1.000000 0.000000 0.000000 0.000000" rgba="0.0941 0.1255 0.1490 1.0000" contype="0" conaffinity="0" group="1"/>
          <geom name="screw_rudder_ear_1" type="mesh" mesh="hardware_M2_shc_mesh" pos="0.008200 -0.025000 -0.007750" quat="1.000000 0.000000 0.000000 0.000000" rgba="0.2235 0.2941 0.3490 0.9000" contype="0" conaffinity="0" group="1"/>
          <geom name="screw_rudder_ear_2" type="mesh" mesh="hardware_M2_shc_mesh" pos="-0.019800 -0.025000 -0.007750" quat="1.000000 0.000000 0.000000 0.000000" rgba="0.2235 0.2941 0.3490 0.9000" contype="0" conaffinity="0" group="1"/>
          <geom name="horn_rudder_out_1" type="mesh" mesh="hardware_M2_shc_mesh" pos="0.004000 -0.021000 0.002000" quat="0.000000 0.000000 -1.000000 0.000000" rgba="0.2235 0.2941 0.3490 0.9000" contype="0" conaffinity="0" group="1"/>
          <geom name="horn_rudder_out_2" type="mesh" mesh="hardware_M2_shc_mesh" pos="0.004000 -0.029000 0.002000" quat="0.000000 0.000000 -1.000000 0.000000" rgba="0.2235 0.2941 0.3490 0.9000" contype="0" conaffinity="0" group="1"/>
          <geom name="horn_rudder_out_3" type="mesh" mesh="hardware_M2_shc_mesh" pos="-0.004000 -0.021000 0.002000" quat="0.000000 0.000000 -1.000000 0.000000" rgba="0.2235 0.2941 0.3490 0.9000" contype="0" conaffinity="0" group="1"/>
          <geom name="horn_rudder_out_4" type="mesh" mesh="hardware_M2_shc_mesh" pos="-0.004000 -0.029000 0.002000" quat="0.000000 0.000000 -1.000000 0.000000" rgba="0.2235 0.2941 0.3490 0.9000" contype="0" conaffinity="0" group="1"/>
          <body name="rudder_surface" pos="0.000000 -0.025000 0.000000">
            <inertial pos="0.000000 0.000000 -0.000000" mass="0.004160" fullinertia="3.024783e-06 2.820588e-06 2.291555e-07 6.691229e-26 -6.882407e-26 -1.720602e-24"/>
            <joint name="rudder" type="hinge" pos="0 0 0" axis="0.000000 0.000000 1.000000" damping="0.0216" range="-0.5200 0.5200"/>
            <geom name="rudder_horn_disc" type="mesh" mesh="horn_rudder_mesh" pos="0.000000 0.000000 0.003000" rgba="0.8824 0.9098 0.9294 0.9000" contype="0" conaffinity="0" group="1"/>
            <geom type="mesh" mesh="rudder_surface_mesh" rgba="0.8078 0.8510 0.8784 1.0000" contype="1" conaffinity="1"/>
          </body>
        </body>
      </body>
      <body name="main_gear" pos="0.000000 0.030000 -0.022000">
        <inertial pos="-0.000000 0.000000 0.000000" mass="0.034829" fullinertia="1.052120e-05 1.265446e-04 1.161686e-04 -4.801618e-25 5.761942e-23 4.465505e-24"/>
        <geom type="mesh" mesh="main_gear_mesh" rgba="0.8078 0.8510 0.8784 1.0000" contype="1" conaffinity="1"/>
      </body>
      <body name="nose_skid" pos="0.000000 0.180000 -0.022000">
        <inertial pos="0.000000 0.000000 0.000000" mass="0.003348" fullinertia="3.138750e-07 1.255500e-07 3.138750e-07 -1.615484e-25 -8.077419e-26 -1.615484e-25"/>
        <geom type="mesh" mesh="nose_skid_mesh" rgba="0.8078 0.8510 0.8784 1.0000" contype="1" conaffinity="1"/>
      </body>
    </body>
  </worldbody>
  <contact>
    <exclude body1="fuselage" body2="elevator_surface"/>
    <exclude body1="fuselage" body2="firewall"/>
    <exclude body1="fuselage" body2="horizontal_stab"/>
    <exclude body1="fuselage" body2="left_aileron_surface"/>
    <exclude body1="fuselage" body2="left_wing"/>
    <exclude body1="fuselage" body2="main_gear"/>
    <exclude body1="fuselage" body2="nose_skid"/>
    <exclude body1="fuselage" body2="right_aileron_surface"/>
    <exclude body1="fuselage" body2="right_wing"/>
    <exclude body1="fuselage" body2="rudder_surface"/>
    <exclude body1="fuselage" body2="tail_boom"/>
    <exclude body1="fuselage" body2="vertical_fin"/>
    <exclude body1="horizontal_stab" body2="elevator_surface"/>
    <exclude body1="left_wing" body2="left_aileron_surface"/>
    <exclude body1="right_wing" body2="right_aileron_surface"/>
    <exclude body1="tail_boom" body2="elevator_surface"/>
    <exclude body1="tail_boom" body2="horizontal_stab"/>
    <exclude body1="tail_boom" body2="rudder_surface"/>
    <exclude body1="tail_boom" body2="vertical_fin"/>
    <exclude body1="vertical_fin" body2="rudder_surface"/>
  </contact>
  <actuator>
    <position name="left_aileron_motor" joint="left_aileron" kp="4.5" ctrlrange="-0.3500 0.3500" forcerange="-0.23 0.23"/>
    <position name="right_aileron_motor" joint="right_aileron" kp="4.5" ctrlrange="-0.3500 0.3500" forcerange="-0.23 0.23"/>
    <position name="elevator_motor" joint="elevator" kp="4.5" ctrlrange="-0.5200 0.5200" forcerange="-0.23 0.23"/>
    <position name="rudder_motor" joint="rudder" kp="4.5" ctrlrange="-0.5200 0.5200" forcerange="-0.23 0.23"/>
  </actuator>
  <sensor>
    <jointpos name="left_aileron_pos_sensor" joint="left_aileron"/>
    <jointvel name="left_aileron_vel_sensor" joint="left_aileron"/>
    <jointpos name="right_aileron_pos_sensor" joint="right_aileron"/>
    <jointvel name="right_aileron_vel_sensor" joint="right_aileron"/>
    <jointpos name="elevator_pos_sensor" joint="elevator"/>
    <jointvel name="elevator_vel_sensor" joint="elevator"/>
    <jointpos name="rudder_pos_sensor" joint="rudder"/>
    <jointvel name="rudder_vel_sensor" joint="rudder"/>
    <gyro name="imu_gyro" site="imu"/>
    <accelerometer name="imu_accel" site="imu"/>
  </sensor>
</mujoco>
