<?xml version='1.0' encoding='utf-8'?>
<mujoco model="wheeler_base">
  <compiler angle="radian" meshdir="meshes"/>
  <default>
    <motor ctrlrange="-1 1" gear="1.0"/>
  </default>
  <asset>
    <mesh name="base_mesh" file="base.stl" scale="1 1 1"/>
    <mesh name="left_rim_mesh" file="left_rim.stl" scale="1 1 1"/>
    <mesh name="right_rim_mesh" file="right_rim.stl" scale="1 1 1"/>
    <mesh name="comp_base_battery_mesh" file="comp_base_battery.stl" scale="1 1 1"/>
    <mesh name="comp_base_camera_mesh" file="comp_base_camera.stl" scale="1 1 1"/>
    <mesh name="comp_base_pi_mesh" file="comp_base_pi.stl" scale="1 1 1"/>
    <mesh name="servo_STS3215_mesh" file="servo_STS3215.stl" scale="1 1 1"/>
  </asset>
  <worldbody>
    <body name="base" pos="0 0 0.0450">
      <freejoint name="root"/>
      <inertial pos="0.002947 0.000294 0.004241" mass="0.233399" fullinertia="1.383622e-04 4.729537e-04 4.994413e-04 5.860502e-07 7.539468e-06 3.785148e-07"/>
      <geom type="mesh" mesh="base_mesh" rgba="0.9 0.9 0.9 1.0" contype="1" conaffinity="1"/>
      <camera name="camera_cam" fovy="72.0" pos="0.000000 0.028000 0.000000" euler="0 3.141592653589793 0"/>
      <site name="imu" pos="0 0 0" size="0.005"/>
      <geom name="comp_base_battery" type="mesh" mesh="comp_base_battery_mesh" pos="0.000000 0.000000 -0.013500" rgba="0.2 0.2 0.8 1.0" contype="0" conaffinity="0" group="1"/>
      <geom name="comp_base_camera" type="mesh" mesh="comp_base_camera_mesh" pos="0.000000 0.028000 0.000000" rgba="0.1 0.4 0.15 1.0" contype="0" conaffinity="0" group="1"/>
      <geom name="comp_base_pi" type="mesh" mesh="comp_base_pi_mesh" pos="0.000000 0.000000 0.020000" rgba="0.13 0.55 0.13 1.0" contype="0" conaffinity="0" group="1"/>
      <geom name="left_wheel_servo" type="mesh" mesh="servo_STS3215_mesh" pos="-0.048700 0.000000 0.012500" quat="0.000000 -0.707107 0.000000 0.707107" rgba="0.15 0.15 0.15 1.0" contype="0" conaffinity="0" group="1"/>
      <geom name="right_wheel_servo" type="mesh" mesh="servo_STS3215_mesh" pos="0.048700 0.000000 0.012500" quat="0.707107 0.000000 0.707107 0.000000" rgba="0.15 0.15 0.15 1.0" contype="0" conaffinity="0" group="1"/>
      <geom name="screw_left_wheel_ear_1" type="cylinder" size="0.0016 0.001" pos="-0.031350 0.010250 -0.004500" rgba="0.7 0.7 0.7 0.9" contype="0" conaffinity="0" group="1"/>
      <geom name="screw_left_wheel_ear_2" type="cylinder" size="0.0016 0.001" pos="-0.031350 0.010250 0.012500" rgba="0.7 0.7 0.7 0.9" contype="0" conaffinity="0" group="1"/>
      <geom name="screw_left_wheel_ear_3" type="cylinder" size="0.0016 0.001" pos="-0.031350 -0.010250 -0.004500" rgba="0.7 0.7 0.7 0.9" contype="0" conaffinity="0" group="1"/>
      <geom name="screw_left_wheel_ear_4" type="cylinder" size="0.0016 0.001" pos="-0.031350 -0.010250 0.012500" rgba="0.7 0.7 0.7 0.9" contype="0" conaffinity="0" group="1"/>
      <geom name="screw_left_wheel_ear_5" type="cylinder" size="0.0016 0.001" pos="-0.031350 0.010250 0.029500" rgba="0.7 0.7 0.7 0.9" contype="0" conaffinity="0" group="1"/>
      <geom name="screw_left_wheel_ear_6" type="cylinder" size="0.0016 0.001" pos="-0.031350 -0.010250 0.029500" rgba="0.7 0.7 0.7 0.9" contype="0" conaffinity="0" group="1"/>
      <geom name="horn_left_wheel_out_1" type="cylinder" size="0.0013 0.001" pos="-0.066700 -0.004950 0.004950" rgba="0.7 0.7 0.7 0.9" contype="0" conaffinity="0" group="1"/>
      <geom name="horn_left_wheel_out_2" type="cylinder" size="0.0013 0.001" pos="-0.066700 -0.004950 -0.004950" rgba="0.7 0.7 0.7 0.9" contype="0" conaffinity="0" group="1"/>
      <geom name="horn_left_wheel_out_3" type="cylinder" size="0.0013 0.001" pos="-0.066700 0.004950 0.004950" rgba="0.7 0.7 0.7 0.9" contype="0" conaffinity="0" group="1"/>
      <geom name="horn_left_wheel_out_4" type="cylinder" size="0.0013 0.001" pos="-0.066700 0.004950 -0.004950" rgba="0.7 0.7 0.7 0.9" contype="0" conaffinity="0" group="1"/>
      <geom name="rear_left_wheel_rear_1" type="cylinder" size="0.0013 0.001" pos="-0.031100 -0.004950 0.004950" rgba="0.7 0.7 0.7 0.9" contype="0" conaffinity="0" group="1"/>
      <geom name="rear_left_wheel_rear_2" type="cylinder" size="0.0013 0.001" pos="-0.031100 -0.004950 -0.004950" rgba="0.7 0.7 0.7 0.9" contype="0" conaffinity="0" group="1"/>
      <geom name="rear_left_wheel_rear_3" type="cylinder" size="0.0013 0.001" pos="-0.031100 0.004950 0.004950" rgba="0.7 0.7 0.7 0.9" contype="0" conaffinity="0" group="1"/>
      <geom name="rear_left_wheel_rear_4" type="cylinder" size="0.0013 0.001" pos="-0.031100 0.004950 -0.004950" rgba="0.7 0.7 0.7 0.9" contype="0" conaffinity="0" group="1"/>
      <geom name="screw_right_wheel_ear_1" type="cylinder" size="0.0016 0.001" pos="0.031350 -0.010250 -0.004500" rgba="0.7 0.7 0.7 0.9" contype="0" conaffinity="0" group="1"/>
      <geom name="screw_right_wheel_ear_2" type="cylinder" size="0.0016 0.001" pos="0.031350 -0.010250 0.012500" rgba="0.7 0.7 0.7 0.9" contype="0" conaffinity="0" group="1"/>
      <geom name="screw_right_wheel_ear_3" type="cylinder" size="0.0016 0.001" pos="0.031350 0.010250 -0.004500" rgba="0.7 0.7 0.7 0.9" contype="0" conaffinity="0" group="1"/>
      <geom name="screw_right_wheel_ear_4" type="cylinder" size="0.0016 0.001" pos="0.031350 0.010250 0.012500" rgba="0.7 0.7 0.7 0.9" contype="0" conaffinity="0" group="1"/>
      <geom name="screw_right_wheel_ear_5" type="cylinder" size="0.0016 0.001" pos="0.031350 -0.010250 0.029500" rgba="0.7 0.7 0.7 0.9" contype="0" conaffinity="0" group="1"/>
      <geom name="screw_right_wheel_ear_6" type="cylinder" size="0.0016 0.001" pos="0.031350 0.010250 0.029500" rgba="0.7 0.7 0.7 0.9" contype="0" conaffinity="0" group="1"/>
      <geom name="horn_right_wheel_out_1" type="cylinder" size="0.0013 0.001" pos="0.066700 0.004950 0.004950" rgba="0.7 0.7 0.7 0.9" contype="0" conaffinity="0" group="1"/>
      <geom name="horn_right_wheel_out_2" type="cylinder" size="0.0013 0.001" pos="0.066700 0.004950 -0.004950" rgba="0.7 0.7 0.7 0.9" contype="0" conaffinity="0" group="1"/>
      <geom name="horn_right_wheel_out_3" type="cylinder" size="0.0013 0.001" pos="0.066700 -0.004950 0.004950" rgba="0.7 0.7 0.7 0.9" contype="0" conaffinity="0" group="1"/>
      <geom name="horn_right_wheel_out_4" type="cylinder" size="0.0013 0.001" pos="0.066700 -0.004950 -0.004950" rgba="0.7 0.7 0.7 0.9" contype="0" conaffinity="0" group="1"/>
      <geom name="rear_right_wheel_rear_1" type="cylinder" size="0.0013 0.001" pos="0.031100 0.004950 0.004950" rgba="0.7 0.7 0.7 0.9" contype="0" conaffinity="0" group="1"/>
      <geom name="rear_right_wheel_rear_2" type="cylinder" size="0.0013 0.001" pos="0.031100 0.004950 -0.004950" rgba="0.7 0.7 0.7 0.9" contype="0" conaffinity="0" group="1"/>
      <geom name="rear_right_wheel_rear_3" type="cylinder" size="0.0013 0.001" pos="0.031100 -0.004950 0.004950" rgba="0.7 0.7 0.7 0.9" contype="0" conaffinity="0" group="1"/>
      <geom name="rear_right_wheel_rear_4" type="cylinder" size="0.0013 0.001" pos="0.031100 -0.004950 -0.004950" rgba="0.7 0.7 0.7 0.9" contype="0" conaffinity="0" group="1"/>
      <geom name="mount_base_camera_m1" type="cylinder" size="0.0011 0.001" pos="-0.010500 0.018500 0.000000" rgba="0.7 0.7 0.7 0.9" contype="0" conaffinity="0" group="1"/>
      <geom name="mount_base_camera_m2" type="cylinder" size="0.0011 0.001" pos="0.010500 0.018500 0.000000" rgba="0.7 0.7 0.7 0.9" contype="0" conaffinity="0" group="1"/>
      <geom name="mount_base_camera_m3" type="cylinder" size="0.0011 0.001" pos="-0.010500 0.031000 0.000000" rgba="0.7 0.7 0.7 0.9" contype="0" conaffinity="0" group="1"/>
      <geom name="mount_base_camera_m4" type="cylinder" size="0.0011 0.001" pos="0.010500 0.031000 0.000000" rgba="0.7 0.7 0.7 0.9" contype="0" conaffinity="0" group="1"/>
      <geom name="mount_base_pi_m1" type="cylinder" size="0.0014 0.001" pos="0.011500 -0.029000 0.020000" rgba="0.7 0.7 0.7 0.9" contype="0" conaffinity="0" group="1"/>
      <geom name="mount_base_pi_m2" type="cylinder" size="0.0014 0.001" pos="0.011500 0.029000 0.020000" rgba="0.7 0.7 0.7 0.9" contype="0" conaffinity="0" group="1"/>
      <geom name="mount_base_pi_m3" type="cylinder" size="0.0014 0.001" pos="-0.011500 -0.029000 0.020000" rgba="0.7 0.7 0.7 0.9" contype="0" conaffinity="0" group="1"/>
      <geom name="mount_base_pi_m4" type="cylinder" size="0.0014 0.001" pos="-0.011500 0.029000 0.020000" rgba="0.7 0.7 0.7 0.9" contype="0" conaffinity="0" group="1"/>
      <geom name="wire_servo_bus_base_0" type="capsule" fromto="0.000000 0.000000 0.000000 -0.032400 0.000000 0.000000" size="0.0009" rgba="0.2 0.4 1.0 0.9" contype="0" conaffinity="0" group="2"/>
      <geom name="wire_servo_bus_base_1" type="capsule" fromto="-0.032400 0.000000 0.000000 -0.032400 0.000000 0.020500" size="0.0009" rgba="0.2 0.4 1.0 0.9" contype="0" conaffinity="0" group="2"/>
      <geom name="wire_servo_bus_base_2" type="capsule" fromto="-0.032400 0.000000 0.020500 -0.032400 0.000000 0.000000" size="0.0009" rgba="0.2 0.4 1.0 0.9" contype="0" conaffinity="0" group="2"/>
      <geom name="wire_servo_bus_base_3" type="capsule" fromto="-0.032400 0.000000 0.000000 0.032400 0.000000 0.000000" size="0.0009" rgba="0.2 0.4 1.0 0.9" contype="0" conaffinity="0" group="2"/>
      <geom name="wire_servo_bus_base_4" type="capsule" fromto="0.032400 0.000000 0.000000 0.032400 0.000000 0.020500" size="0.0009" rgba="0.2 0.4 1.0 0.9" contype="0" conaffinity="0" group="2"/>
      <geom name="wire_power_base_0" type="capsule" fromto="0.036500 0.000000 -0.013500 0.036500 0.000000 0.000000" size="0.0012" rgba="0.9 0.2 0.2 0.9" contype="0" conaffinity="0" group="2"/>
      <geom name="wire_power_base_1" type="capsule" fromto="0.036500 0.000000 0.000000 -0.032500 0.000000 0.000000" size="0.0012" rgba="0.9 0.2 0.2 0.9" contype="0" conaffinity="0" group="2"/>
      <geom name="wire_power_base_2" type="capsule" fromto="-0.032500 0.000000 0.000000 -0.032500 0.000000 0.020000" size="0.0012" rgba="0.9 0.2 0.2 0.9" contype="0" conaffinity="0" group="2"/>
      <body name="left_rim" pos="-0.073200 0.000000 0.000000">
        <inertial pos="0.000000 0.000000 -0.000011" mass="0.042081" fullinertia="4.218287e-05 2.874418e-05 4.342972e-05 -2.127207e-23 2.525915e-21 -9.287670e-22"/>
        <joint name="left_wheel" type="hinge" pos="0.008200 -0.000000 -0.000000" axis="-1.000000 0.000000 0.000000" damping="0.0100"/>
        <geom type="mesh" mesh="left_rim_mesh" rgba="0.15 0.15 0.15 1.0" contype="0" conaffinity="0"/>
        <geom type="cylinder" size="0.045 0.005" quat="0.7071068 0 0.7071068 0" rgba="0.15 0.15 0.15 0.0" contype="1" conaffinity="1" friction="1.5 0.005 0.0001"/>
        <geom name="mount_left_rim_wheel_m1" type="cylinder" size="0.0015 0.001" pos="0.006350 0.000000 0.000000" rgba="0.7 0.7 0.7 0.9" contype="0" conaffinity="0" group="1"/>
        <geom name="mount_left_rim_wheel_m2" type="cylinder" size="0.0015 0.001" pos="0.004775 0.008271 0.000000" rgba="0.7 0.7 0.7 0.9" contype="0" conaffinity="0" group="1"/>
        <geom name="mount_left_rim_wheel_m3" type="cylinder" size="0.0015 0.001" pos="-0.004775 0.008271 0.000000" rgba="0.7 0.7 0.7 0.9" contype="0" conaffinity="0" group="1"/>
        <geom name="mount_left_rim_wheel_m4" type="cylinder" size="0.0015 0.001" pos="-0.006350 0.000000 0.000000" rgba="0.7 0.7 0.7 0.9" contype="0" conaffinity="0" group="1"/>
        <geom name="mount_left_rim_wheel_m5" type="cylinder" size="0.0015 0.001" pos="-0.004775 -0.008271 0.000000" rgba="0.7 0.7 0.7 0.9" contype="0" conaffinity="0" group="1"/>
        <geom name="mount_left_rim_wheel_m6" type="cylinder" size="0.0015 0.001" pos="0.004775 -0.008271 0.000000" rgba="0.7 0.7 0.7 0.9" contype="0" conaffinity="0" group="1"/>
      </body>
      <body name="right_rim" pos="0.073200 0.000000 0.000000">
        <inertial pos="-0.000000 0.000000 0.000011" mass="0.042081" fullinertia="4.218287e-05 2.874418e-05 4.342972e-05 -2.002212e-23 -3.346068e-21 5.636464e-22"/>
        <joint name="right_wheel" type="hinge" pos="-0.008200 -0.000000 -0.000000" axis="1.000000 0.000000 0.000000" damping="0.0100"/>
        <geom type="mesh" mesh="right_rim_mesh" rgba="0.15 0.15 0.15 1.0" contype="0" conaffinity="0"/>
        <geom type="cylinder" size="0.045 0.005" quat="0.7071068 0 0.7071068 0" rgba="0.15 0.15 0.15 0.0" contype="1" conaffinity="1" friction="1.5 0.005 0.0001"/>
        <geom name="mount_right_rim_wheel_m1" type="cylinder" size="0.0015 0.001" pos="0.006350 0.000000 0.000000" rgba="0.7 0.7 0.7 0.9" contype="0" conaffinity="0" group="1"/>
        <geom name="mount_right_rim_wheel_m2" type="cylinder" size="0.0015 0.001" pos="0.004775 0.008271 0.000000" rgba="0.7 0.7 0.7 0.9" contype="0" conaffinity="0" group="1"/>
        <geom name="mount_right_rim_wheel_m3" type="cylinder" size="0.0015 0.001" pos="-0.004775 0.008271 0.000000" rgba="0.7 0.7 0.7 0.9" contype="0" conaffinity="0" group="1"/>
        <geom name="mount_right_rim_wheel_m4" type="cylinder" size="0.0015 0.001" pos="-0.006350 0.000000 0.000000" rgba="0.7 0.7 0.7 0.9" contype="0" conaffinity="0" group="1"/>
        <geom name="mount_right_rim_wheel_m5" type="cylinder" size="0.0015 0.001" pos="-0.004775 -0.008271 0.000000" rgba="0.7 0.7 0.7 0.9" contype="0" conaffinity="0" group="1"/>
        <geom name="mount_right_rim_wheel_m6" type="cylinder" size="0.0015 0.001" pos="0.004775 -0.008271 0.000000" rgba="0.7 0.7 0.7 0.9" contype="0" conaffinity="0" group="1"/>
      </body>
    </body>
  </worldbody>
  <contact>
    <exclude body1="base" body2="left_rim"/>
    <exclude body1="base" body2="right_rim"/>
  </contact>
  <actuator>
    <motor name="left_wheel_motor" joint="left_wheel" gear="2.94" ctrlrange="-1 1"/>
    <motor name="right_wheel_motor" joint="right_wheel" gear="2.94" ctrlrange="-1 1"/>
  </actuator>
  <sensor>
    <jointpos name="left_wheel_pos_sensor" joint="left_wheel"/>
    <jointvel name="left_wheel_vel_sensor" joint="left_wheel"/>
    <jointpos name="right_wheel_pos_sensor" joint="right_wheel"/>
    <jointvel name="right_wheel_vel_sensor" joint="right_wheel"/>
    <gyro name="imu_gyro" site="imu"/>
    <accelerometer name="imu_accel" site="imu"/>
  </sensor>
</mujoco>
