<?xml version='1.0' encoding='utf-8'?>
<mujoco model="wheeler_arm">
  <compiler angle="radian" meshdir="meshes"/>
  <default>
    <motor ctrlrange="-1 1" gear="1.0"/>
  </default>
  <asset>
    <mesh name="base_mesh" file="base.stl" scale="1 1 1"/>
    <mesh name="left_rim_mesh" file="left_rim.stl" scale="1 1 1"/>
    <mesh name="right_rim_mesh" file="right_rim.stl" scale="1 1 1"/>
    <mesh name="turntable_mesh" file="turntable.stl" scale="1 1 1"/>
    <mesh name="upper_arm_mesh" file="upper_arm.stl" scale="1 1 1"/>
    <mesh name="forearm_mesh" file="forearm.stl" scale="1 1 1"/>
    <mesh name="hand_mesh" file="hand.stl" scale="1 1 1"/>
    <mesh name="comp_base_pi_mesh" file="comp_base_pi.stl" scale="1 1 1"/>
    <mesh name="comp_base_battery_mesh" file="comp_base_battery.stl" scale="1 1 1"/>
    <mesh name="comp_hand_camera_mesh" file="comp_hand_camera.stl" scale="1 1 1"/>
    <mesh name="servo_STS3215_mesh" file="servo_STS3215.stl" scale="1 1 1"/>
    <mesh name="hardware_M3_shc_mesh" file="hardware_M3_shc.stl" scale="1 1 1"/>
    <mesh name="hardware_M2_shc_mesh" file="hardware_M2_shc.stl" scale="1 1 1"/>
    <mesh name="hardware_M2.5_shc_mesh" file="hardware_M2.5_shc.stl" scale="1 1 1"/>
    <mesh name="horn_shoulder_yaw_mesh" file="horn_shoulder_yaw.stl" scale="1 1 1"/>
    <mesh name="horn_shoulder_pitch_mesh" file="horn_shoulder_pitch.stl" scale="1 1 1"/>
    <mesh name="horn_elbow_mesh" file="horn_elbow.stl" scale="1 1 1"/>
    <mesh name="horn_wrist_mesh" file="horn_wrist.stl" scale="1 1 1"/>
    <mesh name="wire_servo_bus_base_0_mesh" file="wire_servo_bus_base_0.stl" scale="1 1 1"/>
    <mesh name="wire_servo_bus_base_1_mesh" file="wire_servo_bus_base_1.stl" scale="1 1 1"/>
    <mesh name="wire_servo_bus_base_2_mesh" file="wire_servo_bus_base_2.stl" scale="1 1 1"/>
    <mesh name="wire_servo_bus_base_3_mesh" file="wire_servo_bus_base_3.stl" scale="1 1 1"/>
    <mesh name="wire_servo_bus_base_4_mesh" file="wire_servo_bus_base_4.stl" scale="1 1 1"/>
    <mesh name="wire_servo_bus_base_5_mesh" file="wire_servo_bus_base_5.stl" scale="1 1 1"/>
    <mesh name="wire_servo_bus_base_6_mesh" file="wire_servo_bus_base_6.stl" scale="1 1 1"/>
    <mesh name="wire_servo_bus_base_7_mesh" file="wire_servo_bus_base_7.stl" scale="1 1 1"/>
    <mesh name="wire_servo_bus_turntable_8_mesh" file="wire_servo_bus_turntable_8.stl" scale="1 1 1"/>
    <mesh name="wire_servo_bus_turntable_9_mesh" file="wire_servo_bus_turntable_9.stl" scale="1 1 1"/>
    <mesh name="wire_servo_bus_upper_arm_10_mesh" file="wire_servo_bus_upper_arm_10.stl" scale="1 1 1"/>
    <mesh name="wire_servo_bus_upper_arm_11_mesh" file="wire_servo_bus_upper_arm_11.stl" scale="1 1 1"/>
    <mesh name="wire_servo_bus_forearm_12_mesh" file="wire_servo_bus_forearm_12.stl" scale="1 1 1"/>
    <mesh name="wire_servo_bus_forearm_13_mesh" file="wire_servo_bus_forearm_13.stl" scale="1 1 1"/>
    <mesh name="wire_camera_csi_hand_0_mesh" file="wire_camera_csi_hand_0.stl" scale="1 1 1"/>
    <mesh name="wire_camera_csi_forearm_1_mesh" file="wire_camera_csi_forearm_1.stl" scale="1 1 1"/>
    <mesh name="wire_camera_csi_forearm_2_mesh" file="wire_camera_csi_forearm_2.stl" scale="1 1 1"/>
    <mesh name="wire_camera_csi_upper_arm_3_mesh" file="wire_camera_csi_upper_arm_3.stl" scale="1 1 1"/>
    <mesh name="wire_camera_csi_upper_arm_4_mesh" file="wire_camera_csi_upper_arm_4.stl" scale="1 1 1"/>
    <mesh name="wire_camera_csi_turntable_5_mesh" file="wire_camera_csi_turntable_5.stl" scale="1 1 1"/>
    <mesh name="wire_camera_csi_turntable_6_mesh" file="wire_camera_csi_turntable_6.stl" scale="1 1 1"/>
    <mesh name="wire_camera_csi_base_7_mesh" file="wire_camera_csi_base_7.stl" scale="1 1 1"/>
    <mesh name="wire_camera_csi_base_8_mesh" file="wire_camera_csi_base_8.stl" scale="1 1 1"/>
    <mesh name="wire_power_base_0_mesh" file="wire_power_base_0.stl" scale="1 1 1"/>
    <mesh name="wire_power_base_1_mesh" file="wire_power_base_1.stl" scale="1 1 1"/>
  </asset>
  <worldbody>
    <body name="base" pos="0 0 0.0450">
      <freejoint name="root"/>
      <inertial pos="-0.002358 -0.000000 0.006919" mass="0.313142" fullinertia="1.301361e-04 4.570784e-04 4.050737e-04 7.813497e-10 1.148314e-05 3.022338e-11"/>
      <geom type="mesh" mesh="base_mesh" rgba="0.8078 0.8510 0.8784 1.0000" contype="1" conaffinity="1"/>
      <site name="imu" pos="0 0 0" size="0.005"/>
      <geom name="comp_base_pi" type="mesh" mesh="comp_base_pi_mesh" pos="0.000000 0.000000 0.000000" rgba="0.0588 0.6000 0.3765 1.0000" contype="0" conaffinity="0" group="1"/>
      <geom name="comp_base_battery" type="mesh" mesh="comp_base_battery_mesh" pos="0.000000 0.000000 -0.016000" rgba="0.0745 0.4863 0.7412 1.0000" contype="0" conaffinity="0" group="1"/>
      <geom name="left_wheel_servo" type="mesh" mesh="servo_STS3215_mesh" pos="-0.044000 0.000000 0.012500" quat="0.000000 -0.707107 0.000000 0.707107" rgba="0.0941 0.1255 0.1490 1.0000" contype="0" conaffinity="0" group="1"/>
      <geom name="right_wheel_servo" type="mesh" mesh="servo_STS3215_mesh" pos="0.044000 0.000000 0.012500" quat="0.707107 0.000000 0.707107 0.000000" rgba="0.0941 0.1255 0.1490 1.0000" contype="0" conaffinity="0" group="1"/>
      <geom name="shoulder_yaw_servo" type="mesh" mesh="servo_STS3215_mesh" pos="-0.012500 0.000000 0.024000" quat="1.000000 0.000000 0.000000 0.000000" rgba="0.0941 0.1255 0.1490 1.0000" contype="0" conaffinity="0" group="1"/>
      <geom name="screw_left_wheel_ear_1" type="mesh" mesh="hardware_M3_shc_mesh" pos="-0.026500 0.010250 -0.004500" rgba="0.6549 0.7137 0.7608 0.9000" contype="0" conaffinity="0" group="1" quat="0.707107 -0.000000 0.707107 0.000000"/>
      <geom name="screw_left_wheel_ear_2" type="mesh" mesh="hardware_M3_shc_mesh" pos="-0.026500 0.010250 0.012500" rgba="0.6549 0.7137 0.7608 0.9000" contype="0" conaffinity="0" group="1" quat="0.707107 -0.000000 0.707107 0.000000"/>
      <geom name="screw_left_wheel_ear_3" type="mesh" mesh="hardware_M3_shc_mesh" pos="-0.026500 -0.010250 -0.004500" rgba="0.6549 0.7137 0.7608 0.9000" contype="0" conaffinity="0" group="1" quat="0.707107 -0.000000 0.707107 0.000000"/>
      <geom name="screw_left_wheel_ear_4" type="mesh" mesh="hardware_M3_shc_mesh" pos="-0.026500 -0.010250 0.012500" rgba="0.6549 0.7137 0.7608 0.9000" contype="0" conaffinity="0" group="1" quat="0.707107 -0.000000 0.707107 0.000000"/>
      <geom name="screw_left_wheel_ear_5" type="mesh" mesh="hardware_M3_shc_mesh" pos="-0.026500 0.010250 0.029500" rgba="0.6549 0.7137 0.7608 0.9000" contype="0" conaffinity="0" group="1" quat="0.707107 -0.000000 0.707107 0.000000"/>
      <geom name="screw_left_wheel_ear_6" type="mesh" mesh="hardware_M3_shc_mesh" pos="-0.026500 -0.010250 0.029500" rgba="0.6549 0.7137 0.7608 0.9000" contype="0" conaffinity="0" group="1" quat="0.707107 -0.000000 0.707107 0.000000"/>
      <geom name="horn_left_wheel_horn_out_1" type="mesh" mesh="hardware_M2_shc_mesh" pos="-0.060000 0.000000 -0.007000" rgba="0.6549 0.7137 0.7608 0.9000" contype="0" conaffinity="0" group="1" quat="0.707107 0.000000 -0.707107 0.000000"/>
      <geom name="horn_left_wheel_horn_out_2" type="mesh" mesh="hardware_M2_shc_mesh" pos="-0.060000 0.000000 0.007000" rgba="0.6549 0.7137 0.7608 0.9000" contype="0" conaffinity="0" group="1" quat="0.707107 0.000000 -0.707107 0.000000"/>
      <geom name="horn_left_wheel_horn_out_3" type="mesh" mesh="hardware_M2_shc_mesh" pos="-0.060000 -0.007000 0.000000" rgba="0.6549 0.7137 0.7608 0.9000" contype="0" conaffinity="0" group="1" quat="0.707107 0.000000 -0.707107 0.000000"/>
      <geom name="horn_left_wheel_horn_out_4" type="mesh" mesh="hardware_M2_shc_mesh" pos="-0.060000 0.007000 0.000000" rgba="0.6549 0.7137 0.7608 0.9000" contype="0" conaffinity="0" group="1" quat="0.707107 0.000000 -0.707107 0.000000"/>
      <geom name="rear_left_wheel_horn_rear_1" type="mesh" mesh="hardware_M2_shc_mesh" pos="-0.028000 0.000000 -0.007000" rgba="0.6549 0.7137 0.7608 0.9000" contype="0" conaffinity="0" group="1" quat="0.707107 -0.000000 0.707107 0.000000"/>
      <geom name="rear_left_wheel_horn_rear_2" type="mesh" mesh="hardware_M2_shc_mesh" pos="-0.028000 0.000000 0.007000" rgba="0.6549 0.7137 0.7608 0.9000" contype="0" conaffinity="0" group="1" quat="0.707107 -0.000000 0.707107 0.000000"/>
      <geom name="rear_left_wheel_horn_rear_3" type="mesh" mesh="hardware_M2_shc_mesh" pos="-0.028000 -0.007000 -0.000000" rgba="0.6549 0.7137 0.7608 0.9000" contype="0" conaffinity="0" group="1" quat="0.707107 -0.000000 0.707107 0.000000"/>
      <geom name="rear_left_wheel_horn_rear_4" type="mesh" mesh="hardware_M2_shc_mesh" pos="-0.028000 0.007000 -0.000000" rgba="0.6549 0.7137 0.7608 0.9000" contype="0" conaffinity="0" group="1" quat="0.707107 -0.000000 0.707107 0.000000"/>
      <geom name="screw_right_wheel_ear_1" type="mesh" mesh="hardware_M3_shc_mesh" pos="0.026500 -0.010250 -0.004500" rgba="0.6549 0.7137 0.7608 0.9000" contype="0" conaffinity="0" group="1" quat="0.707107 -0.000000 -0.707107 0.000000"/>
      <geom name="screw_right_wheel_ear_2" type="mesh" mesh="hardware_M3_shc_mesh" pos="0.026500 -0.010250 0.012500" rgba="0.6549 0.7137 0.7608 0.9000" contype="0" conaffinity="0" group="1" quat="0.707107 -0.000000 -0.707107 0.000000"/>
      <geom name="screw_right_wheel_ear_3" type="mesh" mesh="hardware_M3_shc_mesh" pos="0.026500 0.010250 -0.004500" rgba="0.6549 0.7137 0.7608 0.9000" contype="0" conaffinity="0" group="1" quat="0.707107 -0.000000 -0.707107 0.000000"/>
      <geom name="screw_right_wheel_ear_4" type="mesh" mesh="hardware_M3_shc_mesh" pos="0.026500 0.010250 0.012500" rgba="0.6549 0.7137 0.7608 0.9000" contype="0" conaffinity="0" group="1" quat="0.707107 -0.000000 -0.707107 0.000000"/>
      <geom name="screw_right_wheel_ear_5" type="mesh" mesh="hardware_M3_shc_mesh" pos="0.026500 -0.010250 0.029500" rgba="0.6549 0.7137 0.7608 0.9000" contype="0" conaffinity="0" group="1" quat="0.707107 -0.000000 -0.707107 0.000000"/>
      <geom name="screw_right_wheel_ear_6" type="mesh" mesh="hardware_M3_shc_mesh" pos="0.026500 0.010250 0.029500" rgba="0.6549 0.7137 0.7608 0.9000" contype="0" conaffinity="0" group="1" quat="0.707107 -0.000000 -0.707107 0.000000"/>
      <geom name="horn_right_wheel_horn_out_1" type="mesh" mesh="hardware_M2_shc_mesh" pos="0.060000 0.000000 -0.007000" rgba="0.6549 0.7137 0.7608 0.9000" contype="0" conaffinity="0" group="1" quat="0.707107 0.000000 0.707107 0.000000"/>
      <geom name="horn_right_wheel_horn_out_2" type="mesh" mesh="hardware_M2_shc_mesh" pos="0.060000 0.000000 0.007000" rgba="0.6549 0.7137 0.7608 0.9000" contype="0" conaffinity="0" group="1" quat="0.707107 0.000000 0.707107 0.000000"/>
      <geom name="horn_right_wheel_horn_out_3" type="mesh" mesh="hardware_M2_shc_mesh" pos="0.060000 0.007000 0.000000" rgba="0.6549 0.7137 0.7608 0.9000" contype="0" conaffinity="0" group="1" quat="0.707107 0.000000 0.707107 0.000000"/>
      <geom name="horn_right_wheel_horn_out_4" type="mesh" mesh="hardware_M2_shc_mesh" pos="0.060000 -0.007000 0.000000" rgba="0.6549 0.7137 0.7608 0.9000" contype="0" conaffinity="0" group="1" quat="0.707107 0.000000 0.707107 0.000000"/>
      <geom name="rear_right_wheel_horn_rear_1" type="mesh" mesh="hardware_M2_shc_mesh" pos="0.028000 0.000000 -0.007000" rgba="0.6549 0.7137 0.7608 0.9000" contype="0" conaffinity="0" group="1" quat="0.707107 -0.000000 -0.707107 0.000000"/>
      <geom name="rear_right_wheel_horn_rear_2" type="mesh" mesh="hardware_M2_shc_mesh" pos="0.028000 0.000000 0.007000" rgba="0.6549 0.7137 0.7608 0.9000" contype="0" conaffinity="0" group="1" quat="0.707107 -0.000000 -0.707107 0.000000"/>
      <geom name="rear_right_wheel_horn_rear_3" type="mesh" mesh="hardware_M2_shc_mesh" pos="0.028000 0.007000 -0.000000" rgba="0.6549 0.7137 0.7608 0.9000" contype="0" conaffinity="0" group="1" quat="0.707107 -0.000000 -0.707107 0.000000"/>
      <geom name="rear_right_wheel_horn_rear_4" type="mesh" mesh="hardware_M2_shc_mesh" pos="0.028000 -0.007000 -0.000000" rgba="0.6549 0.7137 0.7608 0.9000" contype="0" conaffinity="0" group="1" quat="0.707107 -0.000000 -0.707107 0.000000"/>
      <geom name="screw_shoulder_yaw_ear_1" type="mesh" mesh="hardware_M3_shc_mesh" pos="0.004500 -0.010250 0.006500" rgba="0.6549 0.7137 0.7608 0.9000" contype="0" conaffinity="0" group="1" quat="0.000000 1.000000 0.000000 0.000000"/>
      <geom name="screw_shoulder_yaw_ear_2" type="mesh" mesh="hardware_M3_shc_mesh" pos="-0.012500 -0.010250 0.006500" rgba="0.6549 0.7137 0.7608 0.9000" contype="0" conaffinity="0" group="1" quat="0.000000 1.000000 0.000000 0.000000"/>
      <geom name="screw_shoulder_yaw_ear_3" type="mesh" mesh="hardware_M3_shc_mesh" pos="0.004500 0.010250 0.006500" rgba="0.6549 0.7137 0.7608 0.9000" contype="0" conaffinity="0" group="1" quat="0.000000 1.000000 0.000000 0.000000"/>
      <geom name="screw_shoulder_yaw_ear_4" type="mesh" mesh="hardware_M3_shc_mesh" pos="-0.012500 0.010250 0.006500" rgba="0.6549 0.7137 0.7608 0.9000" contype="0" conaffinity="0" group="1" quat="0.000000 1.000000 0.000000 0.000000"/>
      <geom name="screw_shoulder_yaw_ear_5" type="mesh" mesh="hardware_M3_shc_mesh" pos="-0.029500 -0.010250 0.006500" rgba="0.6549 0.7137 0.7608 0.9000" contype="0" conaffinity="0" group="1" quat="0.000000 1.000000 0.000000 0.000000"/>
      <geom name="screw_shoulder_yaw_ear_6" type="mesh" mesh="hardware_M3_shc_mesh" pos="-0.029500 0.010250 0.006500" rgba="0.6549 0.7137 0.7608 0.9000" contype="0" conaffinity="0" group="1" quat="0.000000 1.000000 0.000000 0.000000"/>
      <geom name="horn_shoulder_yaw_horn_out_1" type="mesh" mesh="hardware_M2_shc_mesh" pos="0.007000 0.000000 0.040000" rgba="0.6549 0.7137 0.7608 0.9000" contype="0" conaffinity="0" group="1"/>
      <geom name="horn_shoulder_yaw_horn_out_2" type="mesh" mesh="hardware_M2_shc_mesh" pos="-0.007000 0.000000 0.040000" rgba="0.6549 0.7137 0.7608 0.9000" contype="0" conaffinity="0" group="1"/>
      <geom name="horn_shoulder_yaw_horn_out_3" type="mesh" mesh="hardware_M2_shc_mesh" pos="0.000000 0.007000 0.040000" rgba="0.6549 0.7137 0.7608 0.9000" contype="0" conaffinity="0" group="1"/>
      <geom name="horn_shoulder_yaw_horn_out_4" type="mesh" mesh="hardware_M2_shc_mesh" pos="0.000000 -0.007000 0.040000" rgba="0.6549 0.7137 0.7608 0.9000" contype="0" conaffinity="0" group="1"/>
      <geom name="rear_shoulder_yaw_horn_rear_1" type="mesh" mesh="hardware_M2_shc_mesh" pos="0.007000 0.000000 0.008000" rgba="0.6549 0.7137 0.7608 0.9000" contype="0" conaffinity="0" group="1" quat="0.000000 1.000000 0.000000 0.000000"/>
      <geom name="rear_shoulder_yaw_horn_rear_2" type="mesh" mesh="hardware_M2_shc_mesh" pos="-0.007000 0.000000 0.008000" rgba="0.6549 0.7137 0.7608 0.9000" contype="0" conaffinity="0" group="1" quat="0.000000 1.000000 0.000000 0.000000"/>
      <geom name="rear_shoulder_yaw_horn_rear_3" type="mesh" mesh="hardware_M2_shc_mesh" pos="0.000000 0.007000 0.008000" rgba="0.6549 0.7137 0.7608 0.9000" contype="0" conaffinity="0" group="1" quat="0.000000 1.000000 0.000000 0.000000"/>
      <geom name="rear_shoulder_yaw_horn_rear_4" type="mesh" mesh="hardware_M2_shc_mesh" pos="0.000000 -0.007000 0.008000" rgba="0.6549 0.7137 0.7608 0.9000" contype="0" conaffinity="0" group="1" quat="0.000000 1.000000 0.000000 0.000000"/>
      <geom name="mount_base_pi_m1" type="mesh" mesh="hardware_M2.5_shc_mesh" pos="-0.029000 -0.011500 0.000000" rgba="0.6549 0.7137 0.7608 0.9000" contype="0" conaffinity="0" group="1" quat="0.000000 1.000000 0.000000 0.000000"/>
      <geom name="mount_base_pi_m2" type="mesh" mesh="hardware_M2.5_shc_mesh" pos="0.029000 -0.011500 0.000000" rgba="0.6549 0.7137 0.7608 0.9000" contype="0" conaffinity="0" group="1" quat="0.000000 1.000000 0.000000 0.000000"/>
      <geom name="mount_base_pi_m3" type="mesh" mesh="hardware_M2.5_shc_mesh" pos="-0.029000 0.011500 0.000000" rgba="0.6549 0.7137 0.7608 0.9000" contype="0" conaffinity="0" group="1" quat="0.000000 1.000000 0.000000 0.000000"/>
      <geom name="mount_base_pi_m4" type="mesh" mesh="hardware_M2.5_shc_mesh" pos="0.029000 0.011500 0.000000" rgba="0.6549 0.7137 0.7608 0.9000" contype="0" conaffinity="0" group="1" quat="0.000000 1.000000 0.000000 0.000000"/>
      <geom name="wire_servo_bus_base_0" type="mesh" mesh="wire_servo_bus_base_0_mesh" pos="0 0 0" rgba="0.1686 0.5843 0.8392 0.9000" contype="0" conaffinity="0" group="2"/>
      <geom name="wire_servo_bus_base_1" type="mesh" mesh="wire_servo_bus_base_1_mesh" pos="0 0 0" rgba="0.1686 0.5843 0.8392 0.9000" contype="0" conaffinity="0" group="2"/>
      <geom name="wire_servo_bus_base_2" type="mesh" mesh="wire_servo_bus_base_2_mesh" pos="0 0 0" rgba="0.1686 0.5843 0.8392 0.9000" contype="0" conaffinity="0" group="2"/>
      <geom name="wire_servo_bus_base_3" type="mesh" mesh="wire_servo_bus_base_3_mesh" pos="0 0 0" rgba="0.1686 0.5843 0.8392 0.9000" contype="0" conaffinity="0" group="2"/>
      <geom name="wire_servo_bus_base_4" type="mesh" mesh="wire_servo_bus_base_4_mesh" pos="0 0 0" rgba="0.1686 0.5843 0.8392 0.9000" contype="0" conaffinity="0" group="2"/>
      <geom name="wire_servo_bus_base_5" type="mesh" mesh="wire_servo_bus_base_5_mesh" pos="0 0 0" rgba="0.1686 0.5843 0.8392 0.9000" contype="0" conaffinity="0" group="2"/>
      <geom name="wire_servo_bus_base_6" type="mesh" mesh="wire_servo_bus_base_6_mesh" pos="0 0 0" rgba="0.1686 0.5843 0.8392 0.9000" contype="0" conaffinity="0" group="2"/>
      <geom name="wire_servo_bus_base_7" type="mesh" mesh="wire_servo_bus_base_7_mesh" pos="0 0 0" rgba="0.1686 0.5843 0.8392 0.9000" contype="0" conaffinity="0" group="2"/>
      <geom name="wire_camera_csi_base_7" type="mesh" mesh="wire_camera_csi_base_7_mesh" pos="0 0 0" rgba="1.0000 0.7882 0.2510 0.9000" contype="0" conaffinity="0" group="2"/>
      <geom name="wire_camera_csi_base_8" type="mesh" mesh="wire_camera_csi_base_8_mesh" pos="0 0 0" rgba="1.0000 0.7882 0.2510 0.9000" contype="0" conaffinity="0" group="2"/>
      <geom name="wire_power_base_0" type="mesh" mesh="wire_power_base_0_mesh" pos="0 0 0" rgba="0.8588 0.2157 0.2157 0.9000" contype="0" conaffinity="0" group="2"/>
      <geom name="wire_power_base_1" type="mesh" mesh="wire_power_base_1_mesh" pos="0 0 0" rgba="0.8588 0.2157 0.2157 0.9000" contype="0" conaffinity="0" group="2"/>
      <body name="left_rim" pos="-0.068000 0.000000 0.000000">
        <inertial pos="-0.000000 0.000000 -0.000000" mass="0.042513" fullinertia="4.249061e-05 2.891092e-05 4.357587e-05 -1.873344e-22 3.105449e-21 1.293483e-21"/>
        <joint name="left_wheel" type="hinge" pos="0.008000 -0.000000 -0.000000" axis="-1.000000 0.000000 0.000000" damping="0.0100"/>
        <geom type="mesh" mesh="left_rim_mesh" rgba="0.0941 0.1255 0.1490 1.0000" contype="0" conaffinity="0"/>
        <geom type="cylinder" size="0.045 0.005" rgba="0.0941 0.1255 0.1490 0.0000" contype="1" conaffinity="1" friction="1.5 0.005 0.0001" quat="0.707107 0.000000 -0.707107 0.000000"/>
        <geom name="mount_left_rim_wheel_m1" type="mesh" mesh="hardware_M3_shc_mesh" pos="0.000000 0.000000 0.006350" rgba="0.6549 0.7137 0.7608 0.9000" contype="0" conaffinity="0" group="1" quat="0.707107 0.000000 -0.707107 0.000000"/>
        <geom name="mount_left_rim_wheel_m2" type="mesh" mesh="hardware_M3_shc_mesh" pos="0.000000 0.008271 0.004775" rgba="0.6549 0.7137 0.7608 0.9000" contype="0" conaffinity="0" group="1" quat="0.707107 0.000000 -0.707107 0.000000"/>
        <geom name="mount_left_rim_wheel_m3" type="mesh" mesh="hardware_M3_shc_mesh" pos="-0.000000 0.008271 -0.004775" rgba="0.6549 0.7137 0.7608 0.9000" contype="0" conaffinity="0" group="1" quat="0.707107 0.000000 -0.707107 0.000000"/>
        <geom name="mount_left_rim_wheel_m4" type="mesh" mesh="hardware_M3_shc_mesh" pos="-0.000000 0.000000 -0.006350" rgba="0.6549 0.7137 0.7608 0.9000" contype="0" conaffinity="0" group="1" quat="0.707107 0.000000 -0.707107 0.000000"/>
        <geom name="mount_left_rim_wheel_m5" type="mesh" mesh="hardware_M3_shc_mesh" pos="-0.000000 -0.008271 -0.004775" rgba="0.6549 0.7137 0.7608 0.9000" contype="0" conaffinity="0" group="1" quat="0.707107 0.000000 -0.707107 0.000000"/>
        <geom name="mount_left_rim_wheel_m6" type="mesh" mesh="hardware_M3_shc_mesh" pos="0.000000 -0.008271 0.004775" rgba="0.6549 0.7137 0.7608 0.9000" contype="0" conaffinity="0" group="1" quat="0.707107 0.000000 -0.707107 0.000000"/>
      </body>
      <body name="right_rim" pos="0.068000 0.000000 0.000000">
        <inertial pos="0.000000 0.000000 -0.000000" mass="0.042513" fullinertia="4.249061e-05 2.891092e-05 4.357587e-05 -2.107546e-22 -3.114633e-21 -1.904663e-21"/>
        <joint name="right_wheel" type="hinge" pos="-0.008000 -0.000000 -0.000000" axis="1.000000 0.000000 0.000000" damping="0.0100"/>
        <geom type="mesh" mesh="right_rim_mesh" rgba="0.0941 0.1255 0.1490 1.0000" contype="0" conaffinity="0"/>
        <geom type="cylinder" size="0.045 0.005" rgba="0.0941 0.1255 0.1490 0.0000" contype="1" conaffinity="1" friction="1.5 0.005 0.0001" quat="0.707107 0.000000 0.707107 0.000000"/>
        <geom name="mount_right_rim_wheel_m1" type="mesh" mesh="hardware_M3_shc_mesh" pos="0.000000 0.000000 -0.006350" rgba="0.6549 0.7137 0.7608 0.9000" contype="0" conaffinity="0" group="1" quat="0.707107 0.000000 0.707107 0.000000"/>
        <geom name="mount_right_rim_wheel_m2" type="mesh" mesh="hardware_M3_shc_mesh" pos="0.000000 0.008271 -0.004775" rgba="0.6549 0.7137 0.7608 0.9000" contype="0" conaffinity="0" group="1" quat="0.707107 0.000000 0.707107 0.000000"/>
        <geom name="mount_right_rim_wheel_m3" type="mesh" mesh="hardware_M3_shc_mesh" pos="-0.000000 0.008271 0.004775" rgba="0.6549 0.7137 0.7608 0.9000" contype="0" conaffinity="0" group="1" quat="0.707107 0.000000 0.707107 0.000000"/>
        <geom name="mount_right_rim_wheel_m4" type="mesh" mesh="hardware_M3_shc_mesh" pos="-0.000000 0.000000 0.006350" rgba="0.6549 0.7137 0.7608 0.9000" contype="0" conaffinity="0" group="1" quat="0.707107 0.000000 0.707107 0.000000"/>
        <geom name="mount_right_rim_wheel_m5" type="mesh" mesh="hardware_M3_shc_mesh" pos="-0.000000 -0.008271 0.004775" rgba="0.6549 0.7137 0.7608 0.9000" contype="0" conaffinity="0" group="1" quat="0.707107 0.000000 0.707107 0.000000"/>
        <geom name="mount_right_rim_wheel_m6" type="mesh" mesh="hardware_M3_shc_mesh" pos="0.000000 -0.008271 -0.004775" rgba="0.6549 0.7137 0.7608 0.9000" contype="0" conaffinity="0" group="1" quat="0.707107 0.000000 0.707107 0.000000"/>
      </body>
      <body name="turntable" pos="0.000000 0.000000 0.040000">
        <inertial pos="-0.009997 -0.000000 0.025623" mass="0.102942" fullinertia="5.428023e-05 6.251562e-05 3.693560e-05 -1.755636e-12 2.889243e-06 -2.573603e-11"/>
        <joint name="shoulder_yaw" type="hinge" pos="0 0 0" axis="0.000000 0.000000 1.000000" damping="0.6237" range="-1.5000 1.5000"/>
        <geom name="shoulder_yaw_horn_disc" type="mesh" mesh="horn_shoulder_yaw_mesh" pos="0.000000 0.000000 0.000000" rgba="0.8824 0.9098 0.9294 0.9000" contype="0" conaffinity="0" group="1"/>
        <geom type="mesh" mesh="turntable_mesh" rgba="0.8078 0.8510 0.8784 1.0000" contype="1" conaffinity="1"/>
        <geom name="shoulder_pitch_servo" type="mesh" mesh="servo_STS3215_mesh" pos="-0.016000 0.000000 0.032500" quat="0.707107 0.000000 0.707107 0.000000" rgba="0.0941 0.1255 0.1490 1.0000" contype="0" conaffinity="0" group="1"/>
        <geom name="screw_shoulder_pitch_ear_1" type="mesh" mesh="hardware_M3_shc_mesh" pos="-0.033500 -0.010250 0.015500" rgba="0.6549 0.7137 0.7608 0.9000" contype="0" conaffinity="0" group="1" quat="0.707107 -0.000000 -0.707107 0.000000"/>
        <geom name="screw_shoulder_pitch_ear_2" type="mesh" mesh="hardware_M3_shc_mesh" pos="-0.033500 -0.010250 0.032500" rgba="0.6549 0.7137 0.7608 0.9000" contype="0" conaffinity="0" group="1" quat="0.707107 -0.000000 -0.707107 0.000000"/>
        <geom name="screw_shoulder_pitch_ear_3" type="mesh" mesh="hardware_M3_shc_mesh" pos="-0.033500 0.010250 0.015500" rgba="0.6549 0.7137 0.7608 0.9000" contype="0" conaffinity="0" group="1" quat="0.707107 -0.000000 -0.707107 0.000000"/>
        <geom name="screw_shoulder_pitch_ear_4" type="mesh" mesh="hardware_M3_shc_mesh" pos="-0.033500 0.010250 0.032500" rgba="0.6549 0.7137 0.7608 0.9000" contype="0" conaffinity="0" group="1" quat="0.707107 -0.000000 -0.707107 0.000000"/>
        <geom name="screw_shoulder_pitch_ear_5" type="mesh" mesh="hardware_M3_shc_mesh" pos="-0.033500 -0.010250 0.049500" rgba="0.6549 0.7137 0.7608 0.9000" contype="0" conaffinity="0" group="1" quat="0.707107 -0.000000 -0.707107 0.000000"/>
        <geom name="screw_shoulder_pitch_ear_6" type="mesh" mesh="hardware_M3_shc_mesh" pos="-0.033500 0.010250 0.049500" rgba="0.6549 0.7137 0.7608 0.9000" contype="0" conaffinity="0" group="1" quat="0.707107 -0.000000 -0.707107 0.000000"/>
        <geom name="horn_shoulder_pitch_horn_out_1" type="mesh" mesh="hardware_M2_shc_mesh" pos="0.000000 0.000000 0.013000" rgba="0.6549 0.7137 0.7608 0.9000" contype="0" conaffinity="0" group="1" quat="0.707107 0.000000 0.707107 0.000000"/>
        <geom name="horn_shoulder_pitch_horn_out_2" type="mesh" mesh="hardware_M2_shc_mesh" pos="0.000000 0.000000 0.027000" rgba="0.6549 0.7137 0.7608 0.9000" contype="0" conaffinity="0" group="1" quat="0.707107 0.000000 0.707107 0.000000"/>
        <geom name="horn_shoulder_pitch_horn_out_3" type="mesh" mesh="hardware_M2_shc_mesh" pos="0.000000 0.007000 0.020000" rgba="0.6549 0.7137 0.7608 0.9000" contype="0" conaffinity="0" group="1" quat="0.707107 0.000000 0.707107 0.000000"/>
        <geom name="horn_shoulder_pitch_horn_out_4" type="mesh" mesh="hardware_M2_shc_mesh" pos="0.000000 -0.007000 0.020000" rgba="0.6549 0.7137 0.7608 0.9000" contype="0" conaffinity="0" group="1" quat="0.707107 0.000000 0.707107 0.000000"/>
        <geom name="rear_shoulder_pitch_horn_rear_1" type="mesh" mesh="hardware_M2_shc_mesh" pos="-0.032000 0.000000 0.013000" rgba="0.6549 0.7137 0.7608 0.9000" contype="0" conaffinity="0" group="1" quat="0.707107 -0.000000 -0.707107 0.000000"/>
        <geom name="rear_shoulder_pitch_horn_rear_2" type="mesh" mesh="hardware_M2_shc_mesh" pos="-0.032000 0.000000 0.027000" rgba="0.6549 0.7137 0.7608 0.9000" contype="0" conaffinity="0" group="1" quat="0.707107 -0.000000 -0.707107 0.000000"/>
        <geom name="rear_shoulder_pitch_horn_rear_3" type="mesh" mesh="hardware_M2_shc_mesh" pos="-0.032000 0.007000 0.020000" rgba="0.6549 0.7137 0.7608 0.9000" contype="0" conaffinity="0" group="1" quat="0.707107 -0.000000 -0.707107 0.000000"/>
        <geom name="rear_shoulder_pitch_horn_rear_4" type="mesh" mesh="hardware_M2_shc_mesh" pos="-0.032000 -0.007000 0.020000" rgba="0.6549 0.7137 0.7608 0.9000" contype="0" conaffinity="0" group="1" quat="0.707107 -0.000000 -0.707107 0.000000"/>
        <geom name="wire_servo_bus_turntable_8" type="mesh" mesh="wire_servo_bus_turntable_8_mesh" pos="0 0 0" rgba="0.1686 0.5843 0.8392 0.9000" contype="0" conaffinity="0" group="2"/>
        <geom name="wire_servo_bus_turntable_9" type="mesh" mesh="wire_servo_bus_turntable_9_mesh" pos="0 0 0" rgba="0.1686 0.5843 0.8392 0.9000" contype="0" conaffinity="0" group="2"/>
        <geom name="wire_camera_csi_turntable_5" type="mesh" mesh="wire_camera_csi_turntable_5_mesh" pos="0 0 0" rgba="1.0000 0.7882 0.2510 0.9000" contype="0" conaffinity="0" group="2"/>
        <geom name="wire_camera_csi_turntable_6" type="mesh" mesh="wire_camera_csi_turntable_6_mesh" pos="0 0 0" rgba="1.0000 0.7882 0.2510 0.9000" contype="0" conaffinity="0" group="2"/>
        <body name="upper_arm" pos="0.000000 0.000000 0.020000">
          <inertial pos="-0.010396 -0.000000 0.095061" mass="0.102806" fullinertia="2.446868e-04 2.613967e-04 2.996000e-05 -2.504890e-13 3.103794e-05 -3.148156e-12"/>
          <joint name="shoulder_pitch" type="hinge" pos="0 0 0" axis="1.000000 0.000000 0.000000" damping="0.6237" range="-1.5000 1.5000"/>
          <geom name="shoulder_pitch_horn_disc" type="mesh" mesh="horn_shoulder_pitch_mesh" pos="0.000000 0.000000 0.000000" rgba="0.8824 0.9098 0.9294 0.9000" contype="0" conaffinity="0" group="1"/>
          <geom type="mesh" mesh="upper_arm_mesh" rgba="0.7490 0.8000 0.8392 1.0000" contype="1" conaffinity="1"/>
          <geom name="elbow_servo" type="mesh" mesh="servo_STS3215_mesh" pos="-0.016000 0.000000 0.132500" quat="0.707107 0.000000 0.707107 0.000000" rgba="0.0941 0.1255 0.1490 1.0000" contype="0" conaffinity="0" group="1"/>
          <geom name="screw_elbow_ear_1" type="mesh" mesh="hardware_M3_shc_mesh" pos="-0.033500 -0.010250 0.115500" rgba="0.6549 0.7137 0.7608 0.9000" contype="0" conaffinity="0" group="1" quat="0.707107 -0.000000 -0.707107 0.000000"/>
          <geom name="screw_elbow_ear_2" type="mesh" mesh="hardware_M3_shc_mesh" pos="-0.033500 -0.010250 0.132500" rgba="0.6549 0.7137 0.7608 0.9000" contype="0" conaffinity="0" group="1" quat="0.707107 -0.000000 -0.707107 0.000000"/>
          <geom name="screw_elbow_ear_3" type="mesh" mesh="hardware_M3_shc_mesh" pos="-0.033500 0.010250 0.115500" rgba="0.6549 0.7137 0.7608 0.9000" contype="0" conaffinity="0" group="1" quat="0.707107 -0.000000 -0.707107 0.000000"/>
          <geom name="screw_elbow_ear_4" type="mesh" mesh="hardware_M3_shc_mesh" pos="-0.033500 0.010250 0.132500" rgba="0.6549 0.7137 0.7608 0.9000" contype="0" conaffinity="0" group="1" quat="0.707107 -0.000000 -0.707107 0.000000"/>
          <geom name="screw_elbow_ear_5" type="mesh" mesh="hardware_M3_shc_mesh" pos="-0.033500 -0.010250 0.149500" rgba="0.6549 0.7137 0.7608 0.9000" contype="0" conaffinity="0" group="1" quat="0.707107 -0.000000 -0.707107 0.000000"/>
          <geom name="screw_elbow_ear_6" type="mesh" mesh="hardware_M3_shc_mesh" pos="-0.033500 0.010250 0.149500" rgba="0.6549 0.7137 0.7608 0.9000" contype="0" conaffinity="0" group="1" quat="0.707107 -0.000000 -0.707107 0.000000"/>
          <geom name="horn_elbow_horn_out_1" type="mesh" mesh="hardware_M2_shc_mesh" pos="0.000000 0.000000 0.113000" rgba="0.6549 0.7137 0.7608 0.9000" contype="0" conaffinity="0" group="1" quat="0.707107 0.000000 0.707107 0.000000"/>
          <geom name="horn_elbow_horn_out_2" type="mesh" mesh="hardware_M2_shc_mesh" pos="0.000000 0.000000 0.127000" rgba="0.6549 0.7137 0.7608 0.9000" contype="0" conaffinity="0" group="1" quat="0.707107 0.000000 0.707107 0.000000"/>
          <geom name="horn_elbow_horn_out_3" type="mesh" mesh="hardware_M2_shc_mesh" pos="0.000000 0.007000 0.120000" rgba="0.6549 0.7137 0.7608 0.9000" contype="0" conaffinity="0" group="1" quat="0.707107 0.000000 0.707107 0.000000"/>
          <geom name="horn_elbow_horn_out_4" type="mesh" mesh="hardware_M2_shc_mesh" pos="0.000000 -0.007000 0.120000" rgba="0.6549 0.7137 0.7608 0.9000" contype="0" conaffinity="0" group="1" quat="0.707107 0.000000 0.707107 0.000000"/>
          <geom name="rear_elbow_horn_rear_1" type="mesh" mesh="hardware_M2_shc_mesh" pos="-0.032000 0.000000 0.113000" rgba="0.6549 0.7137 0.7608 0.9000" contype="0" conaffinity="0" group="1" quat="0.707107 -0.000000 -0.707107 0.000000"/>
          <geom name="rear_elbow_horn_rear_2" type="mesh" mesh="hardware_M2_shc_mesh" pos="-0.032000 0.000000 0.127000" rgba="0.6549 0.7137 0.7608 0.9000" contype="0" conaffinity="0" group="1" quat="0.707107 -0.000000 -0.707107 0.000000"/>
          <geom name="rear_elbow_horn_rear_3" type="mesh" mesh="hardware_M2_shc_mesh" pos="-0.032000 0.007000 0.120000" rgba="0.6549 0.7137 0.7608 0.9000" contype="0" conaffinity="0" group="1" quat="0.707107 -0.000000 -0.707107 0.000000"/>
          <geom name="rear_elbow_horn_rear_4" type="mesh" mesh="hardware_M2_shc_mesh" pos="-0.032000 -0.007000 0.120000" rgba="0.6549 0.7137 0.7608 0.9000" contype="0" conaffinity="0" group="1" quat="0.707107 -0.000000 -0.707107 0.000000"/>
          <geom name="wire_servo_bus_upper_arm_10" type="mesh" mesh="wire_servo_bus_upper_arm_10_mesh" pos="0 0 0" rgba="0.1686 0.5843 0.8392 0.9000" contype="0" conaffinity="0" group="2"/>
          <geom name="wire_servo_bus_upper_arm_11" type="mesh" mesh="wire_servo_bus_upper_arm_11_mesh" pos="0 0 0" rgba="0.1686 0.5843 0.8392 0.9000" contype="0" conaffinity="0" group="2"/>
          <geom name="wire_camera_csi_upper_arm_3" type="mesh" mesh="wire_camera_csi_upper_arm_3_mesh" pos="0 0 0" rgba="1.0000 0.7882 0.2510 0.9000" contype="0" conaffinity="0" group="2"/>
          <geom name="wire_camera_csi_upper_arm_4" type="mesh" mesh="wire_camera_csi_upper_arm_4_mesh" pos="0 0 0" rgba="1.0000 0.7882 0.2510 0.9000" contype="0" conaffinity="0" group="2"/>
          <body name="forearm" pos="0.000000 0.000000 0.120000">
            <inertial pos="-0.010466 -0.000000 0.064908" mass="0.086238" fullinertia="9.057372e-05 1.052944e-04 2.407786e-05 -5.471945e-13 1.259347e-05 -2.712395e-12"/>
            <joint name="elbow" type="hinge" pos="0 0 0" axis="1.000000 0.000000 0.000000" damping="0.6237" range="-1.9200 0.0000"/>
            <geom name="elbow_horn_disc" type="mesh" mesh="horn_elbow_mesh" pos="0.000000 0.000000 0.000000" rgba="0.8824 0.9098 0.9294 0.9000" contype="0" conaffinity="0" group="1"/>
            <geom type="mesh" mesh="forearm_mesh" rgba="0.7490 0.8000 0.8392 1.0000" contype="1" conaffinity="1"/>
            <geom name="wrist_servo" type="mesh" mesh="servo_STS3215_mesh" pos="-0.012500 0.000000 0.084000" quat="1.000000 0.000000 0.000000 0.000000" rgba="0.0941 0.1255 0.1490 1.0000" contype="0" conaffinity="0" group="1"/>
            <geom name="screw_wrist_ear_1" type="mesh" mesh="hardware_M3_shc_mesh" pos="0.004500 -0.010250 0.066500" rgba="0.6549 0.7137 0.7608 0.9000" contype="0" conaffinity="0" group="1" quat="0.000000 1.000000 0.000000 0.000000"/>
            <geom name="screw_wrist_ear_2" type="mesh" mesh="hardware_M3_shc_mesh" pos="-0.012500 -0.010250 0.066500" rgba="0.6549 0.7137 0.7608 0.9000" contype="0" conaffinity="0" group="1" quat="0.000000 1.000000 0.000000 0.000000"/>
            <geom name="screw_wrist_ear_3" type="mesh" mesh="hardware_M3_shc_mesh" pos="0.004500 0.010250 0.066500" rgba="0.6549 0.7137 0.7608 0.9000" contype="0" conaffinity="0" group="1" quat="0.000000 1.000000 0.000000 0.000000"/>
            <geom name="screw_wrist_ear_4" type="mesh" mesh="hardware_M3_shc_mesh" pos="-0.012500 0.010250 0.066500" rgba="0.6549 0.7137 0.7608 0.9000" contype="0" conaffinity="0" group="1" quat="0.000000 1.000000 0.000000 0.000000"/>
            <geom name="screw_wrist_ear_5" type="mesh" mesh="hardware_M3_shc_mesh" pos="-0.029500 -0.010250 0.066500" rgba="0.6549 0.7137 0.7608 0.9000" contype="0" conaffinity="0" group="1" quat="0.000000 1.000000 0.000000 0.000000"/>
            <geom name="screw_wrist_ear_6" type="mesh" mesh="hardware_M3_shc_mesh" pos="-0.029500 0.010250 0.066500" rgba="0.6549 0.7137 0.7608 0.9000" contype="0" conaffinity="0" group="1" quat="0.000000 1.000000 0.000000 0.000000"/>
            <geom name="horn_wrist_horn_out_1" type="mesh" mesh="hardware_M2_shc_mesh" pos="0.007000 0.000000 0.100000" rgba="0.6549 0.7137 0.7608 0.9000" contype="0" conaffinity="0" group="1"/>
            <geom name="horn_wrist_horn_out_2" type="mesh" mesh="hardware_M2_shc_mesh" pos="-0.007000 0.000000 0.100000" rgba="0.6549 0.7137 0.7608 0.9000" contype="0" conaffinity="0" group="1"/>
            <geom name="horn_wrist_horn_out_3" type="mesh" mesh="hardware_M2_shc_mesh" pos="0.000000 0.007000 0.100000" rgba="0.6549 0.7137 0.7608 0.9000" contype="0" conaffinity="0" group="1"/>
            <geom name="horn_wrist_horn_out_4" type="mesh" mesh="hardware_M2_shc_mesh" pos="0.000000 -0.007000 0.100000" rgba="0.6549 0.7137 0.7608 0.9000" contype="0" conaffinity="0" group="1"/>
            <geom name="rear_wrist_horn_rear_1" type="mesh" mesh="hardware_M2_shc_mesh" pos="0.007000 0.000000 0.068000" rgba="0.6549 0.7137 0.7608 0.9000" contype="0" conaffinity="0" group="1" quat="0.000000 1.000000 0.000000 0.000000"/>
            <geom name="rear_wrist_horn_rear_2" type="mesh" mesh="hardware_M2_shc_mesh" pos="-0.007000 0.000000 0.068000" rgba="0.6549 0.7137 0.7608 0.9000" contype="0" conaffinity="0" group="1" quat="0.000000 1.000000 0.000000 0.000000"/>
            <geom name="rear_wrist_horn_rear_3" type="mesh" mesh="hardware_M2_shc_mesh" pos="0.000000 0.007000 0.068000" rgba="0.6549 0.7137 0.7608 0.9000" contype="0" conaffinity="0" group="1" quat="0.000000 1.000000 0.000000 0.000000"/>
            <geom name="rear_wrist_horn_rear_4" type="mesh" mesh="hardware_M2_shc_mesh" pos="0.000000 -0.007000 0.068000" rgba="0.6549 0.7137 0.7608 0.9000" contype="0" conaffinity="0" group="1" quat="0.000000 1.000000 0.000000 0.000000"/>
            <geom name="wire_servo_bus_forearm_12" type="mesh" mesh="wire_servo_bus_forearm_12_mesh" pos="0 0 0" rgba="0.1686 0.5843 0.8392 0.9000" contype="0" conaffinity="0" group="2"/>
            <geom name="wire_servo_bus_forearm_13" type="mesh" mesh="wire_servo_bus_forearm_13_mesh" pos="0 0 0" rgba="0.1686 0.5843 0.8392 0.9000" contype="0" conaffinity="0" group="2"/>
            <geom name="wire_camera_csi_forearm_1" type="mesh" mesh="wire_camera_csi_forearm_1_mesh" pos="0 0 0" rgba="1.0000 0.7882 0.2510 0.9000" contype="0" conaffinity="0" group="2"/>
            <geom name="wire_camera_csi_forearm_2" type="mesh" mesh="wire_camera_csi_forearm_2_mesh" pos="0 0 0" rgba="1.0000 0.7882 0.2510 0.9000" contype="0" conaffinity="0" group="2"/>
            <body name="hand" pos="0.000000 0.000000 0.100000">
              <inertial pos="0.000969 0.000109 -0.007605" mass="0.026757" fullinertia="1.227555e-05 1.261525e-05 6.433816e-06 4.885287e-08 -6.246935e-07 -3.939772e-07"/>
              <joint name="wrist" type="hinge" pos="0 0 0" axis="0.000000 0.000000 1.000000" damping="0.6237" range="-1.5000 1.5000"/>
              <geom name="wrist_horn_disc" type="mesh" mesh="horn_wrist_mesh" pos="0.000000 0.000000 0.000000" rgba="0.8824 0.9098 0.9294 0.9000" contype="0" conaffinity="0" group="1"/>
              <geom type="mesh" mesh="hand_mesh" rgba="0.8078 0.8510 0.8784 1.0000" contype="1" conaffinity="1"/>
              <camera name="camera_cam" fovy="72.0" pos="0.000000 0.008000 0.000000" euler="1.5707963267948966 0 0"/>
              <geom name="comp_hand_camera" type="mesh" mesh="comp_hand_camera_mesh" pos="0.000000 0.008000 0.000000" rgba="0.0392 0.4000 0.2510 1.0000" contype="0" conaffinity="0" group="1"/>
              <geom name="mount_hand_camera_m1" type="mesh" mesh="hardware_M2_shc_mesh" pos="-0.010500 -0.001500 0.000000" rgba="0.6549 0.7137 0.7608 0.9000" contype="0" conaffinity="0" group="1" quat="0.000000 1.000000 0.000000 0.000000"/>
              <geom name="mount_hand_camera_m2" type="mesh" mesh="hardware_M2_shc_mesh" pos="0.010500 -0.001500 0.000000" rgba="0.6549 0.7137 0.7608 0.9000" contype="0" conaffinity="0" group="1" quat="0.000000 1.000000 0.000000 0.000000"/>
              <geom name="mount_hand_camera_m3" type="mesh" mesh="hardware_M2_shc_mesh" pos="-0.010500 0.011000 0.000000" rgba="0.6549 0.7137 0.7608 0.9000" contype="0" conaffinity="0" group="1" quat="0.000000 1.000000 0.000000 0.000000"/>
              <geom name="mount_hand_camera_m4" type="mesh" mesh="hardware_M2_shc_mesh" pos="0.010500 0.011000 0.000000" rgba="0.6549 0.7137 0.7608 0.9000" contype="0" conaffinity="0" group="1" quat="0.000000 1.000000 0.000000 0.000000"/>
              <geom name="wire_camera_csi_hand_0" type="mesh" mesh="wire_camera_csi_hand_0_mesh" pos="0 0 0" rgba="1.0000 0.7882 0.2510 0.9000" contype="0" conaffinity="0" group="2"/>
            </body>
          </body>
        </body>
      </body>
    </body>
  </worldbody>
  <contact>
    <exclude body1="base" body2="forearm"/>
    <exclude body1="base" body2="left_rim"/>
    <exclude body1="base" body2="right_rim"/>
    <exclude body1="base" body2="turntable"/>
    <exclude body1="base" body2="upper_arm"/>
    <exclude body1="forearm" body2="hand"/>
    <exclude body1="turntable" body2="forearm"/>
    <exclude body1="turntable" body2="hand"/>
    <exclude body1="turntable" body2="upper_arm"/>
    <exclude body1="upper_arm" body2="forearm"/>
    <exclude body1="upper_arm" body2="hand"/>
  </contact>
  <actuator>
    <motor name="left_wheel_motor" joint="left_wheel" gear="2.94" ctrlrange="-1 1"/>
    <motor name="right_wheel_motor" joint="right_wheel" gear="2.94" ctrlrange="-1 1"/>
    <position name="shoulder_yaw_motor" joint="shoulder_yaw" kp="58.8" ctrlrange="-1.5000 1.5000" forcerange="-2.94 2.94"/>
    <position name="shoulder_pitch_motor" joint="shoulder_pitch" kp="58.8" ctrlrange="-1.5000 1.5000" forcerange="-2.94 2.94"/>
    <position name="elbow_motor" joint="elbow" kp="58.8" ctrlrange="-1.9200 0.0000" forcerange="-2.94 2.94"/>
    <position name="wrist_motor" joint="wrist" kp="58.8" ctrlrange="-1.5000 1.5000" forcerange="-2.94 2.94"/>
  </actuator>
  <sensor>
    <jointpos name="left_wheel_pos_sensor" joint="left_wheel"/>
    <jointvel name="left_wheel_vel_sensor" joint="left_wheel"/>
    <jointpos name="right_wheel_pos_sensor" joint="right_wheel"/>
    <jointvel name="right_wheel_vel_sensor" joint="right_wheel"/>
    <jointpos name="shoulder_yaw_pos_sensor" joint="shoulder_yaw"/>
    <jointvel name="shoulder_yaw_vel_sensor" joint="shoulder_yaw"/>
    <jointpos name="shoulder_pitch_pos_sensor" joint="shoulder_pitch"/>
    <jointvel name="shoulder_pitch_vel_sensor" joint="shoulder_pitch"/>
    <jointpos name="elbow_pos_sensor" joint="elbow"/>
    <jointvel name="elbow_vel_sensor" joint="elbow"/>
    <jointpos name="wrist_pos_sensor" joint="wrist"/>
    <jointvel name="wrist_vel_sensor" joint="wrist"/>
    <gyro name="imu_gyro" site="imu"/>
    <accelerometer name="imu_accel" site="imu"/>
  </sensor>
</mujoco>
