<?xml version='1.0' encoding='utf-8'?>
<mujoco model="wheeler_arm">
  <compiler angle="radian" meshdir="meshes"/>
  <default>
    <motor ctrlrange="-1 1" gear="1.0"/>
  </default>
  <asset>
    <mesh name="base_mesh" file="base.stl" scale="1 1 1"/>
    <mesh name="left_rim_mesh" file="left_rim.stl" scale="1 1 1"/>
    <mesh name="right_rim_mesh" file="right_rim.stl" scale="1 1 1"/>
    <mesh name="turntable_mesh" file="turntable.stl" scale="1 1 1"/>
    <mesh name="upper_arm_mesh" file="upper_arm.stl" scale="1 1 1"/>
    <mesh name="forearm_mesh" file="forearm.stl" scale="1 1 1"/>
    <mesh name="hand_mesh" file="hand.stl" scale="1 1 1"/>
  </asset>
  <worldbody>
    <body name="base" pos="0 0 0.0500">
      <freejoint name="root"/>
      <inertial pos="0.000000 0.000000 0.003290" mass="0.275818" fullinertia="1.550015e-04 5.977567e-04 4.769207e-04 -0.000000e+00 -0.000000e+00 -0.000000e+00"/>
      <geom type="mesh" mesh="base_mesh" rgba="0.9 0.9 0.9 1.0" contype="1" conaffinity="1"/>
      <site name="imu" pos="0 0 0" size="0.005"/>
      <geom name="wire_servo_bus_0" type="capsule" fromto="-0.010000 0.013000 0.002500 -0.060000 0.000000 0.000000" size="0.0015" rgba="0.2 0.4 1.0 0.9" contype="0" conaffinity="0" group="2"/>
      <geom name="wire_servo_bus_1" type="capsule" fromto="-0.060000 0.000000 0.000000 0.060000 0.000000 0.000000" size="0.0015" rgba="0.2 0.4 1.0 0.9" contype="0" conaffinity="0" group="2"/>
      <geom name="wire_servo_bus_2" type="capsule" fromto="0.060000 0.000000 0.000000 0.000000 0.000000 0.040000" size="0.0015" rgba="0.2 0.4 1.0 0.9" contype="0" conaffinity="0" group="2"/>
      <geom name="wire_servo_bus_3" type="capsule" fromto="0.000000 0.000000 0.040000 0.000000 0.000000 0.060000" size="0.0015" rgba="0.2 0.4 1.0 0.9" contype="0" conaffinity="0" group="2"/>
      <geom name="wire_servo_bus_4" type="capsule" fromto="0.000000 0.000000 0.060000 0.000000 0.000000 0.180000" size="0.0015" rgba="0.2 0.4 1.0 0.9" contype="0" conaffinity="0" group="2"/>
      <geom name="wire_servo_bus_5" type="capsule" fromto="0.000000 0.000000 0.180000 0.000000 0.000000 0.280000" size="0.0015" rgba="0.2 0.4 1.0 0.9" contype="0" conaffinity="0" group="2"/>
      <geom name="wire_camera_csi_0" type="capsule" fromto="0.000000 0.008000 0.280000 0.000000 0.000000 0.000000" size="0.003" rgba="1.0 0.8 0.0 0.9" contype="0" conaffinity="0" group="2"/>
      <geom name="wire_power_0" type="capsule" fromto="0.000000 0.000000 -0.023500 0.000000 0.000000 0.000000" size="0.002" rgba="0.9 0.2 0.2 0.9" contype="0" conaffinity="0" group="2"/>
      <geom name="left_wheel_servo" type="box" size="0.022600 0.012350 0.017500" pos="-0.044100 0.000000 -0.012500" quat="0.707107 0.000000 -0.707107 0.000000" rgba="0.2 0.8 0.2 0.8" contype="0" conaffinity="0" group="1"/>
      <geom name="right_wheel_servo" type="box" size="0.022600 0.012350 0.017500" pos="0.044100 0.000000 0.012500" quat="0.707107 0.000000 0.707107 0.000000" rgba="0.2 0.8 0.2 0.8" contype="0" conaffinity="0" group="1"/>
      <geom name="shoulder_yaw_servo" type="box" size="0.022600 0.012350 0.017500" pos="-0.012500 0.000000 0.024100" quat="1.000000 0.000000 0.000000 0.000000" rgba="0.2 0.8 0.2 0.8" contype="0" conaffinity="0" group="1"/>
      <body name="left_rim" pos="-0.060000 0.000000 0.000000">
        <inertial pos="0.000000 0.000000 0.000000" mass="0.038400" fullinertia="3.488000e-05 3.488000e-05 6.400000e-05 -0.000000e+00 -0.000000e+00 -0.000000e+00"/>
        <joint name="left_wheel" type="hinge" pos="0 0 0" axis="-1.000000 0.000000 0.000000" damping="0.0100"/>
        <geom type="mesh" mesh="left_rim_mesh" rgba="0.15 0.15 0.15 1.0" contype="0" conaffinity="0"/>
        <geom type="cylinder" size="0.05 0.015" quat="0.7071068 0 0.7071068 0" rgba="0.15 0.15 0.15 0.0" contype="1" conaffinity="1" friction="1.5 0.005 0.0001"/>
      </body>
      <body name="right_rim" pos="0.060000 0.000000 0.000000">
        <inertial pos="0.000000 0.000000 0.000000" mass="0.038400" fullinertia="3.488000e-05 3.488000e-05 6.400000e-05 -0.000000e+00 -0.000000e+00 -0.000000e+00"/>
        <joint name="right_wheel" type="hinge" pos="0 0 0" axis="1.000000 0.000000 0.000000" damping="0.0100"/>
        <geom type="mesh" mesh="right_rim_mesh" rgba="0.15 0.15 0.15 1.0" contype="0" conaffinity="0"/>
        <geom type="cylinder" size="0.05 0.015" quat="0.7071068 0 0.7071068 0" rgba="0.15 0.15 0.15 0.0" contype="1" conaffinity="1" friction="1.5 0.005 0.0001"/>
      </body>
      <body name="turntable" pos="0.000000 0.000000 0.040000">
        <inertial pos="0.000000 0.000000 0.018543" mass="0.059320" fullinertia="9.188139e-06 1.627169e-05 1.311531e-05 -0.000000e+00 -0.000000e+00 -0.000000e+00"/>
        <joint name="shoulder_yaw" type="hinge" pos="0 0 0" axis="0.000000 0.000000 1.000000" damping="0.6246" range="-1.5000 1.5000"/>
        <geom type="mesh" mesh="turntable_mesh" rgba="0.9 0.9 0.9 1.0" contype="1" conaffinity="1"/>
        <geom name="shoulder_pitch_servo" type="box" size="0.022600 0.012350 0.017500" pos="-0.015900 0.000000 0.032500" quat="0.707107 0.000000 0.707107 0.000000" rgba="0.2 0.8 0.2 0.8" contype="0" conaffinity="0" group="1"/>
        <body name="upper_arm" pos="0.000000 0.000000 0.020000">
          <inertial pos="0.000000 0.000000 0.095763" mass="0.068920" fullinertia="4.284776e-05 5.107767e-05 1.523781e-05 -0.000000e+00 -0.000000e+00 -0.000000e+00"/>
          <joint name="shoulder_pitch" type="hinge" pos="0 0 0" axis="1.000000 0.000000 0.000000" damping="0.6246" range="-1.5000 1.5000"/>
          <geom type="mesh" mesh="upper_arm_mesh" rgba="0.7 0.7 0.7 1.0" contype="1" conaffinity="1"/>
          <geom name="elbow_servo" type="box" size="0.022600 0.012350 0.017500" pos="-0.015900 0.000000 0.132500" quat="0.707107 0.000000 0.707107 0.000000" rgba="0.2 0.8 0.2 0.8" contype="0" conaffinity="0" group="1"/>
          <body name="forearm" pos="0.000000 0.000000 0.120000">
            <inertial pos="0.000000 0.000000 0.082090" mass="0.067000" fullinertia="2.788905e-05 3.588968e-05 1.481331e-05 -0.000000e+00 -0.000000e+00 -0.000000e+00"/>
            <joint name="elbow" type="hinge" pos="0 0 0" axis="1.000000 0.000000 0.000000" damping="0.6246" range="-2.0000 0.0000"/>
            <geom type="mesh" mesh="forearm_mesh" rgba="0.7 0.7 0.7 1.0" contype="1" conaffinity="1"/>
            <geom name="wrist_servo" type="box" size="0.022600 0.012350 0.017500" pos="-0.012500 0.000000 0.084100" quat="1.000000 0.000000 0.000000 0.000000" rgba="0.2 0.8 0.2 0.8" contype="0" conaffinity="0" group="1"/>
            <body name="hand" pos="0.000000 0.000000 0.100000">
              <inertial pos="0.000000 0.001905 0.000000" mass="0.012600" fullinertia="8.013058e-07 7.413000e-07 1.372506e-06 -0.000000e+00 -0.000000e+00 -0.000000e+00"/>
              <joint name="wrist" type="hinge" pos="0 0 0" axis="0.000000 0.000000 1.000000" damping="0.6246" range="-1.5000 1.5000"/>
              <geom type="mesh" mesh="hand_mesh" rgba="0.9 0.9 0.9 1.0" contype="1" conaffinity="1"/>
              <camera name="camera_1_cam" fovy="72.0" pos="0.000000 0.008000 0.000000" euler="0 3.141592653589793 0"/>
            </body>
          </body>
        </body>
      </body>
    </body>
  </worldbody>
  <contact>
    <exclude body1="base" body2="left_rim"/>
    <exclude body1="base" body2="right_rim"/>
    <exclude body1="base" body2="turntable"/>
    <exclude body1="turntable" body2="upper_arm"/>
    <exclude body1="upper_arm" body2="forearm"/>
    <exclude body1="forearm" body2="hand"/>
  </contact>
  <actuator>
    <motor name="left_wheel_motor" joint="left_wheel" gear="2.94" ctrlrange="-1 1"/>
    <motor name="right_wheel_motor" joint="right_wheel" gear="2.94" ctrlrange="-1 1"/>
    <position name="shoulder_yaw_motor" joint="shoulder_yaw" kp="58.8" ctrlrange="-1.5000 1.5000" forcerange="-2.94 2.94"/>
    <position name="shoulder_pitch_motor" joint="shoulder_pitch" kp="58.8" ctrlrange="-1.5000 1.5000" forcerange="-2.94 2.94"/>
    <position name="elbow_motor" joint="elbow" kp="58.8" ctrlrange="-2.0000 0.0000" forcerange="-2.94 2.94"/>
    <position name="wrist_motor" joint="wrist" kp="58.8" ctrlrange="-1.5000 1.5000" forcerange="-2.94 2.94"/>
  </actuator>
  <sensor>
    <jointpos name="left_wheel_pos_sensor" joint="left_wheel"/>
    <jointvel name="left_wheel_vel_sensor" joint="left_wheel"/>
    <jointpos name="right_wheel_pos_sensor" joint="right_wheel"/>
    <jointvel name="right_wheel_vel_sensor" joint="right_wheel"/>
    <jointpos name="shoulder_yaw_pos_sensor" joint="shoulder_yaw"/>
    <jointvel name="shoulder_yaw_vel_sensor" joint="shoulder_yaw"/>
    <jointpos name="shoulder_pitch_pos_sensor" joint="shoulder_pitch"/>
    <jointvel name="shoulder_pitch_vel_sensor" joint="shoulder_pitch"/>
    <jointpos name="elbow_pos_sensor" joint="elbow"/>
    <jointvel name="elbow_vel_sensor" joint="elbow"/>
    <jointpos name="wrist_pos_sensor" joint="wrist"/>
    <jointvel name="wrist_vel_sensor" joint="wrist"/>
    <gyro name="imu_gyro" site="imu"/>
    <accelerometer name="imu_accel" site="imu"/>
  </sensor>
</mujoco>
