<?xml version='1.0' encoding='utf-8'?>
<mujoco model="wheeler_arm">
  <compiler angle="radian" meshdir="meshes"/>
  <default>
    <motor ctrlrange="-1 1" gear="1.0"/>
  </default>
  <asset>
    <mesh name="base_mesh" file="base.stl" scale="1 1 1"/>
    <mesh name="left_rim_mesh" file="left_rim.stl" scale="1 1 1"/>
    <mesh name="right_rim_mesh" file="right_rim.stl" scale="1 1 1"/>
    <mesh name="turntable_mesh" file="turntable.stl" scale="1 1 1"/>
    <mesh name="upper_arm_mesh" file="upper_arm.stl" scale="1 1 1"/>
    <mesh name="forearm_mesh" file="forearm.stl" scale="1 1 1"/>
    <mesh name="hand_mesh" file="hand.stl" scale="1 1 1"/>
  </asset>
  <worldbody>
    <body name="base" pos="0 0 0.0450">
      <freejoint name="root"/>
      <inertial pos="0.000000 0.000000 0.003454" mass="0.262734" fullinertia="1.529573e-04 5.941500e-04 4.740277e-04 -0.000000e+00 -0.000000e+00 -0.000000e+00"/>
      <geom type="mesh" mesh="base_mesh" rgba="0.9 0.9 0.9 1.0" contype="1" conaffinity="1"/>
      <site name="imu" pos="0 0 0" size="0.005"/>
      <geom name="comp_base_pi" type="box" size="0.032500 0.015000 0.002500" pos="0.000000 0.000000 0.000000" rgba="0.0 0.5 0.0 1.0" contype="0" conaffinity="0" group="1"/>
      <geom name="comp_base_battery" type="box" size="0.036500 0.017500 0.009000" pos="0.000000 0.000000 -0.023500" rgba="0.2 0.2 0.8 1.0" contype="0" conaffinity="0" group="1"/>
      <geom name="screw_left_wheel_ear_1" type="cylinder" size="0.0021 0.001" pos="-0.026600 -0.010250 -0.008300" rgba="0.7 0.7 0.7 0.9" contype="0" conaffinity="0" group="1"/>
      <geom name="screw_left_wheel_ear_2" type="cylinder" size="0.0021 0.001" pos="-0.026600 -0.010250 -0.029000" rgba="0.7 0.7 0.7 0.9" contype="0" conaffinity="0" group="1"/>
      <geom name="screw_left_wheel_ear_3" type="cylinder" size="0.0021 0.001" pos="-0.026600 0.010250 -0.008300" rgba="0.7 0.7 0.7 0.9" contype="0" conaffinity="0" group="1"/>
      <geom name="screw_left_wheel_ear_4" type="cylinder" size="0.0021 0.001" pos="-0.026600 0.010250 -0.029000" rgba="0.7 0.7 0.7 0.9" contype="0" conaffinity="0" group="1"/>
      <geom name="screw_left_wheel_ear_5" type="cylinder" size="0.0021 0.001" pos="-0.026600 -0.010250 -0.032800" rgba="0.7 0.7 0.7 0.9" contype="0" conaffinity="0" group="1"/>
      <geom name="screw_left_wheel_ear_6" type="cylinder" size="0.0021 0.001" pos="-0.026600 0.010250 -0.032800" rgba="0.7 0.7 0.7 0.9" contype="0" conaffinity="0" group="1"/>
      <geom name="horn_left_wheel_out_1" type="cylinder" size="0.0013 0.001" pos="-0.062800 0.004950 -0.004950" rgba="0.7 0.7 0.7 0.9" contype="0" conaffinity="0" group="1"/>
      <geom name="horn_left_wheel_out_2" type="cylinder" size="0.0013 0.001" pos="-0.062800 0.004950 0.004950" rgba="0.7 0.7 0.7 0.9" contype="0" conaffinity="0" group="1"/>
      <geom name="horn_left_wheel_out_3" type="cylinder" size="0.0013 0.001" pos="-0.062800 -0.004950 -0.004950" rgba="0.7 0.7 0.7 0.9" contype="0" conaffinity="0" group="1"/>
      <geom name="horn_left_wheel_out_4" type="cylinder" size="0.0013 0.001" pos="-0.062800 -0.004950 0.004950" rgba="0.7 0.7 0.7 0.9" contype="0" conaffinity="0" group="1"/>
      <geom name="rear_left_wheel_rear_1" type="cylinder" size="0.0013 0.001" pos="-0.025100 0.004950 -0.004950" rgba="0.7 0.7 0.7 0.9" contype="0" conaffinity="0" group="1"/>
      <geom name="rear_left_wheel_rear_2" type="cylinder" size="0.0013 0.001" pos="-0.025100 0.004950 0.004950" rgba="0.7 0.7 0.7 0.9" contype="0" conaffinity="0" group="1"/>
      <geom name="rear_left_wheel_rear_3" type="cylinder" size="0.0013 0.001" pos="-0.025100 -0.004950 -0.004950" rgba="0.7 0.7 0.7 0.9" contype="0" conaffinity="0" group="1"/>
      <geom name="rear_left_wheel_rear_4" type="cylinder" size="0.0013 0.001" pos="-0.025100 -0.004950 0.004950" rgba="0.7 0.7 0.7 0.9" contype="0" conaffinity="0" group="1"/>
      <geom name="screw_right_wheel_ear_1" type="cylinder" size="0.0021 0.001" pos="0.026600 -0.010250 0.008300" rgba="0.7 0.7 0.7 0.9" contype="0" conaffinity="0" group="1"/>
      <geom name="screw_right_wheel_ear_2" type="cylinder" size="0.0021 0.001" pos="0.026600 -0.010250 0.029000" rgba="0.7 0.7 0.7 0.9" contype="0" conaffinity="0" group="1"/>
      <geom name="screw_right_wheel_ear_3" type="cylinder" size="0.0021 0.001" pos="0.026600 0.010250 0.008300" rgba="0.7 0.7 0.7 0.9" contype="0" conaffinity="0" group="1"/>
      <geom name="screw_right_wheel_ear_4" type="cylinder" size="0.0021 0.001" pos="0.026600 0.010250 0.029000" rgba="0.7 0.7 0.7 0.9" contype="0" conaffinity="0" group="1"/>
      <geom name="screw_right_wheel_ear_5" type="cylinder" size="0.0021 0.001" pos="0.026600 -0.010250 0.032800" rgba="0.7 0.7 0.7 0.9" contype="0" conaffinity="0" group="1"/>
      <geom name="screw_right_wheel_ear_6" type="cylinder" size="0.0021 0.001" pos="0.026600 0.010250 0.032800" rgba="0.7 0.7 0.7 0.9" contype="0" conaffinity="0" group="1"/>
      <geom name="horn_right_wheel_out_1" type="cylinder" size="0.0013 0.001" pos="0.062800 0.004950 0.004950" rgba="0.7 0.7 0.7 0.9" contype="0" conaffinity="0" group="1"/>
      <geom name="horn_right_wheel_out_2" type="cylinder" size="0.0013 0.001" pos="0.062800 0.004950 -0.004950" rgba="0.7 0.7 0.7 0.9" contype="0" conaffinity="0" group="1"/>
      <geom name="horn_right_wheel_out_3" type="cylinder" size="0.0013 0.001" pos="0.062800 -0.004950 0.004950" rgba="0.7 0.7 0.7 0.9" contype="0" conaffinity="0" group="1"/>
      <geom name="horn_right_wheel_out_4" type="cylinder" size="0.0013 0.001" pos="0.062800 -0.004950 -0.004950" rgba="0.7 0.7 0.7 0.9" contype="0" conaffinity="0" group="1"/>
      <geom name="rear_right_wheel_rear_1" type="cylinder" size="0.0013 0.001" pos="0.025100 0.004950 0.004950" rgba="0.7 0.7 0.7 0.9" contype="0" conaffinity="0" group="1"/>
      <geom name="rear_right_wheel_rear_2" type="cylinder" size="0.0013 0.001" pos="0.025100 0.004950 -0.004950" rgba="0.7 0.7 0.7 0.9" contype="0" conaffinity="0" group="1"/>
      <geom name="rear_right_wheel_rear_3" type="cylinder" size="0.0013 0.001" pos="0.025100 -0.004950 0.004950" rgba="0.7 0.7 0.7 0.9" contype="0" conaffinity="0" group="1"/>
      <geom name="rear_right_wheel_rear_4" type="cylinder" size="0.0013 0.001" pos="0.025100 -0.004950 -0.004950" rgba="0.7 0.7 0.7 0.9" contype="0" conaffinity="0" group="1"/>
      <geom name="screw_shoulder_yaw_ear_1" type="cylinder" size="0.0021 0.001" pos="-0.008300 -0.010250 0.006600" rgba="0.7 0.7 0.7 0.9" contype="0" conaffinity="0" group="1"/>
      <geom name="screw_shoulder_yaw_ear_2" type="cylinder" size="0.0021 0.001" pos="-0.029000 -0.010250 0.006600" rgba="0.7 0.7 0.7 0.9" contype="0" conaffinity="0" group="1"/>
      <geom name="screw_shoulder_yaw_ear_3" type="cylinder" size="0.0021 0.001" pos="-0.008300 0.010250 0.006600" rgba="0.7 0.7 0.7 0.9" contype="0" conaffinity="0" group="1"/>
      <geom name="screw_shoulder_yaw_ear_4" type="cylinder" size="0.0021 0.001" pos="-0.029000 0.010250 0.006600" rgba="0.7 0.7 0.7 0.9" contype="0" conaffinity="0" group="1"/>
      <geom name="screw_shoulder_yaw_ear_5" type="cylinder" size="0.0021 0.001" pos="-0.032800 -0.010250 0.006600" rgba="0.7 0.7 0.7 0.9" contype="0" conaffinity="0" group="1"/>
      <geom name="screw_shoulder_yaw_ear_6" type="cylinder" size="0.0021 0.001" pos="-0.032800 0.010250 0.006600" rgba="0.7 0.7 0.7 0.9" contype="0" conaffinity="0" group="1"/>
      <geom name="horn_shoulder_yaw_out_1" type="cylinder" size="0.0013 0.001" pos="-0.004950 0.004950 0.042800" rgba="0.7 0.7 0.7 0.9" contype="0" conaffinity="0" group="1"/>
      <geom name="horn_shoulder_yaw_out_2" type="cylinder" size="0.0013 0.001" pos="0.004950 0.004950 0.042800" rgba="0.7 0.7 0.7 0.9" contype="0" conaffinity="0" group="1"/>
      <geom name="horn_shoulder_yaw_out_3" type="cylinder" size="0.0013 0.001" pos="-0.004950 -0.004950 0.042800" rgba="0.7 0.7 0.7 0.9" contype="0" conaffinity="0" group="1"/>
      <geom name="horn_shoulder_yaw_out_4" type="cylinder" size="0.0013 0.001" pos="0.004950 -0.004950 0.042800" rgba="0.7 0.7 0.7 0.9" contype="0" conaffinity="0" group="1"/>
      <geom name="rear_shoulder_yaw_rear_1" type="cylinder" size="0.0013 0.001" pos="-0.004950 0.004950 0.005100" rgba="0.7 0.7 0.7 0.9" contype="0" conaffinity="0" group="1"/>
      <geom name="rear_shoulder_yaw_rear_2" type="cylinder" size="0.0013 0.001" pos="0.004950 0.004950 0.005100" rgba="0.7 0.7 0.7 0.9" contype="0" conaffinity="0" group="1"/>
      <geom name="rear_shoulder_yaw_rear_3" type="cylinder" size="0.0013 0.001" pos="-0.004950 -0.004950 0.005100" rgba="0.7 0.7 0.7 0.9" contype="0" conaffinity="0" group="1"/>
      <geom name="rear_shoulder_yaw_rear_4" type="cylinder" size="0.0013 0.001" pos="0.004950 -0.004950 0.005100" rgba="0.7 0.7 0.7 0.9" contype="0" conaffinity="0" group="1"/>
      <geom name="mount_base_pi_m1" type="cylinder" size="0.0013 0.001" pos="-0.029000 -0.011500 0.000000" rgba="0.7 0.7 0.7 0.9" contype="0" conaffinity="0" group="1"/>
      <geom name="mount_base_pi_m2" type="cylinder" size="0.0013 0.001" pos="0.029000 -0.011500 0.000000" rgba="0.7 0.7 0.7 0.9" contype="0" conaffinity="0" group="1"/>
      <geom name="mount_base_pi_m3" type="cylinder" size="0.0013 0.001" pos="-0.029000 0.011500 0.000000" rgba="0.7 0.7 0.7 0.9" contype="0" conaffinity="0" group="1"/>
      <geom name="mount_base_pi_m4" type="cylinder" size="0.0013 0.001" pos="0.029000 0.011500 0.000000" rgba="0.7 0.7 0.7 0.9" contype="0" conaffinity="0" group="1"/>
      <geom name="wire_servo_bus_base_0" type="capsule" fromto="-0.010000 0.013000 0.002500 -0.028200 0.000000 0.000000" size="0.0009" rgba="0.2 0.4 1.0 0.9" contype="0" conaffinity="0" group="2"/>
      <geom name="wire_servo_bus_base_1" type="capsule" fromto="-0.028200 0.000000 0.000000 -0.028200 0.000000 -0.020500" size="0.0009" rgba="0.2 0.4 1.0 0.9" contype="0" conaffinity="0" group="2"/>
      <geom name="wire_servo_bus_base_2" type="capsule" fromto="-0.028200 0.000000 -0.020500 -0.028200 0.000000 0.000000" size="0.0009" rgba="0.2 0.4 1.0 0.9" contype="0" conaffinity="0" group="2"/>
      <geom name="wire_servo_bus_base_3" type="capsule" fromto="-0.028200 0.000000 0.000000 0.028200 0.000000 0.000000" size="0.0009" rgba="0.2 0.4 1.0 0.9" contype="0" conaffinity="0" group="2"/>
      <geom name="wire_servo_bus_base_4" type="capsule" fromto="0.028200 0.000000 0.000000 0.028200 0.000000 0.020500" size="0.0009" rgba="0.2 0.4 1.0 0.9" contype="0" conaffinity="0" group="2"/>
      <geom name="wire_servo_bus_base_5" type="capsule" fromto="0.028200 0.000000 0.020500 0.028200 0.000000 0.000000" size="0.0009" rgba="0.2 0.4 1.0 0.9" contype="0" conaffinity="0" group="2"/>
      <geom name="wire_servo_bus_base_6" type="capsule" fromto="0.028200 0.000000 0.000000 -0.020500 0.000000 0.000000" size="0.0009" rgba="0.2 0.4 1.0 0.9" contype="0" conaffinity="0" group="2"/>
      <geom name="wire_servo_bus_base_7" type="capsule" fromto="-0.020500 0.000000 0.000000 -0.020500 0.000000 0.008200" size="0.0009" rgba="0.2 0.4 1.0 0.9" contype="0" conaffinity="0" group="2"/>
      <geom name="wire_servo_bus_base_8" type="capsule" fromto="-0.020500 0.000000 0.008200 -0.020500 0.000000 0.000000" size="0.0009" rgba="0.2 0.4 1.0 0.9" contype="0" conaffinity="0" group="2"/>
      <geom name="wire_servo_bus_base_9" type="capsule" fromto="-0.020500 0.000000 0.000000 -0.038000 0.000000 0.000000" size="0.0009" rgba="0.2 0.4 1.0 0.9" contype="0" conaffinity="0" group="2"/>
      <geom name="wire_servo_bus_base_10" type="capsule" fromto="-0.038000 0.000000 0.000000 -0.038000 0.000000 0.008200" size="0.0009" rgba="0.2 0.4 1.0 0.9" contype="0" conaffinity="0" group="2"/>
      <geom name="wire_camera_csi_base_7" type="capsule" fromto="-0.038000 0.000000 0.008200 -0.038000 0.000000 0.000000" size="0.0018" rgba="1.0 0.8 0.0 0.9" contype="0" conaffinity="0" group="2"/>
      <geom name="wire_camera_csi_base_8" type="capsule" fromto="-0.038000 0.000000 0.000000 0.016000 0.000000 0.002500" size="0.0018" rgba="1.0 0.8 0.0 0.9" contype="0" conaffinity="0" group="2"/>
      <geom name="wire_power_base_0" type="capsule" fromto="0.036500 0.000000 -0.023500 0.036500 0.000000 0.000000" size="0.0012" rgba="0.9 0.2 0.2 0.9" contype="0" conaffinity="0" group="2"/>
      <geom name="wire_power_base_1" type="capsule" fromto="0.036500 0.000000 0.000000 -0.032500 0.000000 0.000000" size="0.0012" rgba="0.9 0.2 0.2 0.9" contype="0" conaffinity="0" group="2"/>
      <geom name="left_wheel_servo" type="box" size="0.022700 0.012400 0.015900" pos="-0.044100 0.000000 -0.012500" quat="0.707107 0.000000 -0.707107 0.000000" rgba="0.2 0.8 0.2 0.8" contype="0" conaffinity="0" group="1"/>
      <geom name="right_wheel_servo" type="box" size="0.022700 0.012400 0.015900" pos="0.044100 0.000000 0.012500" quat="0.707107 0.000000 0.707107 0.000000" rgba="0.2 0.8 0.2 0.8" contype="0" conaffinity="0" group="1"/>
      <geom name="shoulder_yaw_servo" type="box" size="0.022700 0.012400 0.015900" pos="-0.012500 0.000000 0.024100" quat="1.000000 0.000000 0.000000 0.000000" rgba="0.2 0.8 0.2 0.8" contype="0" conaffinity="0" group="1"/>
      <geom name="left_wheel_servo_boss" type="cylinder" size="0.004000 0.001400" pos="-0.061400 0.000000 0.000000" rgba="0.2 0.8 0.2 0.8" contype="0" conaffinity="0" group="1" quat="0.707107 -0.000000 -0.707107 0.000000"/>
      <geom name="right_wheel_servo_boss" type="cylinder" size="0.004000 0.001400" pos="0.061400 0.000000 0.000000" rgba="0.2 0.8 0.2 0.8" contype="0" conaffinity="0" group="1" quat="0.707107 -0.000000 0.707107 0.000000"/>
      <geom name="shoulder_yaw_servo_boss" type="cylinder" size="0.004000 0.001400" pos="0.000000 0.000000 0.041400" rgba="0.2 0.8 0.2 0.8" contype="0" conaffinity="0" group="1"/>
      <body name="left_rim" pos="-0.060000 0.000000 0.000000">
        <inertial pos="0.000000 0.000000 0.000000" mass="0.048600" fullinertia="3.321000e-05 3.321000e-05 6.561000e-05 -0.000000e+00 -0.000000e+00 -0.000000e+00"/>
        <joint name="left_wheel" type="hinge" pos="0 0 0" axis="-1.000000 0.000000 0.000000" damping="0.0100"/>
        <geom type="mesh" mesh="left_rim_mesh" rgba="0.15 0.15 0.15 1.0" contype="0" conaffinity="0"/>
        <geom type="cylinder" size="0.045 0.005" quat="0.7071068 0 0.7071068 0" rgba="0.15 0.15 0.15 0.0" contype="1" conaffinity="1" friction="1.5 0.005 0.0001"/>
        <geom name="mount_left_rim_wheel_m1" type="cylinder" size="0.0015 0.001" pos="0.009550 0.000000 0.000000" rgba="0.7 0.7 0.7 0.9" contype="0" conaffinity="0" group="1"/>
        <geom name="mount_left_rim_wheel_m2" type="cylinder" size="0.0015 0.001" pos="-0.009550 0.000000 0.000000" rgba="0.7 0.7 0.7 0.9" contype="0" conaffinity="0" group="1"/>
        <geom name="mount_left_rim_wheel_m3" type="cylinder" size="0.0015 0.001" pos="0.000000 0.009550 0.000000" rgba="0.7 0.7 0.7 0.9" contype="0" conaffinity="0" group="1"/>
        <geom name="mount_left_rim_wheel_m4" type="cylinder" size="0.0015 0.001" pos="0.000000 -0.009550 0.000000" rgba="0.7 0.7 0.7 0.9" contype="0" conaffinity="0" group="1"/>
        <geom name="mount_left_rim_wheel_m5" type="cylinder" size="0.0015 0.001" pos="0.006750 0.006750 0.000000" rgba="0.7 0.7 0.7 0.9" contype="0" conaffinity="0" group="1"/>
        <geom name="mount_left_rim_wheel_m6" type="cylinder" size="0.0015 0.001" pos="-0.006750 -0.006750 0.000000" rgba="0.7 0.7 0.7 0.9" contype="0" conaffinity="0" group="1"/>
      </body>
      <body name="right_rim" pos="0.060000 0.000000 0.000000">
        <inertial pos="0.000000 0.000000 0.000000" mass="0.048600" fullinertia="3.321000e-05 3.321000e-05 6.561000e-05 -0.000000e+00 -0.000000e+00 -0.000000e+00"/>
        <joint name="right_wheel" type="hinge" pos="0 0 0" axis="1.000000 0.000000 0.000000" damping="0.0100"/>
        <geom type="mesh" mesh="right_rim_mesh" rgba="0.15 0.15 0.15 1.0" contype="0" conaffinity="0"/>
        <geom type="cylinder" size="0.045 0.005" quat="0.7071068 0 0.7071068 0" rgba="0.15 0.15 0.15 0.0" contype="1" conaffinity="1" friction="1.5 0.005 0.0001"/>
        <geom name="mount_right_rim_wheel_m1" type="cylinder" size="0.0015 0.001" pos="0.009550 0.000000 0.000000" rgba="0.7 0.7 0.7 0.9" contype="0" conaffinity="0" group="1"/>
        <geom name="mount_right_rim_wheel_m2" type="cylinder" size="0.0015 0.001" pos="-0.009550 0.000000 0.000000" rgba="0.7 0.7 0.7 0.9" contype="0" conaffinity="0" group="1"/>
        <geom name="mount_right_rim_wheel_m3" type="cylinder" size="0.0015 0.001" pos="0.000000 0.009550 0.000000" rgba="0.7 0.7 0.7 0.9" contype="0" conaffinity="0" group="1"/>
        <geom name="mount_right_rim_wheel_m4" type="cylinder" size="0.0015 0.001" pos="0.000000 -0.009550 0.000000" rgba="0.7 0.7 0.7 0.9" contype="0" conaffinity="0" group="1"/>
        <geom name="mount_right_rim_wheel_m5" type="cylinder" size="0.0015 0.001" pos="0.006750 0.006750 0.000000" rgba="0.7 0.7 0.7 0.9" contype="0" conaffinity="0" group="1"/>
        <geom name="mount_right_rim_wheel_m6" type="cylinder" size="0.0015 0.001" pos="-0.006750 -0.006750 0.000000" rgba="0.7 0.7 0.7 0.9" contype="0" conaffinity="0" group="1"/>
      </body>
      <body name="turntable" pos="0.000000 0.000000 0.040000">
        <inertial pos="0.000000 0.000000 0.018543" mass="0.059320" fullinertia="9.188139e-06 1.627169e-05 1.311531e-05 -0.000000e+00 -0.000000e+00 -0.000000e+00"/>
        <joint name="shoulder_yaw" type="hinge" pos="0 0 0" axis="0.000000 0.000000 1.000000" damping="0.6246" range="-1.5000 1.5000"/>
        <geom name="shoulder_yaw_horn_disc" type="cylinder" size="0.009250 0.001400" pos="0.000000 0.000000 0.001400" rgba="0.85 0.85 0.88 0.9" contype="0" conaffinity="0" group="1"/>
        <geom type="mesh" mesh="turntable_mesh" rgba="0.9 0.9 0.9 1.0" contype="1" conaffinity="1"/>
        <geom name="screw_shoulder_pitch_ear_1" type="cylinder" size="0.0021 0.001" pos="-0.033400 -0.010250 0.028300" rgba="0.7 0.7 0.7 0.9" contype="0" conaffinity="0" group="1"/>
        <geom name="screw_shoulder_pitch_ear_2" type="cylinder" size="0.0021 0.001" pos="-0.033400 -0.010250 0.049000" rgba="0.7 0.7 0.7 0.9" contype="0" conaffinity="0" group="1"/>
        <geom name="screw_shoulder_pitch_ear_3" type="cylinder" size="0.0021 0.001" pos="-0.033400 0.010250 0.028300" rgba="0.7 0.7 0.7 0.9" contype="0" conaffinity="0" group="1"/>
        <geom name="screw_shoulder_pitch_ear_4" type="cylinder" size="0.0021 0.001" pos="-0.033400 0.010250 0.049000" rgba="0.7 0.7 0.7 0.9" contype="0" conaffinity="0" group="1"/>
        <geom name="screw_shoulder_pitch_ear_5" type="cylinder" size="0.0021 0.001" pos="-0.033400 -0.010250 0.052800" rgba="0.7 0.7 0.7 0.9" contype="0" conaffinity="0" group="1"/>
        <geom name="screw_shoulder_pitch_ear_6" type="cylinder" size="0.0021 0.001" pos="-0.033400 0.010250 0.052800" rgba="0.7 0.7 0.7 0.9" contype="0" conaffinity="0" group="1"/>
        <geom name="horn_shoulder_pitch_out_1" type="cylinder" size="0.0013 0.001" pos="0.002800 0.004950 0.024950" rgba="0.7 0.7 0.7 0.9" contype="0" conaffinity="0" group="1"/>
        <geom name="horn_shoulder_pitch_out_2" type="cylinder" size="0.0013 0.001" pos="0.002800 0.004950 0.015050" rgba="0.7 0.7 0.7 0.9" contype="0" conaffinity="0" group="1"/>
        <geom name="horn_shoulder_pitch_out_3" type="cylinder" size="0.0013 0.001" pos="0.002800 -0.004950 0.024950" rgba="0.7 0.7 0.7 0.9" contype="0" conaffinity="0" group="1"/>
        <geom name="horn_shoulder_pitch_out_4" type="cylinder" size="0.0013 0.001" pos="0.002800 -0.004950 0.015050" rgba="0.7 0.7 0.7 0.9" contype="0" conaffinity="0" group="1"/>
        <geom name="rear_shoulder_pitch_rear_1" type="cylinder" size="0.0013 0.001" pos="-0.034900 0.004950 0.024950" rgba="0.7 0.7 0.7 0.9" contype="0" conaffinity="0" group="1"/>
        <geom name="rear_shoulder_pitch_rear_2" type="cylinder" size="0.0013 0.001" pos="-0.034900 0.004950 0.015050" rgba="0.7 0.7 0.7 0.9" contype="0" conaffinity="0" group="1"/>
        <geom name="rear_shoulder_pitch_rear_3" type="cylinder" size="0.0013 0.001" pos="-0.034900 -0.004950 0.024950" rgba="0.7 0.7 0.7 0.9" contype="0" conaffinity="0" group="1"/>
        <geom name="rear_shoulder_pitch_rear_4" type="cylinder" size="0.0013 0.001" pos="-0.034900 -0.004950 0.015050" rgba="0.7 0.7 0.7 0.9" contype="0" conaffinity="0" group="1"/>
        <geom name="wire_servo_bus_turntable_11" type="capsule" fromto="0.000000 0.000000 0.000000 0.000000 0.000000 0.040500" size="0.0009" rgba="0.2 0.4 1.0 0.9" contype="0" conaffinity="0" group="2"/>
        <geom name="wire_servo_bus_turntable_12" type="capsule" fromto="0.000000 0.000000 0.040500 -0.031800 0.000000 0.040500" size="0.0009" rgba="0.2 0.4 1.0 0.9" contype="0" conaffinity="0" group="2"/>
        <geom name="wire_servo_bus_turntable_13" type="capsule" fromto="-0.031800 0.000000 0.040500 0.000000 0.000000 0.040500" size="0.0009" rgba="0.2 0.4 1.0 0.9" contype="0" conaffinity="0" group="2"/>
        <geom name="wire_servo_bus_turntable_14" type="capsule" fromto="0.000000 0.000000 0.040500 0.000000 0.000000 0.058000" size="0.0009" rgba="0.2 0.4 1.0 0.9" contype="0" conaffinity="0" group="2"/>
        <geom name="wire_servo_bus_turntable_15" type="capsule" fromto="0.000000 0.000000 0.058000 -0.031800 0.000000 0.058000" size="0.0009" rgba="0.2 0.4 1.0 0.9" contype="0" conaffinity="0" group="2"/>
        <geom name="wire_camera_csi_turntable_5" type="capsule" fromto="-0.031800 0.000000 0.058000 0.000000 0.000000 0.058000" size="0.0018" rgba="1.0 0.8 0.0 0.9" contype="0" conaffinity="0" group="2"/>
        <geom name="wire_camera_csi_turntable_6" type="capsule" fromto="0.000000 0.000000 0.058000 0.000000 0.000000 0.000000" size="0.0018" rgba="1.0 0.8 0.0 0.9" contype="0" conaffinity="0" group="2"/>
        <geom name="shoulder_pitch_servo" type="box" size="0.022700 0.012400 0.015900" pos="-0.015900 0.000000 0.032500" quat="0.707107 0.000000 0.707107 0.000000" rgba="0.2 0.8 0.2 0.8" contype="0" conaffinity="0" group="1"/>
        <geom name="shoulder_pitch_servo_boss" type="cylinder" size="0.004000 0.001400" pos="0.001400 0.000000 0.020000" rgba="0.2 0.8 0.2 0.8" contype="0" conaffinity="0" group="1" quat="0.707107 -0.000000 0.707107 0.000000"/>
        <body name="upper_arm" pos="0.000000 0.000000 0.020000">
          <inertial pos="0.000000 0.000000 0.095763" mass="0.068920" fullinertia="4.284776e-05 5.107767e-05 1.523781e-05 -0.000000e+00 -0.000000e+00 -0.000000e+00"/>
          <joint name="shoulder_pitch" type="hinge" pos="0 0 0" axis="1.000000 0.000000 0.000000" damping="0.6246" range="-1.5000 1.5000"/>
          <geom name="shoulder_pitch_horn_disc" type="cylinder" size="0.009250 0.001400" pos="0.001400 0.000000 0.000000" rgba="0.85 0.85 0.88 0.9" contype="0" conaffinity="0" group="1" quat="0.707107 -0.000000 0.707107 0.000000"/>
          <geom type="mesh" mesh="upper_arm_mesh" rgba="0.7 0.7 0.7 1.0" contype="1" conaffinity="1"/>
          <geom name="screw_elbow_ear_1" type="cylinder" size="0.0021 0.001" pos="-0.033400 -0.010250 0.128300" rgba="0.7 0.7 0.7 0.9" contype="0" conaffinity="0" group="1"/>
          <geom name="screw_elbow_ear_2" type="cylinder" size="0.0021 0.001" pos="-0.033400 -0.010250 0.149000" rgba="0.7 0.7 0.7 0.9" contype="0" conaffinity="0" group="1"/>
          <geom name="screw_elbow_ear_3" type="cylinder" size="0.0021 0.001" pos="-0.033400 0.010250 0.128300" rgba="0.7 0.7 0.7 0.9" contype="0" conaffinity="0" group="1"/>
          <geom name="screw_elbow_ear_4" type="cylinder" size="0.0021 0.001" pos="-0.033400 0.010250 0.149000" rgba="0.7 0.7 0.7 0.9" contype="0" conaffinity="0" group="1"/>
          <geom name="screw_elbow_ear_5" type="cylinder" size="0.0021 0.001" pos="-0.033400 -0.010250 0.152800" rgba="0.7 0.7 0.7 0.9" contype="0" conaffinity="0" group="1"/>
          <geom name="screw_elbow_ear_6" type="cylinder" size="0.0021 0.001" pos="-0.033400 0.010250 0.152800" rgba="0.7 0.7 0.7 0.9" contype="0" conaffinity="0" group="1"/>
          <geom name="horn_elbow_out_1" type="cylinder" size="0.0013 0.001" pos="0.002800 0.004950 0.124950" rgba="0.7 0.7 0.7 0.9" contype="0" conaffinity="0" group="1"/>
          <geom name="horn_elbow_out_2" type="cylinder" size="0.0013 0.001" pos="0.002800 0.004950 0.115050" rgba="0.7 0.7 0.7 0.9" contype="0" conaffinity="0" group="1"/>
          <geom name="horn_elbow_out_3" type="cylinder" size="0.0013 0.001" pos="0.002800 -0.004950 0.124950" rgba="0.7 0.7 0.7 0.9" contype="0" conaffinity="0" group="1"/>
          <geom name="horn_elbow_out_4" type="cylinder" size="0.0013 0.001" pos="0.002800 -0.004950 0.115050" rgba="0.7 0.7 0.7 0.9" contype="0" conaffinity="0" group="1"/>
          <geom name="rear_elbow_rear_1" type="cylinder" size="0.0013 0.001" pos="-0.034900 0.004950 0.124950" rgba="0.7 0.7 0.7 0.9" contype="0" conaffinity="0" group="1"/>
          <geom name="rear_elbow_rear_2" type="cylinder" size="0.0013 0.001" pos="-0.034900 0.004950 0.115050" rgba="0.7 0.7 0.7 0.9" contype="0" conaffinity="0" group="1"/>
          <geom name="rear_elbow_rear_3" type="cylinder" size="0.0013 0.001" pos="-0.034900 -0.004950 0.124950" rgba="0.7 0.7 0.7 0.9" contype="0" conaffinity="0" group="1"/>
          <geom name="rear_elbow_rear_4" type="cylinder" size="0.0013 0.001" pos="-0.034900 -0.004950 0.115050" rgba="0.7 0.7 0.7 0.9" contype="0" conaffinity="0" group="1"/>
          <geom name="wire_servo_bus_upper_arm_16" type="capsule" fromto="0.000000 0.000000 0.000000 0.000000 0.000000 0.140500" size="0.0009" rgba="0.2 0.4 1.0 0.9" contype="0" conaffinity="0" group="2"/>
          <geom name="wire_servo_bus_upper_arm_17" type="capsule" fromto="0.000000 0.000000 0.140500 -0.031800 0.000000 0.140500" size="0.0009" rgba="0.2 0.4 1.0 0.9" contype="0" conaffinity="0" group="2"/>
          <geom name="wire_servo_bus_upper_arm_18" type="capsule" fromto="-0.031800 0.000000 0.140500 0.000000 0.000000 0.140500" size="0.0009" rgba="0.2 0.4 1.0 0.9" contype="0" conaffinity="0" group="2"/>
          <geom name="wire_servo_bus_upper_arm_19" type="capsule" fromto="0.000000 0.000000 0.140500 0.000000 0.000000 0.158000" size="0.0009" rgba="0.2 0.4 1.0 0.9" contype="0" conaffinity="0" group="2"/>
          <geom name="wire_servo_bus_upper_arm_20" type="capsule" fromto="0.000000 0.000000 0.158000 -0.031800 0.000000 0.158000" size="0.0009" rgba="0.2 0.4 1.0 0.9" contype="0" conaffinity="0" group="2"/>
          <geom name="wire_camera_csi_upper_arm_3" type="capsule" fromto="-0.031800 0.000000 0.158000 0.000000 0.000000 0.158000" size="0.0018" rgba="1.0 0.8 0.0 0.9" contype="0" conaffinity="0" group="2"/>
          <geom name="wire_camera_csi_upper_arm_4" type="capsule" fromto="0.000000 0.000000 0.158000 0.000000 0.000000 0.000000" size="0.0018" rgba="1.0 0.8 0.0 0.9" contype="0" conaffinity="0" group="2"/>
          <geom name="elbow_servo" type="box" size="0.022700 0.012400 0.015900" pos="-0.015900 0.000000 0.132500" quat="0.707107 0.000000 0.707107 0.000000" rgba="0.2 0.8 0.2 0.8" contype="0" conaffinity="0" group="1"/>
          <geom name="elbow_servo_boss" type="cylinder" size="0.004000 0.001400" pos="0.001400 0.000000 0.120000" rgba="0.2 0.8 0.2 0.8" contype="0" conaffinity="0" group="1" quat="0.707107 -0.000000 0.707107 0.000000"/>
          <body name="forearm" pos="0.000000 0.000000 0.120000">
            <inertial pos="0.000000 0.000000 0.082090" mass="0.067000" fullinertia="2.788905e-05 3.588968e-05 1.481331e-05 -0.000000e+00 -0.000000e+00 -0.000000e+00"/>
            <joint name="elbow" type="hinge" pos="0 0 0" axis="1.000000 0.000000 0.000000" damping="0.6246" range="-2.0000 0.0000"/>
            <geom name="elbow_horn_disc" type="cylinder" size="0.009250 0.001400" pos="0.001400 0.000000 0.000000" rgba="0.85 0.85 0.88 0.9" contype="0" conaffinity="0" group="1" quat="0.707107 -0.000000 0.707107 0.000000"/>
            <geom type="mesh" mesh="forearm_mesh" rgba="0.7 0.7 0.7 1.0" contype="1" conaffinity="1"/>
            <geom name="screw_wrist_ear_1" type="cylinder" size="0.0021 0.001" pos="-0.008300 -0.010250 0.066600" rgba="0.7 0.7 0.7 0.9" contype="0" conaffinity="0" group="1"/>
            <geom name="screw_wrist_ear_2" type="cylinder" size="0.0021 0.001" pos="-0.029000 -0.010250 0.066600" rgba="0.7 0.7 0.7 0.9" contype="0" conaffinity="0" group="1"/>
            <geom name="screw_wrist_ear_3" type="cylinder" size="0.0021 0.001" pos="-0.008300 0.010250 0.066600" rgba="0.7 0.7 0.7 0.9" contype="0" conaffinity="0" group="1"/>
            <geom name="screw_wrist_ear_4" type="cylinder" size="0.0021 0.001" pos="-0.029000 0.010250 0.066600" rgba="0.7 0.7 0.7 0.9" contype="0" conaffinity="0" group="1"/>
            <geom name="screw_wrist_ear_5" type="cylinder" size="0.0021 0.001" pos="-0.032800 -0.010250 0.066600" rgba="0.7 0.7 0.7 0.9" contype="0" conaffinity="0" group="1"/>
            <geom name="screw_wrist_ear_6" type="cylinder" size="0.0021 0.001" pos="-0.032800 0.010250 0.066600" rgba="0.7 0.7 0.7 0.9" contype="0" conaffinity="0" group="1"/>
            <geom name="horn_wrist_out_1" type="cylinder" size="0.0013 0.001" pos="-0.004950 0.004950 0.102800" rgba="0.7 0.7 0.7 0.9" contype="0" conaffinity="0" group="1"/>
            <geom name="horn_wrist_out_2" type="cylinder" size="0.0013 0.001" pos="0.004950 0.004950 0.102800" rgba="0.7 0.7 0.7 0.9" contype="0" conaffinity="0" group="1"/>
            <geom name="horn_wrist_out_3" type="cylinder" size="0.0013 0.001" pos="-0.004950 -0.004950 0.102800" rgba="0.7 0.7 0.7 0.9" contype="0" conaffinity="0" group="1"/>
            <geom name="horn_wrist_out_4" type="cylinder" size="0.0013 0.001" pos="0.004950 -0.004950 0.102800" rgba="0.7 0.7 0.7 0.9" contype="0" conaffinity="0" group="1"/>
            <geom name="rear_wrist_rear_1" type="cylinder" size="0.0013 0.001" pos="-0.004950 0.004950 0.065100" rgba="0.7 0.7 0.7 0.9" contype="0" conaffinity="0" group="1"/>
            <geom name="rear_wrist_rear_2" type="cylinder" size="0.0013 0.001" pos="0.004950 0.004950 0.065100" rgba="0.7 0.7 0.7 0.9" contype="0" conaffinity="0" group="1"/>
            <geom name="rear_wrist_rear_3" type="cylinder" size="0.0013 0.001" pos="-0.004950 -0.004950 0.065100" rgba="0.7 0.7 0.7 0.9" contype="0" conaffinity="0" group="1"/>
            <geom name="rear_wrist_rear_4" type="cylinder" size="0.0013 0.001" pos="0.004950 -0.004950 0.065100" rgba="0.7 0.7 0.7 0.9" contype="0" conaffinity="0" group="1"/>
            <geom name="wire_servo_bus_forearm_21" type="capsule" fromto="0.000000 0.000000 0.000000 0.000000 0.000000 0.068200" size="0.0009" rgba="0.2 0.4 1.0 0.9" contype="0" conaffinity="0" group="2"/>
            <geom name="wire_servo_bus_forearm_22" type="capsule" fromto="0.000000 0.000000 0.068200 -0.020500 0.000000 0.068200" size="0.0009" rgba="0.2 0.4 1.0 0.9" contype="0" conaffinity="0" group="2"/>
            <geom name="wire_camera_csi_forearm_1" type="capsule" fromto="-0.038000 0.000000 0.068200 0.000000 0.000000 0.068200" size="0.0018" rgba="1.0 0.8 0.0 0.9" contype="0" conaffinity="0" group="2"/>
            <geom name="wire_camera_csi_forearm_2" type="capsule" fromto="0.000000 0.000000 0.068200 0.000000 0.000000 0.000000" size="0.0018" rgba="1.0 0.8 0.0 0.9" contype="0" conaffinity="0" group="2"/>
            <geom name="wrist_servo" type="box" size="0.022700 0.012400 0.015900" pos="-0.012500 0.000000 0.084100" quat="1.000000 0.000000 0.000000 0.000000" rgba="0.2 0.8 0.2 0.8" contype="0" conaffinity="0" group="1"/>
            <geom name="wrist_servo_boss" type="cylinder" size="0.004000 0.001400" pos="0.000000 0.000000 0.101400" rgba="0.2 0.8 0.2 0.8" contype="0" conaffinity="0" group="1"/>
            <body name="hand" pos="0.000000 0.000000 0.100000">
              <inertial pos="0.000000 0.001905 0.000000" mass="0.012600" fullinertia="8.013058e-07 7.413000e-07 1.372506e-06 -0.000000e+00 -0.000000e+00 -0.000000e+00"/>
              <joint name="wrist" type="hinge" pos="0 0 0" axis="0.000000 0.000000 1.000000" damping="0.6246" range="-1.5000 1.5000"/>
              <geom name="wrist_horn_disc" type="cylinder" size="0.009250 0.001400" pos="0.000000 0.000000 0.001400" rgba="0.85 0.85 0.88 0.9" contype="0" conaffinity="0" group="1"/>
              <geom type="mesh" mesh="hand_mesh" rgba="0.9 0.9 0.9 1.0" contype="1" conaffinity="1"/>
              <camera name="camera_1_cam" fovy="72.0" pos="0.000000 0.008000 0.000000" euler="0 3.141592653589793 0"/>
              <geom name="comp_hand_camera" type="box" size="0.012500 0.012000 0.004500" pos="0.000000 0.008000 0.000000" rgba="0.1 0.6 0.1 1.0" contype="0" conaffinity="0" group="1"/>
              <geom name="mount_hand_camera_m1" type="cylinder" size="0.0010 0.001" pos="-0.010500 -0.001500 0.000000" rgba="0.7 0.7 0.7 0.9" contype="0" conaffinity="0" group="1"/>
              <geom name="mount_hand_camera_m2" type="cylinder" size="0.0010 0.001" pos="0.010500 -0.001500 0.000000" rgba="0.7 0.7 0.7 0.9" contype="0" conaffinity="0" group="1"/>
              <geom name="wire_camera_csi_hand_0" type="capsule" fromto="0.000000 -0.004000 0.000000 0.000000 0.000000 0.000000" size="0.0018" rgba="1.0 0.8 0.0 0.9" contype="0" conaffinity="0" group="2"/>
            </body>
          </body>
        </body>
      </body>
    </body>
  </worldbody>
  <contact>
    <exclude body1="base" body2="left_rim"/>
    <exclude body1="base" body2="right_rim"/>
    <exclude body1="base" body2="turntable"/>
    <exclude body1="turntable" body2="upper_arm"/>
    <exclude body1="upper_arm" body2="forearm"/>
    <exclude body1="forearm" body2="hand"/>
  </contact>
  <actuator>
    <motor name="left_wheel_motor" joint="left_wheel" gear="2.94" ctrlrange="-1 1"/>
    <motor name="right_wheel_motor" joint="right_wheel" gear="2.94" ctrlrange="-1 1"/>
    <position name="shoulder_yaw_motor" joint="shoulder_yaw" kp="58.8" ctrlrange="-1.5000 1.5000" forcerange="-2.94 2.94"/>
    <position name="shoulder_pitch_motor" joint="shoulder_pitch" kp="58.8" ctrlrange="-1.5000 1.5000" forcerange="-2.94 2.94"/>
    <position name="elbow_motor" joint="elbow" kp="58.8" ctrlrange="-2.0000 0.0000" forcerange="-2.94 2.94"/>
    <position name="wrist_motor" joint="wrist" kp="58.8" ctrlrange="-1.5000 1.5000" forcerange="-2.94 2.94"/>
  </actuator>
  <sensor>
    <jointpos name="left_wheel_pos_sensor" joint="left_wheel"/>
    <jointvel name="left_wheel_vel_sensor" joint="left_wheel"/>
    <jointpos name="right_wheel_pos_sensor" joint="right_wheel"/>
    <jointvel name="right_wheel_vel_sensor" joint="right_wheel"/>
    <jointpos name="shoulder_yaw_pos_sensor" joint="shoulder_yaw"/>
    <jointvel name="shoulder_yaw_vel_sensor" joint="shoulder_yaw"/>
    <jointpos name="shoulder_pitch_pos_sensor" joint="shoulder_pitch"/>
    <jointvel name="shoulder_pitch_vel_sensor" joint="shoulder_pitch"/>
    <jointpos name="elbow_pos_sensor" joint="elbow"/>
    <jointvel name="elbow_vel_sensor" joint="elbow"/>
    <jointpos name="wrist_pos_sensor" joint="wrist"/>
    <jointvel name="wrist_vel_sensor" joint="wrist"/>
    <gyro name="imu_gyro" site="imu"/>
    <accelerometer name="imu_accel" site="imu"/>
  </sensor>
</mujoco>
